Workbook

Sheet May2022
B2: Note: Recording should be done 1st hour of the day
B3: DAILY BIOGAS USAGE MONITORING | AB3: SBVC RECORD | AE3: DPO RECORD (Lowela) | AG3: Biogas Operation Utility Consumption | AM3: Remarks/ Shifts
B4: Date | C4: Day | D4: Gas Storage (%) | H4: Quality | I4: Gas Meters (Nmᶾ) | M4: Gas Flare | P4: Gas Engine Power Meter (kWh) | R4: Diesel Fuel Consumption | U4: Biogas Fuel Consumption | X4: Ope. Hrs w/ Diesel | Z4: Ope. Hrs w/ Biogas | AB4: Waste Hauling Operation | AE4: Waste Hauling Operation
D5: F1 | E5: F2 | F5: F3 | G5: Total | H5: Methane Content | I5: Gas Engine Line Totalizer | K5: Thermax 2 | M5: Time | O5: Total Volume | R5: Thermax 1 | S5: Thermax 2 | T5: Total | U5: Thermax 1 | V5: Thermax 2 | W5: Total | X5: Thermax 1 | Y5: Thermax 2 | Z5: Thermax 1 | AA5: Thermax 2 | AB5: Actual Waste Delivered (MT) | AD5: DS | AE5: Actual Waste Delivered (MT) | AG5: Electricity @ Biogas plant, kWhr | AI5: Electricity @ DPO cannery (Blower) , kWhr | AK5: Water, m3
D6: 8350 | E6: 8350 | F6: 8350 | G6: =D6+F6 -> 16700 | H6: 55% Min | I6: Totalizer | J6: Output | K6: Totalizer | L6: Output | M6: Start | N6: End | O6: Nm³ | P6: Totalizer | Q6: Output | R6: Li. | S6: Li. | T6: Li. | X6: Hrs | Y6: Hrs | Z6: Hrs | AA6: Hrs | AB6: Delivery | AC6: Cummulative | AD6: % | AE6: Delivery | AF6: Cummulative | AG6: Totalizer | AH6: Consumed | AI6: Totalizer | AJ6: Consumed | AK6: Totalizer | AL6: Consumed
B7: 44682 | C7: =TEXT(B7,"ddd") -> Sun | G7: =SUMPRODUCT($D$6:$F$6,D7:F7) -> 0 | J7: =I7-0 -> 0 | L7: =K7-0 -> 0 | Q7: =P7-0 -> 0 | R7: 0 | S7: 0 | T7: =SUM(R7:S7) -> 0 | U7: 0 | V7: 0 | W7: =SUM(U7:V7) -> 0 | X7: 0 | Y7: 0 | Z7: 0 | AA7: 0 | AC7: =AB7 -> 0 | AE7: 0 | AF7: =AE7 -> 0 | AM7: n/a - biogas not yet opearational
B8: =B7+1 -> 44683 | C8: =TEXT(B8,"ddd") -> Mon | G8: =SUMPRODUCT($D$6:$F$6,D8:F8) -> 0 | J8: =I8-I7 -> 0 | L8: =K8-K7 -> 0 | Q8: =P8-P7 -> 0 | R8: 0 | S8: 0 | T8: =SUM(R8:S8) -> 0 | U8: 0 | V8: 0 | W8: =SUM(U8:V8) -> 0 | X8: 0 | Y8: 0 | Z8: 0 | AA8: 0 | AC8: =AB8+AC7 -> 0 | AE8: 0 | AF8: =AE8+AF7 -> 0 | AM8: n/a - biogas not yet opearational
B9: =B8+1 -> 44684 | C9: =TEXT(B9,"ddd") -> Tue | G9: =SUMPRODUCT($D$6:$F$6,D9:F9) -> 0 | J9: =I9-I8 -> 0 | L9: =K9-K8 -> 0 | Q9: =P9-P8 -> 0 | R9: 0 | S9: 0 | T9: =SUM(R9:S9) -> 0 | U9: 0 | V9: 0 | W9: =SUM(U9:V9) -> 0 | X9: 0 | Y9: 0 | Z9: 0 | AA9: 0 | AC9: =AB9+AC8 -> 0 | AE9: 0 | AF9: =AE9+AF8 -> 0 | AM9: n/a - biogas not yet opearational
B10: =B9+1 -> 44685 | C10: =TEXT(B10,"ddd") -> Wed | G10: =SUMPRODUCT($D$6:$F$6,D10:F10) -> 0 | J10: =I10-I9 -> 0 | L10: =K10-K9 -> 0 | Q10: =P10-P9 -> 0 | R10: 0 | S10: 0 | T10: =SUM(R10:S10) -> 0 | U10: 0 | V10: 0 | W10: =SUM(U10:V10) -> 0 | X10: 0 | Y10: 0 | Z10: 0 | AA10: 0 | AC10: =AB10+AC9 -> 0 | AE10: 78.75 | AF10: =AE10+AF9 -> 78.75 | AM10: n/a - biogas not yet opearational
B11: =B10+1 -> 44686 | C11: =TEXT(B11,"ddd") -> Thu | G11: =SUMPRODUCT($D$6:$F$6,D11:F11) -> 0 | J11: =I11-I10 -> 0 | L11: =K11-K10 -> 0 | Q11: =P11-P10 -> 0 | R11: 0 | S11: 0 | T11: =SUM(R11:S11) -> 0 | U11: 0 | V11: 0 | W11: =SUM(U11:V11) -> 0 | X11: 0 | Y11: 0 | Z11: 0 | AA11: 0 | AC11: =AB11+AC10 -> 0 | AE11: 73.27 | AF11: =AE11+AF10 -> 152.02 | AM11: n/a - biogas not yet opearational
B12: =B11+1 -> 44687 | C12: =TEXT(B12,"ddd") -> Fri | G12: =SUMPRODUCT($D$6:$F$6,D12:F12) -> 0 | J12: =I12-I11 -> 0 | L12: =K12-K11 -> 0 | Q12: =P12-P11 -> 0 | R12: 0 | S12: 0 | T12: =SUM(R12:S12) -> 0 | U12: 0 | V12: 0 | W12: =SUM(U12:V12) -> 0 | X12: 0 | Y12: 0 | Z12: 0 | AA12: 0 | AC12: =AB12+AC11 -> 0 | AE12: 31.69 | AF12: =AE12+AF11 -> 183.71 | AM12: n/a - biogas not yet opearational
B13: =B12+1 -> 44688 | C13: =TEXT(B13,"ddd") -> Sat | G13: =SUMPRODUCT($D$6:$F$6,D13:F13) -> 0 | J13: =I13-I12 -> 0 | L13: =K13-K12 -> 0 | Q13: =P13-P12 -> 0 | R13: 0 | S13: 0 | T13: =SUM(R13:S13) -> 0 | U13: 0 | V13: 0 | W13: =SUM(U13:V13) -> 0 | X13: 0 | Y13: 0 | Z13: 0 | AA13: 0 | AC13: =AB13+AC12 -> 0 | AE13: 157.05 | AF13: =AE13+AF12 -> 340.76 | AM13: n/a - biogas not yet opearational
B14: =B13+1 -> 44689 | C14: =TEXT(B14,"ddd") -> Sun | G14: =SUMPRODUCT($D$6:$F$6,D14:F14) -> 0 | J14: =I14-I13 -> 0 | L14: =K14-K13 -> 0 | Q14: =P14-P13 -> 0 | R14: 0 | S14: 0 | T14: =SUM(R14:S14) -> 0 | U14: 0 | V14: 0 | W14: =SUM(U14:V14) -> 0 | X14: 0 | Y14: 0 | Z14: 0 | AA14: 0 | AC14: =AB14+AC13 -> 0 | AE14: 0 | AF14: =AE14+AF13 -> 340.76 | AM14: n/a - biogas not yet opearational
B15: =B14+1 -> 44690 | C15: =TEXT(B15,"ddd") -> Mon | G15: =SUMPRODUCT($D$6:$F$6,D15:F15) -> 0 | J15: =I15-I14 -> 0 | L15: =K15-K14 -> 0 | Q15: =P15-P14 -> 0 | R15: 0 | S15: 0 | T15: =SUM(R15:S15) -> 0 | U15: 0 | V15: 0 | W15: =SUM(U15:V15) -> 0 | X15: 0 | Y15: 0 | Z15: 0 | AA15: 0 | AC15: =AB15+AC14 -> 0 | AE15: 0 | AF15: =AE15+AF14 -> 340.76 | AM15: n/a - biogas not yet opearational
B16: =B15+1 -> 44691 | C16: =TEXT(B16,"ddd") -> Tue | G16: =SUMPRODUCT($D$6:$F$6,D16:F16) -> 0 | J16: =I16-I15 -> 0 | L16: =K16-K15 -> 0 | Q16: =P16-P15 -> 0 | R16: 0 | S16: 0 | T16: =SUM(R16:S16) -> 0 | U16: 0 | V16: 0 | W16: =SUM(U16:V16) -> 0 | X16: 0 | Y16: 0 | Z16: 0 | AA16: 0 | AC16: =AB16+AC15 -> 0 | AE16: 0 | AF16: =AE16+AF15 -> 340.76 | AM16: n/a - biogas not yet opearational
B17: =B16+1 -> 44692 | C17: =TEXT(B17,"ddd") -> Wed | G17: =SUMPRODUCT($D$6:$F$6,D17:F17) -> 0 | J17: =I17-I16 -> 0 | L17: =K17-K16 -> 0 | Q17: =P17-P16 -> 0 | R17: 0 | S17: 0 | T17: =SUM(R17:S17) -> 0 | U17: 0 | V17: 0 | W17: =SUM(U17:V17) -> 0 | X17: 0 | Y17: 0 | Z17: 0 | AA17: 0 | AC17: =AB17+AC16 -> 0 | AE17: 152.62 | AF17: =AE17+AF16 -> 493.38 | AM17: n/a - biogas not yet opearational
B18: =B17+1 -> 44693 | C18: =TEXT(B18,"ddd") -> Thu | G18: =SUMPRODUCT($D$6:$F$6,D18:F18) -> 0 | J18: =I18-I17 -> 0 | L18: =K18-K17 -> 0 | Q18: =P18-P17 -> 0 | R18: 0 | S18: 0 | T18: =SUM(R18:S18) -> 0 | U18: 0 | V18: 0 | W18: =SUM(U18:V18) -> 0 | X18: 0 | Y18: 0 | Z18: 0 | AA18: 0 | AC18: =AB18+AC17 -> 0 | AE18: 52.89 | AF18: =AE18+AF17 -> 546.27 | AM18: n/a - biogas not yet opearational
B19: =B18+1 -> 44694 | C19: =TEXT(B19,"ddd") -> Fri | G19: =SUMPRODUCT($D$6:$F$6,D19:F19) -> 0 | J19: =I19-I18 -> 0 | L19: =K19-K18 -> 0 | Q19: =P19-P18 -> 0 | R19: 0 | S19: 0 | T19: =SUM(R19:S19) -> 0 | U19: 0 | V19: 0 | W19: =SUM(U19:V19) -> 0 | X19: 0 | Y19: 0 | Z19: 0 | AA19: 0 | AC19: =AB19+AC18 -> 0 | AE19: 140.26 | AF19: =AE19+AF18 -> 686.53 | AM19: n/a - biogas not yet opearational
... B22: =B21+1 -> 44697 | C22: =TEXT(B22,"ddd") -> Mon | G22: =SUMPRODUCT($D$6:$F$6,D22:F22) -> 0 | J22: =I22-I21 -> 0 | L22: =K22-K21 -> 0 | Q22: =P22-P21 -> 0 | R22: 0 | S22: 0 | T22: =SUM(R22:S22) -> 0 | U22: 0 | V22: 0 | W22: =SUM(U22:V22) -> 0 | X22: 0 | Y22: 0 | Z22: 0 | AA22: 0 | AC22: =AB22+AC21 -> 0 | AE22: 0 | AF22: =AE22+AF21 -> 707.9 | AM22: n/a - biogas not yet opearational
B23: =B22+1 -> 44698 | C23: =TEXT(B23,"ddd") -> Tue | G23: =SUMPRODUCT($D$6:$F$6,D23:F23) -> 0 | J23: =I23-I22 -> 0 | K23: 11356 | L23: =K23-K22 -> 11356 | Q23: =P23-P22 -> 0 | R23: 0 | S23: 0 | T23: =SUM(R23:S23) -> 0 | U23: 0 | V23: 0 | W23: =SUM(U23:V23) -> 0 | X23: 0 | Y23: 0 | Z23: 0 | AA23: 0 | AC23: =AB23+AC22 -> 0 | AE23: 0 | AF23: =AE23+AF22 -> 707.9 | AM23: n/a - biogas not yet opearational
B24: =B23+1 -> 44699 | C24: =TEXT(B24,"ddd") -> Wed | D24: 1 | E24: 1 | F24: 0.77 | G24: =SUMPRODUCT($D$6:$F$6,D24:F24) -> 23129.5 | H24: 0.552 | J24: =I24-I23 -> 0 | K24: 29685 | L24: =K24-K23 -> 18329 | Q24: =P24-P23 -> 0 | R24: 0 | S24: 0 | T24: =SUM(R24:S24) -> 0 | U24: 0 | V24: 0 | W24: =SUM(U24:V24) -> 0 | X24: 0 | Y24: 0 | Z24: 0 | AA24: 0 | AC24: =AB24+AC23 -> 0 | AE24: 204.38 | AF24: =AE24+AF23 -> 912.28 | AM24: n/a - biogas not yet opearational
B25: =B24+1 -> 44700 | C25: =TEXT(B25,"ddd") -> Thu | D25: 0 | E25: 0.54 | F25: 0.41 | G25: =SUMPRODUCT($D$6:$F$6,D25:F25) -> 7932.5 | H25: 0.556 | J25: =I25-I24 -> 0 | K25: 38308 | L25: =K25-K24 -> 8623 | Q25: =P25-P24 -> 0 | R25: 0 | S25: 0 | T25: =SUM(R25:S25) -> 0 | U25: 0 | V25: 0 | W25: =SUM(U25:V25) -> 0 | X25: 0 | Y25: 0 | Z25: 0 | AA25: 0 | AC25: =AB25+AC24 -> 0 | AE25: 233.5 | AF25: =AE25+AF24 -> 1145.78 | AM25: n/a
B26: =B25+1 -> 44701 | C26: =TEXT(B26,"ddd") -> Fri | D26: 0.07 | E26: 0.8453 | F26: 0.72 | G26: =SUMPRODUCT($D$6:$F$6,D26:F26) -> 13654.755 | H26: 0.55 | J26: =I26-I25 -> 0 | K26: 63218 | L26: =K26-K25 -> 24910 | Q26: =P26-P25 -> 0 | R26: 0 | S26: 0 | T26: =SUM(R26:S26) -> 0 | U26: 0 | V26: 0 | W26: =SUM(U26:V26) -> 0 | X26: 0 | Y26: 0 | Z26: 0 | AA26: 0 | AC26: =AB26+AC25 -> 0 | AE26: 225.5 | AF26: =AE26+AF25 -> 1371.28 | AM26: n/a
B27: =B26+1 -> 44702 | C27: =TEXT(B27,"ddd") -> Sat | D27: 0.05 | E27: 0.49 | F27: 0.1135 | G27: =SUMPRODUCT($D$6:$F$6,D27:F27) -> 5456.725 | H27: 0.561 | J27: =I27-I26 -> 0 | K27: 80268 | L27: =K27-K26 -> 17050 | Q27: =P27-P26 -> 0 | R27: 0 | S27: 0 | T27: =SUM(R27:S27) -> 0 | U27: 0 | V27: 0 | W27: =SUM(U27:V27) -> 0 | X27: 0 | Y27: 0 | Z27: 0 | AA27: 0 | AC27: =AB27+AC26 -> 0 | AE27: 135.51 | AF27: =AE27+AF26 -> 1506.79 | AM27: n/a
B28: =B27+1 -> 44703 | C28: =TEXT(B28,"ddd") -> Sun | D28: 0.19 | E28: 0.97 | F28: 0.24 | G28: =SUMPRODUCT($D$6:$F$6,D28:F28) -> 11690 | H28: 0.555 | J28: =I28-I27 -> 0 | K28: 82900 | L28: =K28-K27 -> 2632 | Q28: =P28-P27 -> 0 | R28: 0 | S28: 0 | T28: =SUM(R28:S28) -> 0 | U28: 0 | V28: 4020 | W28: =SUM(U28:V28) -> 4020 | X28: 0 | Y28: 0 | Z28: 0 | AA28: 2.97 | AC28: =AB28+AC27 -> 0 | AE28: 0 | AF28: =AE28+AF27 -> 1506.79 | AM28: No Canning
B29: =B28+1 -> 44704 | C29: =TEXT(B29,"ddd") -> Mon | D29: 0.42 | E29: 1 | F29: 1 | G29: =SUMPRODUCT($D$6:$F$6,D29:F29) -> 20207 | H29: 0.556 | J29: =I29-I28 -> 0 | K29: 82900 | L29: =K29-K28 -> 0 | Q29: =P29-P28 -> 0 | R29: 0 | S29: 0 | T29: =SUM(R29:S29) -> 0 | U29: 0 | V29: 17049 | W29: =SUM(U29:V29) -> 17049 | X29: 0 | Y29: 0 | Z29: 0 | AA29: 23.52 | AC29: =AB29+AC28 -> 0 | AE29: 144.63 | AF29: =AE29+AF28 -> 1651.42 | AM29: 2
B30: =B29+1 -> 44705 | C30: =TEXT(B30,"ddd") -> Tue | D30: 0.4 | E30: 0.2808 | F30: 0 | G30: =SUMPRODUCT($D$6:$F$6,D30:F30) -> 5684.68 | H30: 0.552 | J30: =I30-I29 -> 0 | K30: 113332 | L30: =K30-K29 -> 30432 | M30: 266 | Q30: =P30-P29 -> 0 | R30: 266 | S30: 0 | T30: =SUM(R30:S30) -> 266 | U30: 0 | V30: 13430 | W30: =SUM(U30:V30) -> 13430 | X30: 0.87 | Y30: 0 | Z30: 0 | AA30: 23.72 | AC30: =AB30+AC29 -> 0 | AE30: 307.99 | AF30: =AE30+AF29 -> 1959.41 | AM30: 2
B31: =B30+1 -> 44706 | C31: =TEXT(B31,"ddd") -> Wed | D31: 0.59 | E31: 0.11 | F31: 0 | G31: =SUMPRODUCT($D$6:$F$6,D31:F31) -> 5845 | H31: 0.557 | J31: =I31-I30 -> 0 | K31: 130705 | L31: =K31-K30 -> 17373 | M31: 2494 | Q31: =P31-P30 -> 0 | R31: 2494 | S31: 0 | T31: =SUM(R31:S31) -> 2494 | U31: 0 | V31: 17583 | W31: =SUM(U31:V31) -> 17583 | X31: 5.05 | Y31: 0 | Z31: 0 | AA31: 23.39 | AC31: =AB31+AC30 -> 0 | AE31: 245.94 | AF31: =AE31+AF30 -> 2205.35 | AM31: 2
B32: =B31+1 -> 44707 | C32: =TEXT(B32,"ddd") -> Thu | D32: 0.04 | E32: 0.67 | F32: 0.59 | G32: =SUMPRODUCT($D$6:$F$6,D32:F32) -> 10855 | H32: 0.563 | J32: =I32-I31 -> 0 | K32: 153846 | L32: =K32-K31 -> 23141 | M32: 185 | Q32: =P32-P31 -> 0 | R32: 185 | S32: 0 | T32: =SUM(R32:S32) -> 185 | U32: 0 | V32: 22595 | W32: =SUM(U32:V32) -> 22595 | X32: 0.47 | Y32: 0 | Z32: 0 | AA32: 23.66 | AC32: =AB32+AC31 -> 0 | AE32: 356.02 | AF32: =AE32+AF31 -> 2561.37 | AM32: 2
B33: =B32+1 -> 44708 | C33: =TEXT(B33,"ddd") -> Fri | D33: 0.23 | E33: 0.7 | F33: 0.35 | G33: =SUMPRODUCT($D$6:$F$6,D33:F33) -> 10688 | H33: 0.552 | J33: =I33-I32 -> 0 | K33: 175232 | L33: =K33-K32 -> 21386 | Q33: =P33-P32 -> 0 | R33: 0 | S33: 0 | T33: =SUM(R33:S33) -> 0 | U33: 0 | V33: 21326 | W33: =SUM(U33:V33) -> 21326 | X33: 0 | Y33: 0 | Z33: 0 | AA33: 23.94 | AC33: =AB33+AC32 -> 0 | AE33: 304.03 | AF33: =AE33+AF32 -> 2865.4 | AM33: 2
B34: =B33+1 -> 44709 | C34: =TEXT(B34,"ddd") -> Sat | D34: 0.4 | E34: 1.0008 | F34: 0.9807 | G34: =SUMPRODUCT($D$6:$F$6,D34:F34) -> 19885.525 | H34: 0.55 | J34: =I34-I33 -> 0 | K34: 208869 | L34: =K34-K33 -> 33637 | Q34: =P34-P33 -> 0 | R34: 0 | S34: 0 | T34: =SUM(R34:S34) -> 0 | U34: 0 | V34: 28677 | W34: =SUM(U34:V34) -> 28677 | X34: 0 | Y34: 0 | Z34: 0 | AA34: 23.2 | AC34: =AB34+AC33 -> 0 | AE34: 40.79 | AF34: =AE34+AF33 -> 2906.19 | AM34: 2
B35: =B34+1 -> 44710 | C35: =TEXT(B35,"ddd") -> Sun | D35: 0.46 | E35: 0.53 | F35: 0.36 | G35: =SUMPRODUCT($D$6:$F$6,D35:F35) -> 11272.5 | H35: 0.567 | J35: =I35-I34 -> 0 | K35: 208869 | L35: =K35-K34 -> 0 | R35: 0 | S35: 0 | T35: =SUM(R35:S35) -> 0 | U35: 0 | V35: 6155 | W35: =SUM(U35:V35) -> 6155 | X35: 0 | Y35: 0 | Z35: 0 | AA35: 9.62 | AC35: =AB35+AC34 -> 0 | AE35: 0 | AF35: =AE35+AF34 -> 2906.19 | AM35: No Canning
B36: =B35+1 -> 44711 | C36: =TEXT(B36,"ddd") -> Mon | D36: 0.57 | E36: 1 | F36: 1 | G36: =SUMPRODUCT($D$6:$F$6,D36:F36) -> 21459.5 | H36: 0.559 | J36: =I36-I35 -> 0 | K36: 231339 | L36: =K36-K35 -> 22470 | Q36: =P36-P35 -> 0 | R36: 0 | S36: 0 | T36: =SUM(R36:S36) -> 0 | U36: 0 | V36: 21110 | W36: =SUM(U36:V36) -> 21110 | X36: 0 | Y36: 0 | Z36: 0 | AA36: 20.39 | AC36: =AB36+AC35 -> 0 | AE36: 147.38 | AF36: =AE36+AF35 -> 3053.57 | AM36: 2
B37: =B36+1 -> 44712 | C37: =TEXT(B37,"ddd") -> Tue | D37: 0.4 | E37: 0.24 | F37: 0 | G37: =SUMPRODUCT($D$6:$F$6,D37:F37) -> 5344 | H37: 0.565 | J37: =I37-I36 -> 0 | K37: 234643 | L37: =K37-K36 -> 3304 | N37: 3860 | Q37: =P37-P36 -> 0 | R37: 0 | S37: 3860 | T37: =SUM(R37:S37) -> 3860 | U37: 0 | V37: 4664 | W37: =SUM(U37:V37) -> 4664 | X37: 0 | Y37: 0 | Z37: 10.18 | AA37: 7.6 | AC37: =AB37+AC36 -> 0 | AE37: 286.6 | AF37: =AE37+AF36 -> 3340.17 | AM37: 2
B38: Total/Average | D38: =AVERAGE(D7:D37) -> 0.34428571 | F38: =AVERAGE(F7:F37) -> 0.46672857 | G38: =AVERAGE(G7:G37) -> 5584.0221 | H38: =AVERAGE(H7:H37) -> 0.55678571 | J38: =SUMIFS(J7:J37,J7:J37,">0") -> 0 | L38: =SUMIFS(L7:L37,L7:L37,">0") -> 234643 | O38: =SUM(O7:O37) -> 0 | Q38: =SUMIFS(Q7:Q37,Q7:Q37,">0") -> 0 | R38: =SUM(R7:R37) -> 2945 | S38: =SUM(S7:S37) -> 3860 | T38: =SUM(T7:T37) -> 6805 | W38: =SUM(W7:W37) -> 156609 | X38: =SUM(X7:X37) -> 6.39 | Y38: =SUM(Y7:Y37) -> 0 | Z38: =SUM(Z7:Z37) -> 10.18 | AA38: =SUM(AA7:AA37) -> 182.01 | AB38: =SUM(AB7:AB37) -> 0 | AD38: =AVERAGE(AD7:AD37) -> #DIV/0! | AE38: =SUM(AE7:AE37) -> 3340.17 | AH38: =SUM(AH7:AH37) -> 0 | AJ38: =SUM(AJ7:AJ37) -> 0

Sheet Jun2022
B2: Note: Recording should be done 1st hour of the day
B3: DAILY BIOGAS USAGE MONITORING | AF3: SBVC RECORD | AI3: DPO RECORD (Lowela) | AK3: Biogas Operation Utility Consumption | AQ3: Remarks/ Shifts
B4: Date | C4: Day | D4: Gas Storage (%) | H4: Quality | I4: Gas Meters (Nmᶾ) | Q4: Gas Flare | T4: Gas Engine Power Meter (kWh) | V4: Diesel Fuel Consumption | Y4: Biogas Fuel Consumption | AB4: Ope. Hrs w/ Diesel | AD4: Ope. Hrs w/ Biogas | AF4: Waste Hauling Operation | AI4: Waste Hauling Operation
D5: F1 | E5: F2 | F5: F3 | G5: Total | H5: Methane Content | I5: Gas Engine 1 Totalizer | K5: Gas Engine 2 Totalizer | M5: Thermax 1 Consumption | O5: Thermax 2 Consumption | Q5: Time | S5: Total Volume | V5: Thermax 1 | W5: Thermax 2 | X5: Total | Y5: Thermax 1 | Z5: Thermax 2 | AA5: Total | AB5: Thermax 1 | AC5: Thermax 2 | AD5: Thermax 1 | AE5: Thermax 2 | AF5: Actual Waste Delivered (MT) | AH5: DS | AI5: Actual Waste Delivered (MT) | AK5: Electricity @ Biogas plant, kWhr | AM5: Electricity @ DPO cannery (Blower) , kWhr | AO5: Water, m3
D6: 8350 | E6: 8350 | F6: 8350 | G6: =D6+F6 -> 16700 | H6: 55% Min | I6: Totalizer | J6: Output | K6: Totalizer | L6: Output | M6: Totalizer | N6: Consumption | O6: Totalizer | P6: Consumption | Q6: Start | R6: End | S6: Nm³ | T6: Totalizer | U6: Output | V6: Li. | W6: Li. | X6: Li. | AB6: Hrs | AC6: Hrs | AD6: Hrs | AE6: Hrs | AF6: Delivery | AG6: Cummulative | AH6: % | AI6: Delivery | AJ6: Cummulative | AK6: Totalizer | AL6: Consumed | AM6: Totalizer | AN6: Consumed | AO6: Totalizer | AP6: Consumed
B7: 44713 | C7: =TEXT(B7,"ddd") -> Wed | D7: 0.85 | E7: 0.65 | F7: 0.41 | G7: =SUMPRODUCT($D$6:$F$6,D7:F7) -> 15948.5 | H7: 0.554 | J7: =I7-0 -> 0 | L7: =K7-0 -> 0 | O7: 254773 | P7: =O7-234643 -> 20130 | U7: =T7-0 -> 0 | W7: 1023 | X7: =SUM(V7:W7) -> 1023 | Z7: 19447 | AA7: =SUM(Y7:Z7) -> 19447 | AD7: 1.44 | AE7: 19.74 | AG7: =AF7 -> 0 | AI7: 316.11 | AJ7: =AI7 -> 316.11 | AQ7: 2
B8: =B7+1 -> 44714 | C8: =TEXT(B8,"ddd") -> Thu | D8: 0.84 | E8: 0.7 | F8: 0.56 | G8: =SUMPRODUCT($D$6:$F$6,D8:F8) -> 17535 | H8: 0.557 | J8: =I8-I7 -> 0 | L8: =K8-K7 -> 0 | O8: 276874 | P8: =O8-O7 -> 22101 | U8: =T8-T7 -> 0 | X8: =SUM(V8:W8) -> 0 | Z8: 21945 | AA8: =SUM(Y8:Z8) -> 21945 | AE8: 18.93 | AG8: =AF8+AG7 -> 0 | AI8: 268.31 | AJ8: =AI8+AJ7 -> 584.42 | AQ8: 2
B9: =B8+1 -> 44715 | C9: =TEXT(B9,"ddd") -> Fri | D9: 1 | E9: 0.74 | F9: 0.58 | G9: =SUMPRODUCT($D$6:$F$6,D9:F9) -> 19372 | H9: 0.561 | J9: =I9-I8 -> 0 | L9: =K9-K8 -> 0 | O9: 313193 | P9: =O9-O8 -> 36319 | U9: =T9-T8 -> 0 | X9: =SUM(V9:W9) -> 0 | Z9: 28446 | AA9: =SUM(Y9:Z9) -> 28446 | AE9: 22.81 | AG9: =AF9+AG8 -> 0 | AI9: 223.24 | AJ9: =AI9+AJ8 -> 807.66 | AQ9: 2
B10: =B9+1 -> 44716 | C10: =TEXT(B10,"ddd") -> Sat | D10: 0.56 | E10: 0.39 | F10: 0.01 | G10: =SUMPRODUCT($D$6:$F$6,D10:F10) -> 8016 | H10: 0.558 | J10: =I10-I9 -> 0 | L10: =K10-K9 -> 0 | O10: 336441 | P10: =O10-O9 -> 23248 | U10: =T10-T9 -> 0 | X10: =SUM(V10:W10) -> 0 | Z10: 31147 | AA10: =SUM(Y10:Z10) -> 31147 | AE10: 22.32 | AG10: =AF10+AG9 -> 0 | AI10: 228.65 | AJ10: =AI10+AJ9 -> 1036.31 | AQ10: 2
B11: =B10+1 -> 44717 | C11: =TEXT(B11,"ddd") -> Sun | D11: 0.06 | E11: 0.27 | F11: 0 | G11: =SUMPRODUCT($D$6:$F$6,D11:F11) -> 2755.5 | H11: 0.558 | J11: =I11-I10 -> 0 | L11: =K11-K10 -> 0 | O11: 342988 | P11: =O11-O10 -> 6547 | U11: =T11-T10 -> 0 | X11: =SUM(V11:W11) -> 0 | Z11: 7008 | AA11: =SUM(Y11:Z11) -> 7008 | AE11: 8.13 | AG11: =AF11+AG10 -> 0 | AI11: 0 | AJ11: =AI11+AJ10 -> 1036.31 | AQ11: no canning
B12: =B11+1 -> 44718 | C12: =TEXT(B12,"ddd") -> Mon | D12: 0.25 | E12: 1 | F12: 0.29 | G12: =SUMPRODUCT($D$6:$F$6,D12:F12) -> 12859 | H12: 0.567 | J12: =I12-I11 -> 0 | L12: =K12-K11 -> 0 | O12: 363921 | P12: =O12-O11 -> 20933 | U12: =T12-T11 -> 0 | X12: =SUM(V12:W12) -> 0 | Z12: 20084 | AA12: =SUM(Y12:Z12) -> 20084 | AE12: 22.46 | AG12: =AF12+AG11 -> 0 | AI12: 286.92 | AJ12: =AI12+AJ11 -> 1323.23 | AQ12: 2
B13: =B12+1 -> 44719 | C13: =TEXT(B13,"ddd") -> Tue | D13: 0.53 | E13: 0.6 | F13: 0 | G13: =SUMPRODUCT($D$6:$F$6,D13:F13) -> 9435.5 | H13: 0.568 | J13: =I13-I12 -> 0 | L13: =K13-K12 -> 0 | O13: 386162 | P13: =O13-O12 -> 22241 | U13: =T13-T12 -> 0 | X13: =SUM(V13:W13) -> 0 | Z13: 21273 | AA13: =SUM(Y13:Z13) -> 21273 | AE13: 23.87 | AG13: =AF13+AG12 -> 0 | AI13: 449.12 | AJ13: =AI13+AJ12 -> 1772.35 | AQ13: 2
B14: =B13+1 -> 44720 | C14: =TEXT(B14,"ddd") -> Wed | D14: 0.42 | E14: 0.44 | F14: 0.86 | G14: =SUMPRODUCT($D$6:$F$6,D14:F14) -> 14362 | H14: 0.562 | J14: =I14-I13 -> 0 | L14: =K14-K13 -> 0 | O14: 414353 | P14: =O14-O13 -> 28191 | U14: =T14-T13 -> 0 | X14: =SUM(V14:W14) -> 0 | Z14: 27690 | AA14: =SUM(Y14:Z14) -> 27690 | AE14: 23.79 | AG14: =AF14+AG13 -> 0 | AI14: 331.83 | AJ14: =AI14+AJ13 -> 2104.18 | AQ14: 2
B15: =B14+1 -> 44721 | C15: =TEXT(B15,"ddd") -> Thu | D15: 0.75 | E15: 0.74 | F15: 0.98 | G15: =SUMPRODUCT($D$6:$F$6,D15:F15) -> 20624.5 | H15: 0.556 | J15: =I15-I14 -> 0 | L15: =K15-K14 -> 0 | O15: 452345 | P15: =O15-O14 -> 37992 | U15: =T15-T14 -> 0 | X15: =SUM(V15:W15) -> 0 | Z15: 38408 | AA15: =SUM(Y15:Z15) -> 38408 | AE15: 23.43 | AG15: =AF15+AG14 -> 0 | AI15: 339.07 | AJ15: =AI15+AJ14 -> 2443.25 | AQ15: 2
B16: =B15+1 -> 44722 | C16: =TEXT(B16,"ddd") -> Fri | D16: 0.37 | E16: 0.48 | F16: 0.62 | G16: =SUMPRODUCT($D$6:$F$6,D16:F16) -> 12274.5 | H16: 0.564 | J16: =I16-I15 -> 0 | L16: =K16-K15 -> 0 | O16: 482221 | P16: =O16-O15 -> 29876 | U16: =T16-T15 -> 0 | X16: =SUM(V16:W16) -> 0 | Z16: 29826 | AA16: =SUM(Y16:Z16) -> 29826 | AE16: 24.14 | AG16: =AF16+AG15 -> 0 | AI16: 304.67 | AJ16: =AI16+AJ15 -> 2747.92 | AQ16: 2
B17: =B16+1 -> 44723 | C17: =TEXT(B17,"ddd") -> Sat | D17: 0.42 | E17: 0.53 | F17: 0.5 | G17: =SUMPRODUCT($D$6:$F$6,D17:F17) -> 12107.5 | H17: 0.571 | J17: =I17-I16 -> 0 | L17: =K17-K16 -> 0 | O17: 505566 | P17: =O17-O16 -> 23345 | U17: =T17-T16 -> 0 | X17: =SUM(V17:W17) -> 0 | Z17: 25649 | AA17: =SUM(Y17:Z17) -> 25649 | AE17: 19.5 | AG17: =AF17+AG16 -> 0 | AI17: 178.08 | AJ17: =AI17+AJ16 -> 2926 | AQ17: 1
B18: =B17+1 -> 44724 | C18: =TEXT(B18,"ddd") -> Sun | D18: 0.08 | E18: 0.69 | F18: 0.47 | G18: =SUMPRODUCT($D$6:$F$6,D18:F18) -> 10354 | H18: 0.571 | J18: =I18-I17 -> 0 | L18: =K18-K17 -> 0 | O18: 507310 | P18: =O18-O17 -> 1744 | U18: =T18-T17 -> 0 | X18: =SUM(V18:W18) -> 0 | Z18: 0 | AA18: =SUM(Y18:Z18) -> 0 | AE18: 0 | AG18: =AF18+AG17 -> 0 | AI18: 0 | AJ18: =AI18+AJ17 -> 2926 | AQ18: no canning
B19: =B18+1 -> 44725 | C19: =TEXT(B19,"ddd") -> Mon | D19: 0.84 | E19: 0.97 | F19: 0.76 | G19: =SUMPRODUCT($D$6:$F$6,D19:F19) -> 21459.5 | H19: 0.567 | J19: =I19-I18 -> 0 | L19: =K19-K18 -> 0 | O19: 524854 | P19: =O19-O18 -> 17544 | U19: =T19-T18 -> 0 | X19: =SUM(V19:W19) -> 0 | Z19: 19288 | AA19: =SUM(Y19:Z19) -> 19288 | AE19: 16.88 | AG19: =AF19+AG18 -> 0 | AI19: 136.66 | AJ19: =AI19+AJ18 -> 3062.66 | AQ19: 1
B20: =B19+1 -> 44726 | C20: =TEXT(B20,"ddd") -> Tue | D20: 0.07 | E20: 1 | F20: 0.56 | G20: =SUMPRODUCT($D$6:$F$6,D20:F20) -> 13610.5 | H20: 0.565 | J20: =I20-I19 -> 0 | L20: =K20-K19 -> 0 | O20: 544085 | P20: =O20-O19 -> 19231 | U20: =T20-T19 -> 0 | X20: =SUM(V20:W20) -> 0 | Z20: 17880 | AA20: =SUM(Y20:Z20) -> 17880 | AE20: 21.6 | AG20: =AF20+AG19 -> 0 | AI20: 346.2 | AJ20: =AI20+AJ19 -> 3408.86 | AQ20: 2
B21: =B20+1 -> 44727 | C21: =TEXT(B21,"ddd") -> Wed | D21: 0.22 | E21: 1 | F21: 0.52 | G21: =SUMPRODUCT($D$6:$F$6,D21:F21) -> 14529 | H21: 0.554 | J21: =I21-I20 -> 0 | L21: =K21-K20 -> 0 | O21: 571791 | P21: =O21-O20 -> 27706 | U21: =T21-T20 -> 0 | X21: =SUM(V21:W21) -> 0 | Z21: 27028 | AA21: =SUM(Y21:Z21) -> 27028 | AE21: 23.89 | AG21: =AF21+AG20 -> 0 | AI21: 364.76 | AJ21: =AI21+AJ20 -> 3773.62 | AQ21: 2
B22: =B21+1 -> 44728 | C22: =TEXT(B22,"ddd") -> Thu | D22: 0.48 | E22: 0.83 | F22: 0.45 | G22: =SUMPRODUCT($D$6:$F$6,D22:F22) -> 14696 | H22: 0.561 | J22: =I22-I21 -> 0 | L22: =K22-K21 -> 0 | O22: 599069 | P22: =O22-O21 -> 27278 | U22: =T22-T21 -> 0 | X22: =SUM(V22:W22) -> 0 | Z22: 28126 | AA22: =SUM(Y22:Z22) -> 28126 | AE22: 23.79 | AG22: =AF22+AG21 -> 0 | AI22: 281.23 | AJ22: =AI22+AJ21 -> 4054.85 | AQ22: 1
B23: =B22+1 -> 44729 | C23: =TEXT(B23,"ddd") -> Fri | D23: 0.66 | E23: 0.82 | F23: 0.38 | G23: =SUMPRODUCT($D$6:$F$6,D23:F23) -> 15531 | H23: 0.559 | J23: =I23-I22 -> 0 | L23: =K23-K22 -> 0 | O23: 623702 | P23: =O23-O22 -> 24633 | U23: =T23-T22 -> 0 | V23: 290 | W23: 324 | X23: =SUM(V23:W23) -> 614 | Z23: 22655 | AA23: =SUM(Y23:Z23) -> 22655 | AB23: 0.95 | AD23: 1.22 | AE23: 22.17 | AG23: =AF23+AG22 -> 0 | AI23: 378.56 | AJ23: =AI23+AJ22 -> 4433.41 | AQ23: 2
B24: =B23+1 -> 44730 | C24: =TEXT(B24,"ddd") -> Sat | D24: 0.88 | E24: 0.53 | F24: 0.49 | G24: =SUMPRODUCT($D$6:$F$6,D24:F24) -> 15865 | H24: 0.556 | J24: =I24-I23 -> 0 | L24: =K24-K23 -> 0 | O24: 639167 | P24: =O24-O23 -> 15465 | U24: =T24-T23 -> 0 | X24: =SUM(V24:W24) -> 0 | Z24: 11624 | AA24: =SUM(Y24:Z24) -> 11624 | AE24: 9.14 | AG24: =AF24+AG23 -> 0 | AI24: 0 | AJ24: =AI24+AJ23 -> 4433.41 | AQ24: 1
B25: =B24+1 -> 44731 | C25: =TEXT(B25,"ddd") -> Sun | D25: 0.66 | E25: 0.82 | F25: 0.38 | G25: =SUMPRODUCT($D$6:$F$6,D25:F25) -> 15531 | H25: 0.561 | J25: =I25-I24 -> 0 | L25: =K25-K24 -> 0 | O25: 643523 | P25: =O25-O24 -> 4356 | U25: =T25-T24 -> 0 | X25: =SUM(V25:W25) -> 0 | Z25: 0 | AA25: =SUM(Y25:Z25) -> 0 | AE25: 0 | AG25: =AF25+AG24 -> 0 | AI25: 0 | AJ25: =AI25+AJ24 -> 4433.41 | AQ25: no canning
B26: =B25+1 -> 44732 | C26: =TEXT(B26,"ddd") -> Mon | D26: 0.48 | E26: 0.11 | F26: 0.21 | G26: =SUMPRODUCT($D$6:$F$6,D26:F26) -> 6680 | H26: 0.554 | J26: =I26-I25 -> 0 | L26: =K26-K25 -> 0 | O26: 645239 | P26: =O26-O25 -> 1716 | U26: =T26-T25 -> 0 | X26: =SUM(V26:W26) -> 0 | Z26: 12976 | AA26: =SUM(Y26:Z26) -> 12976 | AE26: 11.03 | AG26: =AF26+AG25 -> 0 | AI26: 0 | AJ26: =AI26+AJ25 -> 4433.41 | AQ26: no canning
B27: =B26+1 -> 44733 | C27: =TEXT(B27,"ddd") -> Tue | D27: 1 | E27: 0.24 | F27: 0.31 | G27: =SUMPRODUCT($D$6:$F$6,D27:F27) -> 12942.5 | H27: 0.554 | J27: =I27-I26 -> 0 | L27: =K27-K26 -> 0 | O27: 651232 | P27: =O27-O26 -> 5993 | U27: =T27-T26 -> 0 | X27: =SUM(V27:W27) -> 0 | Z27: 5396 | AA27: =SUM(Y27:Z27) -> 5396 | AE27: 6.2 | AG27: =AF27+AG26 -> 0 | AI27: 250.41 | AJ27: =AI27+AJ26 -> 4683.82 | AQ27: 1
B28: =B27+1 -> 44734 | C28: =TEXT(B28,"ddd") -> Wed | D28: 1 | E28: 0.37 | F28: 0.01 | G28: =SUMPRODUCT($D$6:$F$6,D28:F28) -> 11523 | H28: 0.558 | J28: =I28-I27 -> 0 | L28: =K28-K27 -> 0 | O28: 660348 | P28: =O28-O27 -> 9116 | U28: =T28-T27 -> 0 | X28: =SUM(V28:W28) -> 0 | Z28: 11209 | AA28: =SUM(Y28:Z28) -> 11209 | AE28: 14.01 | AG28: =AF28+AG27 -> 0 | AI28: 323.97 | AJ28: =AI28+AJ27 -> 5007.79 | AQ28: 2
B29: =B28+1 -> 44735 | C29: =TEXT(B29,"ddd") -> Thu | D29: 0.96 | E29: 0.52 | F29: 0.44 | G29: =SUMPRODUCT($D$6:$F$6,D29:F29) -> 16032 | H29: 0.563 | J29: =I29-I28 -> 0 | L29: =K29-K28 -> 0 | O29: 683457 | P29: =O29-O28 -> 23109 | U29: =T29-T28 -> 0 | X29: =SUM(V29:W29) -> 0 | Z29: 21709 | AA29: =SUM(Y29:Z29) -> 21709 | AE29: 22.61 | AG29: =AF29+AG28 -> 0 | AI29: 296.67 | AJ29: =AI29+AJ28 -> 5304.46 | AQ29: 2
B30: =B29+1 -> 44736 | C30: =TEXT(B30,"ddd") -> Fri | D30: 0 | E30: 0.81 | F30: 0.71 | G30: =SUMPRODUCT($D$6:$F$6,D30:F30) -> 12692 | H30: 0.563 | J30: =I30-I29 -> 0 | L30: =K30-K29 -> 0 | O30: 695339 | P30: =O30-O29 -> 11882 | U30: =T30-T29 -> 0 | X30: =SUM(V30:W30) -> 0 | Z30: 10497 | AA30: =SUM(Y30:Z30) -> 10497 | AE30: 12.99 | AG30: =AF30+AG29 -> 0 | AI30: 354.61 | AJ30: =AI30+AJ29 -> 5659.07 | AQ30: 2
B31: =B30+1 -> 44737 | C31: =TEXT(B31,"ddd") -> Sat | D31: 0.37 | E31: 0.64 | F31: 0.91 | G31: =SUMPRODUCT($D$6:$F$6,D31:F31) -> 16032 | H31: 0.566 | J31: =I31-I30 -> 0 | L31: =K31-K30 -> 0 | O31: 720683 | P31: =O31-O30 -> 25344 | U31: =T31-T30 -> 0 | X31: =SUM(V31:W31) -> 0 | Z31: 23662 | AA31: =SUM(Y31:Z31) -> 23662 | AE31: 23.69 | AG31: =AF31+AG30 -> 0 | AI31: 310.86 | AJ31: =AI31+AJ30 -> 5969.93 | AQ31: 1
B32: =B31+1 -> 44738 | C32: =TEXT(B32,"ddd") -> Sun | D32: 0.28 | E32: 0.48 | F32: 0.63 | G32: =SUMPRODUCT($D$6:$F$6,D32:F32) -> 11606.5 | H32: 0.566 | J32: =I32-I31 -> 0 | L32: =K32-K31 -> 0 | O32: 734498 | P32: =O32-O31 -> 13815 | U32: =T32-T31 -> 0 | X32: =SUM(V32:W32) -> 0 | Z32: 16576 | AA32: =SUM(Y32:Z32) -> 16576 | AE32: 17.22 | AG32: =AF32+AG31 -> 0 | AI32: 0 | AJ32: =AI32+AJ31 -> 5969.93 | AQ32: no canning
B33: =B32+1 -> 44739 | C33: =TEXT(B33,"ddd") -> Mon | D33: 0.18 | E33: 0.61 | F33: 0.76 | G33: =SUMPRODUCT($D$6:$F$6,D33:F33) -> 12942.5 | H33: 0.567 | J33: =I33-I32 -> 0 | L33: =K33-K32 -> 0 | O33: 742078 | P33: =O33-O32 -> 7580 | U33: =T33-T32 -> 0 | X33: =SUM(V33:W33) -> 0 | Z33: 7885 | AA33: =SUM(Y33:Z33) -> 7885 | AE33: 13.03 | AG33: =AF33+AG32 -> 0 | AI33: 0 | AJ33: =AI33+AJ32 -> 5969.93 | AQ33: no canning
B34: =B33+1 -> 44740 | C34: =TEXT(B34,"ddd") -> Tue | D34: 0.44 | E34: 0.94 | F34: 0.37 | G34: =SUMPRODUCT($D$6:$F$6,D34:F34) -> 14612.5 | H34: 0.562 | J34: =I34-I33 -> 0 | L34: =K34-K33 -> 0 | O34: 762549 | P34: =O34-O33 -> 20471 | U34: =T34-T33 -> 0 | V34: 3006 | X34: =SUM(V34:W34) -> 3006 | Z34: 19564 | AA34: =SUM(Y34:Z34) -> 19564 | AB34: 7.06 | AE34: 20.16 | AG34: =AF34+AG33 -> 0 | AI34: 289 | AJ34: =AI34+AJ33 -> 6258.93 | AQ34: 2
B35: =B34+1 -> 44741 | C35: =TEXT(B35,"ddd") -> Wed | D35: 0.22 | E35: 0.2 | F35: 0.09 | G35: =SUMPRODUCT($D$6:$F$6,D35:F35) -> 4258.5 | H35: 0.563 | J35: =I35-I34 -> 0 | L35: =K35-K34 -> 0 | O35: 770416 | P35: =O35-O34 -> 7867 | V35: 210 | X35: =SUM(V35:W35) -> 210 | Z35: 8775 | AA35: =SUM(Y35:Z35) -> 8775 | AB35: 0.87 | AE35: 12.05 | AG35: =AF35+AG34 -> 0 | AI35: 197.4 | AJ35: =AI35+AJ34 -> 6456.33 | AQ35: 2
B36: =B35+1 -> 44742 | C36: =TEXT(B36,"ddd") -> Thu | D36: 0.53 | E36: 0.26 | F36: 0.43 | G36: =SUMPRODUCT($D$6:$F$6,D36:F36) -> 10187 | H36: 0.557 | J36: =I36-I35 -> 0 | L36: =K36-K35 -> 0 | O36: 791580 | P36: =O36-O35 -> 21164 | U36: =T36-T35 -> 0 | V36: 0 | W36: 430 | X36: =SUM(V36:W36) -> 430 | Z36: 20431 | AA36: =SUM(Y36:Z36) -> 20431 | AB36: 0 | AC36: 0.56 | AE36: 21.52 | AG36: =AF36+AG35 -> 0 | AI36: 318.27 | AJ36: =AI36+AJ35 -> 6774.6 | AQ36: 2
B37: Total/Average | D37: =AVERAGE(D7:D36) -> 0.51333333 | F37: =AVERAGE(F7:F36) -> 0.45633333 | G37: =AVERAGE(G7:G36) -> 13212.483 | H37: =AVERAGE(H7:H36) -> 0.56143333 | J37: =SUMIFS(J7:J36,J7:J36,">0") -> 0 | P37: =SUMIFS(P7:P36,P7:P36,">0") -> 556937 | S37: =SUM(S7:S36) -> 0 | U37: =SUMIFS(U7:U36,U7:U36,">0") -> 0 | V37: =SUM(V7:V36) -> 3506 | W37: =SUM(W7:W36) -> 1777 | X37: =SUM(X7:X36) -> 5283 | AA37: =SUM(AA7:AA36) -> 556204 | AB37: =SUM(AB7:AB36) -> 8.88 | AC37: =SUM(AC7:AC36) -> 0.56 | AD37: =SUM(AD7:AD36) -> 2.66 | AE37: =SUM(AE7:AE36) -> 521.1 | AF37: =SUM(AF7:AF36) -> 0 | AH37: =AVERAGE(AH7:AH36) -> #DIV/0! | AI37: =SUM(AI7:AI36) -> 6774.6 | AL37: =SUM(AL7:AL36) -> 0 | AN37: =SUM(AN7:AN36) -> 0

Sheet Jul2022
B2: Note: Recording should be done 1st hour of the day
B3: DAILY BIOGAS USAGE MONITORING | AD3: SBVC RECORD | AG3: DPO RECORD (Lowela) | AI3: JANETTE'S RECORD | AL3: Biogas Operation Utility Consumption | AR3: Remarks/ Shifts
B4: Date | C4: Day | D4: Gas Storage (%) | H4: Quality | I4: Gas Meters (Nmᶾ) | M4: Gas Flare | P4: Gas Engine 1 Power Meter (kWh) | R4: Gas Engine 2 Power Meter (kWh) | T4: Diesel Fuel Consumption | W4: Biogas Fuel Consumption | Z4: Ope. Hrs w/ Diesel | AB4: Ope. Hrs w/ Biogas | AD4: Waste Hauling Operation | AG4: Waste Hauling Operation | AI4: Waste Hauling Operation
D5: F1 | E5: F2 | F5: F3 | G5: Total | H5: Methane Content | I5: Thermax 1 Consumption | K5: Thermax 2 Consumption | M5: Time | O5: Total Volume | T5: Thermax 1 | U5: Thermax 2 | V5: Total | W5: Thermax 1 | X5: Thermax 2 | Y5: Total | Z5: Thermax 1 | AA5: Thermax 2 | AB5: Thermax 1 | AC5: Thermax 2 | AD5: Actual Waste Delivered (MT) | AF5: DS | AG5: Actual Waste Delivered (MT) | AI5: Cannery Waste to Biogas, MT | AJ5: Other Fruit Waste to Biogas, MT | AK5: Total Waste to Biogas, MT | AL5: Electricity @ Biogas plant, kWhr | AN5: Electricity @ DPO cannery (Blower) , kWhr | AP5: Water, m3
D6: 8350 | E6: 8350 | F6: 8350 | G6: =D6+E6+F6 -> 25050 | H6: 55% Min | I6: Totalizer | J6: Output | K6: Totalizer | L6: Output | M6: Start | N6: End | O6: Nm³ | P6: Totalizer | Q6: Output | R6: Totalizer | S6: Output | T6: Li. | U6: Li. | V6: Li. | Z6: Hrs | AA6: Hrs | AB6: Hrs | AC6: Hrs | AD6: Delivery | AE6: Cummulative | AF6: % | AG6: Delivery | AH6: Cummulative | AL6: Totalizer | AM6: Consumed | AN6: Totalizer | AO6: Consumed | AP6: Totalizer | AQ6: Consumed
B7: 44743 | C7: =TEXT(B7,"ddd") -> Fri | D7: 0.17 | E7: 0.59 | F7: 0.77 | G7: =SUMPRODUCT(D7:F7,$D$6:$F$6) -> 12775.5 | H7: 0.559 | J7: =I7-0 -> 0 | K7: 813362 | L7: =K7-791580 -> 21782 | P7: 3331 | Q7: =P7-3331 -> 0 | R7: 3374 | S7: =R7-3374 -> 0 | T7: 243 | U7: 0 | V7: =SUM(T7:U7) -> 243 | W7: 0 | X7: 21424 | Y7: =SUM(W7:X7) -> 21424 | Z7: 0.8 | AA7: 0 | AB7: 0 | AC7: 19.03 | AD7: 358.8 | AE7: =AD7 -> 358.8 | AF7: 15.62 | AG7: 358.8 | AH7: =AG7 -> 358.8 | AI7: 358.8 | AK7: 358.8 | AL7: 137896 | AM7: =AL7-135932 -> 1964 | AN7: 14699 | AO7: =AN7-14699 -> 0
B8: =B7+1 -> 44744 | C8: =TEXT(B8,"ddd") -> Sat | D8: 0.05 | E8: 0.37 | F8: 0.46 | G8: =SUMPRODUCT(D8:F8,$D$6:$F$6) -> 7348 | H8: 0.561 | J8: =I8-I7 -> 0 | K8: 833102 | L8: =K8-K7 -> 19740 | P8: 3331 | Q8: =P8-P7 -> 0 | R8: 3374 | S8: =R8-R7 -> 0 | T8: 155 | U8: 0 | V8: =SUM(T8:U8) -> 155 | W8: 0 | X8: 32461 | Y8: =SUM(W8:X8) -> 32461 | Z8: 0.55 | AA8: 0 | AB8: 0 | AC8: 24.04 | AD8: 347.78 | AE8: =AD8+AE7 -> 706.58 | AF8: 16.12 | AG8: 347.78 | AH8: =AG8+AH7 -> 706.58 | AI8: 347.78 | AK8: 347.78 | AL8: 140474 | AM8: =AL8-AL7 -> 2578 | AN8: 15301 | AO8: =AN8-AN7 -> 602 | AR8: 2
B9: =B8+1 -> 44745 | C9: =TEXT(B9,"ddd") -> Sun | D9: 0.45 | E9: 1 | F9: 0.83 | G9: =SUMPRODUCT(D9:F9,$D$6:$F$6) -> 19038 | H9: 0.561 | J9: =I9-I8 -> 0 | K9: 857356 | L9: =K9-K8 -> 24254 | P9: 3331 | Q9: =P9-P8 -> 0 | R9: 3374 | S9: =R9-R8 -> 0 | T9: 0 | U9: 0 | V9: =SUM(T9:U9) -> 0 | W9: 0 | X9: 8895 | Y9: =SUM(W9:X9) -> 8895 | Z9: 0 | AA9: 0 | AB9: 0 | AC9: 7.62 | AE9: =AD9+AE8 -> 706.58 | AG9: 0 | AH9: =AG9+AH8 -> 706.58 | AI9: 0 | AK9: 0 | AL9: 143166 | AM9: =AL9-AL8 -> 2692 | AN9: 15642 | AO9: =AN9-AN8 -> 341 | AR9: 2
B10: =B9+1 -> 44746 | C10: =TEXT(B10,"ddd") -> Mon | D10: 0.24 | E10: 0.37 | F10: 0.71 | G10: =SUMPRODUCT(D10:F10,$D$6:$F$6) -> 11022 | H10: 0.564 | J10: =I10-I9 -> 0 | K10: 877747 | L10: =K10-K9 -> 20391 | P10: 3331 | Q10: =P10-P9 -> 0 | R10: 3374 | S10: =R10-R9 -> 0 | T10: 172 | U10: 438 | V10: =SUM(T10:U10) -> 610 | W10: 0 | X10: 23293 | Y10: =SUM(W10:X10) -> 23293 | Z10: 0.57 | AA10: 1.26 | AB10: 0 | AC10: 22.53 | AD10: 141.16 | AE10: =AD10+AE9 -> 847.74 | AF10: 6.91 | AG10: 141.16 | AH10: =AG10+AH9 -> 847.74 | AI10: 141.16 | AJ10: 5.996 | AK10: 147.156 | AL10: 144780 | AM10: =AL10-AL9 -> 1614 | AN10: 15989 | AO10: =AN10-AN9 -> 347 | AR10: 1
B11: =B10+1 -> 44747 | C11: =TEXT(B11,"ddd") -> Tue | D11: 0.07 | E11: 0.15 | F11: 0.14 | G11: =SUMPRODUCT(D11:F11,$D$6:$F$6) -> 3006 | H11: 0.558 | J11: =I11-I10 -> 0 | K11: 898865 | L11: =K11-K10 -> 21118 | P11: 3331 | Q11: =P11-P10 -> 0 | R11: 3374 | S11: =R11-R10 -> 0 | T11: 182 | U11: 0 | V11: =SUM(T11:U11) -> 182 | W11: 0 | X11: 20723 | Y11: =SUM(W11:X11) -> 20723 | Z11: 1.09 | AA11: 0 | AB11: 0 | AC11: 19.34 | AD11: 265.98 | AE11: =AD11+AE10 -> 1113.72 | AF11: 15.61 | AG11: 265.98 | AH11: =AG11+AH10 -> 1113.72 | AI11: 265.98 | AK11: 265.98 | AL11: 147114 | AM11: =AL11-AL10 -> 2334 | AN11: 16270 | AO11: =AN11-AN10 -> 281 | AR11: 2
B12: =B11+1 -> 44748 | C12: =TEXT(B12,"ddd") -> Wed | D12: 0.2 | E12: 0.39 | F12: 0.24 | G12: =SUMPRODUCT(D12:F12,$D$6:$F$6) -> 6930.5 | H12: 0.56 | J12: =I12-I11 -> 0 | K12: 915324 | L12: =K12-K11 -> 16459 | P12: 3331 | Q12: =P12-P11 -> 0 | R12: 3374 | S12: =R12-R11 -> 0 | T12: 6621 | U12: 0 | V12: =SUM(T12:U12) -> 6621 | W12: 0 | X12: 17391 | Y12: =SUM(W12:X12) -> 17391 | Z12: 12.05 | AA12: 0 | AB12: 0 | AC12: 21.98 | AD12: 271.98 | AE12: =AD12+AE11 -> 1385.7 | AF12: 15.87 | AG12: 271.98 | AH12: =AG12+AH11 -> 1385.7 | AI12: 271.98 | AK12: 271.98 | AL12: 149774 | AM12: =AL12-AL11 -> 2660 | AN12: 16632 | AO12: =AN12-AN11 -> 362 | AR12: 2
B13: =B12+1 -> 44749 | C13: =TEXT(B13,"ddd") -> Thu | D13: 0.24 | E13: 0.37 | F13: 0.36 | G13: =SUMPRODUCT(D13:F13,$D$6:$F$6) -> 8099.5 | H13: 0.56 | J13: =I13-I12 -> 0 | K13: 935700 | L13: =K13-K12 -> 20376 | P13: 3331 | Q13: =P13-P12 -> 0 | R13: 3374 | S13: =R13-R12 -> 0 | T13: 233 | U13: 0 | V13: =SUM(T13:U13) -> 233 | W13: 0 | X13: 20666 | Y13: =SUM(W13:X13) -> 20666 | Z13: 0.84 | AA13: 0 | AB13: 0 | AC13: 21.56 | AD13: 279.77 | AE13: =AD13+AE12 -> 1665.47 | AF13: 15.86 | AG13: 279.72 | AH13: =AG13+AH12 -> 1665.42 | AI13: 279.72 | AK13: 279.72 | AL13: 151426 | AM13: =AL13-AL12 -> 1652 | AN13: 16632 | AO13: =AN13-AN12 -> 0 | AR13: 2
B14: =B13+1 -> 44750 | C14: =TEXT(B14,"ddd") -> Fri | D14: 0.1 | E14: 0.24 | F14: 0.12 | G14: =SUMPRODUCT(D14:F14,$D$6:$F$6) -> 3841 | H14: 0.56 | J14: =I14-I13 -> 0 | K14: 939817 | L14: =K14-K13 -> 4117 | P14: 3331 | Q14: =P14-P13 -> 0 | R14: 3374 | S14: =R14-R13 -> 0 | T14: 4369 | U14: 0.21 | V14: =SUM(T14:U14) -> 4369.21 | W14: 0 | X14: 33455 | Y14: =SUM(W14:X14) -> 33455 | Z14: 9.01 | AA14: 0.21 | AB14: 0 | AC14: 22.76 | AD14: 294.2 | AE14: =AD14+AE13 -> 1959.67 | AF14: 15.83 | AG14: 294.2 | AH14: =AG14+AH13 -> 1959.62 | AI14: 294.2 | AJ14: 23.44 | AK14: 317.64 | AL14: 153305 | AM14: =AL14-AL13 -> 1879 | AN14: 16632 | AO14: =AN14-AN13 -> 0 | AR14: 2
B15: =B14+1 -> 44751 | C15: =TEXT(B15,"ddd") -> Sat | D15: 0.42 | E15: 0.91 | F15: 0.94 | G15: =SUMPRODUCT(D15:F15,$D$6:$F$6) -> 18954.5 | H15: 0.563 | J15: =I15-I14 -> 0 | K15: 969155 | L15: =K15-K14 -> 29338 | P15: 3331 | Q15: =P15-P14 -> 0 | R15: 3374 | S15: =R15-R14 -> 0 | T15: 0 | U15: 0 | V15: =SUM(T15:U15) -> 0 | W15: 0 | X15: 10810 | Y15: =SUM(W15:X15) -> 10810 | Z15: 0 | AA15: 0 | AB15: 0 | AC15: 8.39 | AE15: =AD15+AE14 -> 1959.67 | AG15: 0 | AH15: =AG15+AH14 -> 1959.62 | AI15: 0 | AK15: 0 | AL15: 154944 | AM15: =AL15-AL14 -> 1639 | AN15: 17251 | AO15: =AN15-AN14 -> 619 | AR15: no canning
B16: =B15+1 -> 44752 | C16: =TEXT(B16,"ddd") -> Sun | D16: 0.7 | E16: 0.96 | F16: 0.99 | G16: =SUMPRODUCT(D16:F16,$D$6:$F$6) -> 22127.5 | H16: 0.564 | J16: =I16-I15 -> 0 | K16: 979965 | L16: =K16-K15 -> 10810 | M16: 0.22569444 | N16: 0.64583333 | O16: 14509 | P16: 3331 | Q16: =P16-P15 -> 0 | R16: 3374 | S16: =R16-R15 -> 0 | T16: 0 | U16: 0 | V16: =SUM(T16:U16) -> 0 | W16: 0 | X16: 0 | Y16: =SUM(W16:X16) -> 0 | Z16: 0 | AA16: 0 | AB16: 0 | AC16: 0 | AE16: =AD16+AE15 -> 1959.67 | AG16: 0 | AH16: =AG16+AH15 -> 1959.62 | AI16: 0 | AK16: 0 | AL16: 156144 | AM16: =AL16-AL15 -> 1200 | AN16: 17563 | AO16: =AN16-AN15 -> 312 | AR16: no canning
B17: =B16+1 -> 44753 | C17: =TEXT(B17,"ddd") -> Mon | D17: 0.15 | E17: 0.05 | F17: 0.06 | G17: =SUMPRODUCT(D17:F17,$D$6:$F$6) -> 2171 | H17: 0.563 | J17: =I17-I16 -> 0 | K17: 1003827 | L17: =K17-K16 -> 23862 | P17: 3331 | Q17: =P17-P16 -> 0 | R17: 3374 | S17: =R17-R16 -> 0 | T17: 795 | U17: 0 | V17: =SUM(T17:U17) -> 795 | W17: 0 | X17: 23862 | Y17: =SUM(W17:X17) -> 23862 | Z17: 2.51 | AA17: 0 | AB17: 0 | AC17: 20.88 | AD17: 160.87 | AE17: =AD17+AE16 -> 2120.54 | AF17: 13.58 | AG17: 160.87 | AH17: =AG17+AH16 -> 2120.49 | AI17: 160.87 | AJ17: 3.868 | AK17: 164.738 | AL17: 157503 | AM17: =AL17-AL16 -> 1359 | AN17: 17798 | AO17: =AN17-AN16 -> 235 | AR17: 1
B18: =B17+1 -> 44754 | C18: =TEXT(B18,"ddd") -> Tue | D18: 0.11 | E18: 0.29 | F18: 0.36 | G18: =SUMPRODUCT(D18:F18,$D$6:$F$6) -> 6346 | H18: 0.563 | J18: =I18-I17 -> 0 | K18: 1013045 | L18: =K18-K17 -> 9218 | P18: 3331 | Q18: =P18-P17 -> 0 | R18: 3374 | S18: =R18-R17 -> 0 | T18: 11039 | U18: 1.02 | V18: =SUM(T18:U18) -> 11040.02 | W18: 0 | X18: 8229 | Y18: =SUM(W18:X18) -> 8229 | Z18: 18.42 | AA18: 1.02 | AB18: 0 | AC18: 14.36 | AD18: 273.81 | AE18: 2394.35 | AF18: 13.32 | AG18: 273.81 | AH18: =AG18+AH17 -> 2394.3 | AI18: 273.81 | AJ18: 18.642 | AK18: 292.452 | AL18: 159716 | AM18: =AL18-AL17 -> 2213 | AN18: 17931 | AO18: =AN18-AN17 -> 133 | AR18: 2
B19: =B18+1 -> 44755 | C19: =TEXT(B19,"ddd") -> Wed | D19: 0.19 | E19: 0.73 | F19: 0.67 | G19: =SUMPRODUCT(D19:F19,$D$6:$F$6) -> 13276.5 | H19: 0.568 | J19: =I19-I18 -> 0 | K19: 1019571 | L19: =K19-K18 -> 6526 | P19: 3331 | Q19: =P19-P18 -> 0 | R19: 3374 | S19: =R19-R18 -> 0 | T19: 14425 | U19: 2851 | V19: =SUM(T19:U19) -> 17276 | W19: 0 | X19: 7515 | Y19: =SUM(W19:X19) -> 7515 | Z19: 17.23 | AA19: 6.23 | AC19: 11.92 | AD19: 269.7 | AE19: 2664.05 | AF19: 15.76 | AG19: 269.72 | AH19: =AG19+AH18 -> 2664.02 | AI19: 269.72 | AJ19: 18.552 | AK19: 288.272 | AL19: 161717 | AM19: =AL19-AL18 -> 2001 | AN19: 18207 | AO19: =AN19-AN18 -> 276 | AR19: 2
B20: =B19+1 -> 44756 | C20: =TEXT(B20,"ddd") -> Thu | D20: 0.28 | E20: 0.05 | F20: 0.84 | G20: =SUMPRODUCT(D20:F20,$D$6:$F$6) -> 9769.5 | H20: 0.567 | J20: =I20-I19 -> 0 | K20: 1036096 | L20: =K20-K19 -> 16525 | P20: 3331 | Q20: =P20-P19 -> 0 | R20: 3374 | S20: =R20-R19 -> 0 | T20: 8901 | U20: 235 | V20: =SUM(T20:U20) -> 9136 | W20: 0 | X20: 15821 | Y20: =SUM(W20:X20) -> 15821 | Z20: 16.92 | AA20: 0.35 | AC20: 21.39 | AD20: 274.99 | AE20: =AD20+AE19 -> 2939.04 | AF20: 16.11 | AG20: 256.76 | AH20: =AG20+AH19 -> 2920.78 | AI20: 256.76 | AK20: 256.76 | AL20: 164102 | AM20: =AL20-AL19 -> 2385 | AN20: 18482 | AO20: =AN20-AN19 -> 275 | AR20: 2
B21: =B20+1 -> 44757 | C21: =TEXT(B21,"ddd") -> Fri | D21: 0.14 | E21: 0.45 | F21: 0.55 | G21: =SUMPRODUCT(D21:F21,$D$6:$F$6) -> 9519 | H21: 0.564 | J21: =I21-I20 -> 0 | K21: 1051910 | L21: =K21-K20 -> 15814 | P21: 3331 | Q21: =P21-P20 -> 0 | R21: 3374 | S21: =R21-R20 -> 0 | T21: 10162 | U21: 0 | V21: =SUM(T21:U21) -> 10162 | W21: 0 | X21: 16528 | Y21: =SUM(W21:X21) -> 16528 | Z21: 17.18 | AA21: 0 | AC21: 24.33 | AD21: 324.17 | AE21: =AD21+AE20 -> 3263.21 | AF21: 14.75 | AG21: 324.66 | AH21: =AG21+AH20 -> 3245.44 | AI21: 324.66 | AK21: 324.66 | AL21: 166822 | AM21: =AL21-AL20 -> 2720 | AN21: 18482 | AO21: =AN21-AN20 -> 0 | AR21: 2
B22: =B21+1 -> 44758 | C22: =TEXT(B22,"ddd") -> Sat | D22: 0.29 | E22: 0.3 | F22: 0.18 | G22: =SUMPRODUCT(D22:F22,$D$6:$F$6) -> 6429.5 | H22: 0.564 | J22: =I22-I21 -> 0 | K22: 1076687 | L22: =K22-K21 -> 24777 | P22: 3331 | Q22: =P22-P21 -> 0 | R22: 3374 | S22: =R22-R21 -> 0 | T22: 12481 | U22: 0 | V22: =SUM(T22:U22) -> 12481 | W22: 0 | X22: 24767 | Y22: =SUM(W22:X22) -> 24767 | Z22: 21.44 | AA22: 0 | AC22: 23.94 | AD22: 274.13 | AE22: =AD22+AE21 -> 3537.34 | AF22: 15.49 | AG22: 271.17 | AH22: =AG22+AH21 -> 3516.61 | AI22: 271.17 | AK22: 271.17 | AL22: 169223 | AM22: =AL22-AL21 -> 2401 | AN22: 19116 | AO22: =AN22-AN21 -> 634 | AR22: 2
B23: =B22+1 -> 44759 | C23: =TEXT(B23,"ddd") -> Sun | D23: 0.2 | E23: 0.14 | F23: 0.19 | G23: =SUMPRODUCT(D23:F23,$D$6:$F$6) -> 4425.5 | H23: 0.56 | J23: =I23-I22 -> 0 | K23: 1092637 | L23: =K23-K22 -> 15950 | P23: 3331 | Q23: =P23-P22 -> 0 | R23: 3374 | S23: =R23-R22 -> 0 | T23: 9163 | U23: 0 | V23: =SUM(T23:U23) -> 9163 | W23: 0 | X23: 15950 | Y23: =SUM(W23:X23) -> 15950 | Z23: 23.07 | AA23: 0 | AC23: 23.84 | AE23: =AD23+AE22 -> 3537.34 | AG23: 0 | AH23: =AG23+AH22 -> 3516.61 | AI23: 0 | AK23: 0 | AL23: 171743 | AM23: =AL23-AL22 -> 2520 | AN23: 19116 | AO23: =AN23-AN22 -> 0 | AR23: no canning
B24: =B23+1 -> 44760 | C24: =TEXT(B24,"ddd") -> Mon | D24: 0.26 | E24: 0.99 | F24: 0.53 | G24: =SUMPRODUCT(D24:F24,$D$6:$F$6) -> 14863 | H24: 0.561 | J24: =I24-I23 -> 0 | K24: 1101790 | L24: =K24-K23 -> 9153 | P24: 3331 | Q24: =P24-P23 -> 0 | R24: 3374 | S24: =R24-R23 -> 0 | T24: 23480 | U24: 14957 | V24: =SUM(T24:U24) -> 38437 | W24: 0 | X24: 8151 | Y24: =SUM(W24:X24) -> 8151 | Z24: 23.88 | AA24: 23.04 | AC24: 5.27 | AD24: 224.08 | AE24: =AD24+AE23 -> 3761.42 | AF24: 14.79 | AG24: 224.08 | AH24: =AG24+AH23 -> 3740.69 | AI24: 224.08 | AK24: 224.08 | AL24: 174227 | AM24: =AL24-AL23 -> 2484 | AN24: 19603 | AO24: =AN24-AN23 -> 487 | AR24: 2
B25: =B24+1 -> 44761 | C25: =TEXT(B25,"ddd") -> Tue | D25: 0.46 | E25: 0.46 | F25: 0.3124 | G25: =SUMPRODUCT(D25:F25,$D$6:$F$6) -> 10290.54 | H25: 0.557 | J25: =I25-I24 -> 0 | K25: 1125624 | L25: =K25-K24 -> 23834 | P25: 3331 | Q25: =P25-P24 -> 0 | R25: 3374 | S25: =R25-R24 -> 0 | T25: 8139 | U25: 13506 | V25: =SUM(T25:U25) -> 21645 | W25: 0 | X25: 23233 | Y25: =SUM(W25:X25) -> 23233 | Z25: 18.41 | AA25: 23.64 | AC25: 23.62 | AD25: 272.17 | AE25: =AD25+AE24 -> 4033.59 | AF25: 15.61 | AG25: 251.93 | AH25: =AG25+AH24 -> 3992.62 | AI25: 251.93 | AK25: 251.93 | AL25: 177018 | AM25: =AL25-AL24 -> 2791 | AN25: 19879 | AO25: =AN25-AN24 -> 276 | AR25: 2
B26: =B25+1 -> 44762 | C26: =TEXT(B26,"ddd") -> Wed | D26: 0.47 | E26: 0.51 | F26: 0.27 | G26: =SUMPRODUCT(D26:F26,$D$6:$F$6) -> 10437.5 | H26: 0.554 | J26: =I26-I25 -> 0 | K26: 1143323 | L26: =K26-K25 -> 17699 | P26: 3331 | Q26: =P26-P25 -> 0 | R26: 3374 | S26: =R26-R25 -> 0 | T26: 4521 | U26: 14589 | V26: =SUM(T26:U26) -> 19110 | W26: 0 | X26: 19302 | Y26: =SUM(W26:X26) -> 19302 | Z26: 12.87 | AA26: 22.68 | AC26: 22.68 | AD26: 270.03 | AE26: =AD26+AE25 -> 4303.62 | AF26: 16.1 | AG26: 270.13 | AH26: =AG26+AH25 -> 4262.75 | AI26: 270.13 | AK26: 270.13 | AL26: 181635 | AM26: =AL26-AL25 -> 4617 | AN26: 20188 | AO26: =AN26-AN25 -> 309 | AR26: 2
B27: =B26+1 -> 44763 | C27: =TEXT(B27,"ddd") -> Thu | D27: 0.56 | E27: 0.5 | F27: 0.44 | G27: =SUMPRODUCT(D27:F27,$D$6:$F$6) -> 12525 | H27: 0.556 | J27: =I27-I26 -> 0 | K27: 1166805 | L27: =K27-K26 -> 23482 | P27: 3331 | Q27: =P27-P26 -> 0 | R27: 3374 | S27: =R27-R26 -> 0 | T27: 6571 | U27: 12646 | V27: =SUM(T27:U27) -> 19217 | W27: 0 | X27: 23482 | Y27: =SUM(W27:X27) -> 23482 | Z27: 16.19 | AA27: 21.54 | AC27: 22.73 | AD27: 290.51 | AE27: =AD27+AE26 -> 4594.13 | AF27: 17.11 | AG27: 290.51 | AH27: =AG27+AH26 -> 4553.26 | AI27: 290.51 | AK27: 290.51 | AL27: 184988 | AM27: =AL27-AL26 -> 3353 | AN27: 20548 | AO27: =AN27-AN26 -> 360 | AR27: 2
B28: =B27+1 -> 44764 | C28: =TEXT(B28,"ddd") -> Fri | D28: 0.25 | E28: 0.27 | F28: 0.89 | G28: =SUMPRODUCT(D28:F28,$D$6:$F$6) -> 11773.5 | H28: 0.558 | J28: =I28-I27 -> 0 | K28: 1197037 | L28: =K28-K27 -> 30232 | P28: 3331 | Q28: =P28-P27 -> 0 | R28: 3374 | S28: =R28-R27 -> 0 | T28: 9171 | U28: 11178 | V28: =SUM(T28:U28) -> 20349 | W28: 0 | X28: 26795 | Y28: =SUM(W28:X28) -> 26795 | Z28: 18.31 | AA28: 20.38 | AC28: 23.84 | AD28: 288.95 | AE28: =AD28+AE27 -> 4883.08 | AF28: 16.52 | AG28: 288.93 | AH28: =AG28+AH27 -> 4842.19 | AI28: 288.93 | AK28: 288.93 | AL28: 188686 | AM28: =AL28-AL27 -> 3698 | AN28: 20548 | AO28: =AN28-AN27 -> 0 | AR28: 2
B29: =B28+1 -> 44765 | C29: =TEXT(B29,"ddd") -> Sat | D29: 0.15 | E29: 0.18 | F29: 0.12 | G29: =SUMPRODUCT(D29:F29,$D$6:$F$6) -> 3757.5 | H29: 0.558 | J29: =I29-I28 -> 0 | K29: 1224349 | L29: =K29-K28 -> 27312 | P29: 3331 | Q29: =P29-P28 -> 0 | R29: 3374 | S29: =R29-R28 -> 0 | T29: 12067 | U29: 0 | V29: =SUM(T29:U29) -> 12067 | W29: 0 | X29: 30749 | Y29: =SUM(W29:X29) -> 30749 | Z29: 22.97 | AA29: 0 | AC29: 23.63 | AD29: 257.08 | AE29: =AD29+AE28 -> 5140.16 | AF29: 16.38 | AG29: 279.09 | AH29: =AG29+AH28 -> 5121.28 | AI29: 279.09 | AK29: 279.09 | AL29: 191364 | AM29: =AL29-AL28 -> 2678 | AN29: 20548 | AO29: =AN29-AN28 -> 0 | AR29: 2
B30: =B29+1 -> 44766 | C30: =TEXT(B30,"ddd") -> Sun | D30: 0.22 | E30: 0.27 | F30: 0.28 | G30: =SUMPRODUCT(D30:F30,$D$6:$F$6) -> 6429.5 | H30: 0.56 | J30: =I30-I29 -> 0 | K30: 1246772 | L30: =K30-K29 -> 22423 | P30: 3331 | Q30: =P30-P29 -> 0 | R30: 3374 | S30: =R30-R29 -> 0 | T30: 1435 | U30: 0 | V30: =SUM(T30:U30) -> 1435 | W30: 0 | X30: 14615 | Y30: =SUM(W30:X30) -> 14615 | Z30: 2.25 | AA30: 0 | AC30: 17.25 | AE30: =AD30+AE29 -> 5140.16 | AG30: 0 | AH30: =AG30+AH29 -> 5121.28 | AI30: 0 | AK30: 0 | AL30: 193948 | AM30: =AL30-AL29 -> 2584 | AN30: 21514 | AO30: =AN30-AN29 -> 966 | AR30: no canning
B31: =B30+1 -> 44767 | C31: =TEXT(B31,"ddd") -> Mon | D31: 0.45 | E31: 0.15 | F31: 0.44 | G31: =SUMPRODUCT(D31:F31,$D$6:$F$6) -> 8684 | H31: 0.563 | J31: =I31-I30 -> 0 | K31: 1255676 | L31: =K31-K30 -> 8904 | P31: 3331 | Q31: =P31-P30 -> 0 | R31: 3374 | S31: =R31-R30 -> 0 | T31: 6345 | U31: 0 | V31: =SUM(T31:U31) -> 6345 | W31: 0 | X31: 17230 | Y31: =SUM(W31:X31) -> 17230 | Z31: 13.83 | AA31: 0 | AC31: 23.89 | AD31: 192.42 | AE31: =AD31+AE30 -> 5332.58 | AF31: 16.24 | AG31: 192.45 | AH31: =AG31+AH30 -> 5313.73 | AI31: 192.45 | AK31: 192.45 | AL31: 196678 | AM31: =AL31-AL30 -> 2730 | AN31: 21734 | AO31: =AN31-AN30 -> 220 | AR31: 2
B32: =B31+1 -> 44768 | C32: =TEXT(B32,"ddd") -> Tue | D32: 0.44 | E32: 0.23 | F32: 0.3 | G32: =SUMPRODUCT(D32:F32,$D$6:$F$6) -> 8099.5 | H32: 0.563 | J32: =I32-I31 -> 0 | K32: 1277042 | L32: =K32-K31 -> 21366 | P32: 3331 | Q32: =P32-P31 -> 0 | R32: 3374 | S32: =R32-R31 -> 0 | T32: 8531 | U32: 0 | V32: =SUM(T32:U32) -> 8531 | W32: 0 | X32: 20923 | Y32: =SUM(W32:X32) -> 20923 | Z32: 18.44 | AA32: 0 | AC32: 23.9 | AD32: 216.4 | AE32: =AD32+AE31 -> 5548.98 | AF32: 15.16 | AG32: 216.4 | AH32: =AG32+AH31 -> 5530.13 | AI32: 216.4 | AK32: 216.4 | AL32: 199388 | AM32: =AL32-AL31 -> 2710 | AN32: 22031 | AO32: =AN32-AN31 -> 297 | AR32: 2
B33: =B32+1 -> 44769 | C33: =TEXT(B33,"ddd") -> Wed | D33: 0.5 | E33: 0.12 | F33: 0.26 | G33: =SUMPRODUCT(D33:F33,$D$6:$F$6) -> 7348 | H33: 0.561 | J33: =I33-I32 -> 0 | K33: 1295132 | L33: =K33-K32 -> 18090 | P33: 3331 | Q33: =P33-P32 -> 0 | R33: 3374 | S33: =R33-R32 -> 0 | T33: 12221 | U33: 1438 | V33: =SUM(T33:U33) -> 13659 | W33: 0 | X33: 18015 | Y33: =SUM(W33:X33) -> 18015 | Z33: 19.81 | AA33: 3.8 | AC33: 22.29 | AD33: 239.88 | AE33: =AD33+AE32 -> 5788.86 | AF33: 13.25 | AG33: 239.88 | AH33: =AG33+AH32 -> 5770.01 | AI33: 239.88 | AK33: 239.88 | AL33: 202127 | AM33: =AL33-AL32 -> 2739 | AN33: 22339 | AO33: =AN33-AN32 -> 308 | AR33: 2
B34: =B33+1 -> 44770 | C34: =TEXT(B34,"ddd") -> Thu | D34: 0.15 | E34: 0.32 | F34: 0.25 | G34: =SUMPRODUCT(D34:F34,$D$6:$F$6) -> 6012 | H34: 0.556 | J34: =I34-I33 -> 0 | K34: 1315515 | L34: =K34-K33 -> 20383 | P34: 3331 | Q34: =P34-P33 -> 0 | R34: 3374 | S34: =R34-R33 -> 0 | T34: 7374 | U34: 0 | V34: =SUM(T34:U34) -> 7374 | W34: 0 | X34: 19682 | Y34: =SUM(W34:X34) -> 19682 | Z34: 18.7 | AA34: 0 | AC34: 22.16 | AD34: 324.89 | AE34: =AD34+AE33 -> 6113.75 | AF34: 11.81 | AG34: 324.94 | AH34: =AG34+AH33 -> 6094.95 | AI34: 324.94 | AK34: 324.94 | AL34: 204866 | AM34: =AL34-AL33 -> 2739 | AN34: 22638 | AO34: =AN34-AN33 -> 299 | AR34: 2
B35: =B34+1 -> 44771 | C35: =TEXT(B35,"ddd") -> Fri | D35: 0.36 | E35: 0.28 | F35: 0.22 | G35: =SUMPRODUCT(D35:F35,$D$6:$F$6) -> 7181 | H35: 0.554 | J35: =I35-I34 -> 0 | K35: 1334679 | L35: =K35-K34 -> 19164 | P35: 3331 | Q35: =P35-P34 -> 0 | R35: 3374 | S35: =R35-R34 -> 0 | T35: 7515 | U35: 0 | V35: =SUM(T35:U35) -> 7515 | W35: 0 | X35: 18710 | Y35: =SUM(W35:X35) -> 18710 | Z35: 14.83 | AA35: 0 | AC35: 23.84 | AD35: 331.1 | AE35: =AD35+AE34 -> 6444.85 | AF35: 13.74 | AG35: 331.1 | AH35: =AG35+AH34 -> 6426.05 | AI35: 331.1 | AK35: 331.1 | AL35: 207858 | AM35: =AL35-AL34 -> 2992 | AN35: 22638 | AO35: =AN35-AN34 -> 0 | AR35: 2
B36: =B35+1 -> 44772 | C36: =TEXT(B36,"ddd") -> Sat | D36: 0.21 | E36: 0.23 | F36: 0.42 | G36: =SUMPRODUCT(D36:F36,$D$6:$F$6) -> 7181 | H36: 0.554 | J36: =I36-I35 -> 0 | K36: 1350840 | L36: =K36-K35 -> 16161 | P36: 3331 | Q36: =P36-P35 -> 0 | R36: 3374 | S36: =R36-R35 -> 0 | T36: 2829 | U36: 0 | V36: =SUM(T36:U36) -> 2829 | W36: 0 | X36: 17316 | Y36: =SUM(W36:X36) -> 17316 | Z36: 8.48 | AA36: 0 | AC36: 20.71 | AD36: 258.48 | AE36: =AD36+AE35 -> 6703.33 | AF36: 14.49 | AG36: 258.48 | AH36: =AG36+AH35 -> 6684.53 | AI36: 258.48 | AK36: 258.48 | AL36: 210303 | AM36: 2445 | AN36: 23147 | AO36: =AN36-AN35 -> 509 | AR36: 2
B37: =B36+1 -> 44773 | C37: =TEXT(B37,"ddd") -> Sun | D37: 0.41 | E37: 0.58 | F37: 0.3 | G37: =SUMPRODUCT(D37:F37,$D$6:$F$6) -> 10771.5 | H37: 0.559 | K37: 1367245 | L37: =K37-K36 -> 16405 | P37: 3331 | Q37: =P37-P36 -> 0 | R37: 3374 | S37: =R37-R36 -> 0 | T37: 2444 | U37: 0 | V37: =SUM(T37:U37) -> 2444 | W37: 0 | X37: 16405 | Y37: =SUM(W37:X37) -> 16405 | Z37: 5.14 | AA37: 0 | AC37: 14.87 | AD37: 154.98 | AE37: =AD37+AE36 -> 6858.31 | AF37: 15.13 | AG37: 155 | AH37: =AG37+AH36 -> 6839.53 | AI37: 155 | AK37: 155 | AL37: 212748 | AM37: 2445 | AN37: 23147 | AO37: =AN37-AN36 -> 0 | AR37: 1
B38: Total/Average | D38: =AVERAGE(D7:D37) -> 0.28677419 | F38: =AVERAGE(F7:F37) -> 0.43362581 | G38: =AVERAGE(G7:G37) -> 9368.8077 | H38: =AVERAGE(H7:H37) -> 0.56041935 | J38: =SUMIFS(J7:J37,J7:J37,">0") -> 0 | L38: =SUMIFS(L7:L37,L7:L37,">0") -> 575665 | O38: =SUM(O7:O37) -> 14509 | Q38: =SUMIFS(Q7:Q37,Q7:Q37,">0") -> 0 | S38: =SUMIFS(S7:S37,S7:S37,">0") -> 0 | T38: =SUM(T7:T37) -> 191584 | U38: =SUM(U7:U37) -> 71839.23 | V38: =SUM(V7:V37) -> 263423.23 | Y38: =SUM(Y7:Y37)-733 -> 575665 | Z38: =SUM(Z7:Z37) -> 355.79 | AA38: =SUM(AA7:AA37) -> 124.15 | AB38: =SUM(AB7:AB37) -> 0 | AC38: =SUM(AC7:AC37) -> 598.59 | AD38: =SUM(AD7:AD37) -> 6858.31 | AF38: =AVERAGE(AF7:AF37) -> 14.890769 | AG38: =SUM(AG7:AG37) -> 6839.53 | AI38: 6839.53 | AJ38: 70.498 | AK38: 6910.028 | AM38: =SUM(AM7:AM37) -> 76816 | AO38: =SUM(AO7:AO37) -> 8448
Y41: Note: There's adifference of 733 between DPO and SBVC due to different time of reading.
Y42: Added 733 to DPO to coincide since this was already billed

Sheet Aug2022
B2: Note: Recording should be done 1st hour of the day
B3: DAILY BIOGAS USAGE MONITORING | AD3: SBVC RECORD | AG3: DPO RECORD (Lowela) | AI3: JANETTE'S RECORD | AL3: Biogas Operation Utility Consumption | AR3: Remarks/ Shifts
B4: Date | C4: Day | D4: Gas Storage (%) | H4: Quality | I4: Gas Meters (Nmᶾ) | M4: Gas Flare | P4: Gas Engine 1 Power Meter (kWh) | R4: Gas Engine 2 Power Meter (kWh) | T4: Diesel Fuel Consumption | W4: Biogas Fuel Consumption | Z4: Ope. Hrs w/ Diesel | AB4: Ope. Hrs w/ Biogas | AD4: Waste Hauling Operation | AG4: Waste Hauling Operation | AI4: Waste Hauling Operation
D5: F1 | E5: F2 | F5: F3 | G5: Total | H5: Methane Content | I5: Thermax 1 Totalizer | K5: Thermax 2 Totalizer | M5: Time | O5: Total Volume | T5: Thermax 1 | U5: Thermax 2 | V5: Total | W5: Thermax 1 | X5: Thermax 2 | Y5: Total | Z5: Thermax 1 | AA5: Thermax 2 | AB5: Thermax 1 | AC5: Thermax 2 | AD5: Actual Waste Delivered (MT) | AF5: DS | AG5: Actual Waste Delivered (MT) | AI5: Cannery Waste to Biogas, MT | AJ5: Other Fruit Waste to Biogas, MT | AK5: Total Waste to Biogas, MT | AL5: Electricity @ Biogas plant, kWhr | AN5: Electricity @ DPO cannery (Blower) , kWhr | AP5: Water, m3
D6: 8350 | E6: 8350 | F6: 8350 | G6: =D6+E6+F6 -> 25050 | H6: 55% Min | I6: Totalizer | J6: Output | K6: Totalizer | L6: Output | M6: Start | N6: End | O6: Nm³ | P6: Totalizer | Q6: Output | R6: Totalizer | S6: Output | T6: Li. | U6: Li. | V6: Li. | Z6: Hrs | AA6: Hrs | AB6: Hrs | AC6: Hrs | AD6: Delivery | AE6: Cummulative | AF6: % | AG6: Delivery | AH6: Cummulative | AL6: Totalizer | AM6: Consumed | AN6: Totalizer | AO6: Consumed | AP6: Totalizer | AQ6: Consumed
B7: 44774 | C7: =TEXT(B7,"ddd") -> Mon | D7: 0.45 | E7: 0.18 | F7: 0.3 | G7: 7765.5 | H7: 0.564 | J7: 0 | K7: 1386087 | L7: 18842 | P7: 3331 | Q7: 0 | R7: 3374 | S7: 0 | T7: 9383 | U7: 7184 | V7: =SUM(T7:U7) -> 16567 | W7: 0 | X7: 18842 | Y7: =SUM(W7:X7) -> 18842 | Z7: 15.41 | AA7: 12.88 | AB7: 0 | AC7: 22.84 | AD7: 279.15 | AE7: =AD7 -> 279.15 | AF7: 14.36 | AG7: 279.15 | AH7: =AG7 -> 279.15 | AI7: 279.15 | AK7: 279.15 | AL7: 215217 | AM7: =AL7-'Jul2022'!AL37 -> 2469 | AN7: 23467 | AO7: 320 | AR7: 2
B8: =B7+1 -> 44775 | C8: =TEXT(B8,"ddd") -> Tue | D8: 0.32 | E8: 0.3 | F8: 0.13 | G8: 6262.5 | H8: 0.564 | J8: 0 | K8: 1405316 | L8: 19229 | P8: 3331 | Q8: 0 | R8: 3374 | S8: 0 | T8: 12400 | U8: 1770 | V8: =SUM(T8:U8) -> 14170 | W8: 0 | X8: 19188 | Y8: =SUM(W8:X8) -> 19188 | Z8: 23.78 | AA8: 0 | AB8: 0 | AC8: 23.76 | AD8: 346.48 | AE8: =AD8+AE7 -> 625.63 | AF8: 15.12 | AG8: 346.48 | AH8: =AG8+AH7 -> 625.63 | AI8: 346.48 | AK8: 346.48 | AL8: 217936 | AM8: =AL8-AL7 -> 2719 | AN8: 23776 | AO8: =AN8-AN7 -> 309 | AR8: 2
B9: =B8+1 -> 44776 | C9: =TEXT(B9,"ddd") -> Wed | D9: 0.42 | E9: 0.45 | F9: 0.21 | G9: 9018 | H9: 0.572 | J9: 0 | K9: 1429700 | L9: 24384 | P9: 3331 | Q9: 0 | R9: 3374 | S9: 0 | T9: 13967 | U9: 0 | V9: =SUM(T9:U9) -> 13967 | W9: 0 | X9: 24425 | Y9: =SUM(W9:X9) -> 24425 | Z9: 20.09 | AA9: 0 | AB9: 0 | AC9: 23.97 | AD9: 279.49 | AE9: =AD9+AE8 -> 905.12 | AF9: 14.94 | AG9: 278.49 | AH9: =AG9+AH8 -> 904.12 | AI9: 278.49 | AK9: 278.49 | AL9: 220699 | AM9: =AL9-AL8 -> 2763 | AN9: 24113 | AO9: =AN9-AN8 -> 337 | AR9: 2
B10: =B9+1 -> 44777 | C10: =TEXT(B10,"ddd") -> Thu | D10: 0.15 | E10: 0.14 | F10: 0.16 | G10: 3757.5 | H10: 0.563 | J10: 0 | K10: 1461575 | L10: 31875 | P10: 3331 | Q10: 0 | R10: 3374 | S10: 0 | T10: 8543 | U10: 0 | V10: =SUM(T10:U10) -> 8543 | W10: 0 | X10: 29373 | Y10: =SUM(W10:X10) -> 29373 | Z10: 15.68 | AA10: 0 | AB10: 0 | AC10: 24 | AD10: 263.2 | AE10: =AD10+AE9 -> 1168.32 | AF10: 14.27 | AG10: 263.23 | AH10: =AG10+AH9 -> 1167.35 | AI10: 263.23 | AK10: 263.23 | AL10: 223518 | AM10: =AL10-AL9 -> 2819 | AN10: 24479 | AO10: =AN10-AN9 -> 366 | AR10: 2
B11: =B10+1 -> 44778 | C11: =TEXT(B11,"ddd") -> Fri | D11: 0.98 | E11: 0.32 | F11: 0.1 | G11: 11690 | H11: 0.57 | J11: 0 | K11: 1465706 | L11: 4131 | P11: 3331 | Q11: 0 | R11: 3374 | S11: 0 | T11: 0 | U11: 0 | V11: =SUM(T11:U11) -> 0 | W11: 0 | X11: 6633 | Y11: =SUM(W11:X11) -> 6633 | Z11: 0 | AA11: 0 | AB11: 0 | AC11: 7.06 | AD11: 0 | AE11: =AD11+AE10 -> 1168.32 | AG11: 0 | AH11: =AG11+AH10 -> 1167.35 | AI11: - | AK11: 0 | AL11: 224151 | AM11: =AL11-AL10 -> 633 | AN11: 24585 | AO11: =AN11-AN10 -> 106 | AR11: DPO under mini shutdown
B12: =B11+1 -> 44779 | C12: =TEXT(B12,"ddd") -> Sat | D12: 0.61 | E12: 0.15 | F12: 0.09 | G12: 7097.5 | H12: 0.56 | J12: 0 | K12: 1465706 | L12: 0 | P12: 3331 | Q12: 0 | R12: 5878 | S12: 2504 | T12: 0 | U12: 0 | V12: =SUM(T12:U12) -> 0 | W12: 0 | X12: 0 | Y12: =SUM(W12:X12) -> 0 | Z12: 0 | AA12: 0 | AB12: 0 | AC12: 0 | AD12: 0 | AE12: =AD12+AE11 -> 1168.32 | AG12: 0 | AH12: =AG12+AH11 -> 1167.35 | AI12: - | AK12: 0 | AL12: 225702 | AM12: =AL12-AL11 -> 1551 | AN12: 24705 | AO12: =AN12-AN11 -> 120 | AR12: DPO under mini shutdown
B13: =B12+1 -> 44780 | C13: =TEXT(B13,"ddd") -> Sun | D13: 0.8 | E13: 0.67 | F13: 0.46 | G13: 16115.5 | H13: 0.56 | J13: 0 | K13: 1465706 | L13: 0 | P13: 3331 | Q13: 0 | R13: 16077 | S13: 10199 | T13: 0 | U13: 0 | V13: =SUM(T13:U13) -> 0 | W13: 0 | X13: 0 | Y13: =SUM(W13:X13) -> 0 | Z13: 0 | AA13: 0 | AB13: 0 | AC13: 0 | AD13: 0 | AE13: =AD13+AE12 -> 1168.32 | AG13: 0 | AH13: =AG13+AH12 -> 1167.35 | AI13: - | AK13: 0 | AL13: 226098 | AM13: =AL13-AL12 -> 396 | AN13: 25049 | AO13: =AN13-AN12 -> 344 | AR13: DPO under mini shutdown
B14: =B13+1 -> 44781 | C14: =TEXT(B14,"ddd") -> Mon | D14: 0.64 | E14: 0.67 | F14: 0.35 | G14: 13861 | H14: 0.556 | J14: 0 | K14: 1465706 | L14: 0 | P14: 3331 | Q14: 0 | R14: 32113 | S14: 16036 | T14: 0 | U14: 0 | V14: =SUM(T14:U14) -> 0 | W14: 0 | X14: 0 | Y14: =SUM(W14:X14) -> 0 | Z14: 0 | AA14: 0 | AB14: 0 | AC14: 0 | AD14: 0 | AE14: =AD14+AE13 -> 1168.32 | AG14: 0 | AH14: =AG14+AH13 -> 1167.35 | AI14: - | AK14: 0 | AL14: 227685 | AM14: =AL14-AL13 -> 1587 | AN14: 25652 | AO14: =AN14-AN13 -> 603 | AR14: DPO under mini shutdown
B15: =B14+1 -> 44782 | C15: =TEXT(B15,"ddd") -> Tue | D15: 0.89 | E15: 0.71 | F15: 0.79 | G15: 19956.5 | H15: 0.556 | J15: 0 | K15: 1474752 | L15: 9046 | P15: 3331 | Q15: 0 | R15: 44134 | S15: 12021 | T15: 0 | U15: 0 | V15: =SUM(T15:U15) -> 0 | W15: 0 | X15: 9056 | Y15: =SUM(W15:X15) -> 9056 | Z15: 0 | AA15: 0 | AB15: 0 | AC15: 14.98 | AD15: 0 | AE15: =AD15+AE14 -> 1168.32 | AG15: 0 | AH15: =AG15+AH14 -> 1167.35 | AI15: - | AK15: 0 | AL15: 229615 | AM15: =AL15-AL14 -> 1930 | AN15: 26004 | AO15: =AN15-AN14 -> 352 | AR15: DPO under mini shutdown
B16: =B15+1 -> 44783 | C16: =TEXT(B16,"ddd") -> Wed | D16: 0.62 | E16: 0.77 | F16: 0.62 | G16: 16783.5 | H16: 0.554 | J16: 0 | K16: 1494169 | L16: 19417 | P16: 3331 | Q16: 0 | R16: 44134 | S16: 0 | T16: 180 | U16: 0 | V16: =SUM(T16:U16) -> 180 | W16: 0 | X16: 19407 | Y16: =SUM(W16:X16) -> 19407 | Z16: 0.63 | AA16: 0 | AB16: 0 | AC16: 23.79 | AD16: 0 | AE16: =AD16+AE15 -> 1168.32 | AG16: 0 | AH16: =AG16+AH15 -> 1167.35 | AI16: - | AK16: 0 | AL16: 232238 | AM16: =AL16-AL15 -> 2623 | AN16: 26515 | AO16: =AN16-AN15 -> 511 | AR16: 2
B17: =B16+1 -> 44784 | C17: =TEXT(B17,"ddd") -> Thu | D17: 0.64 | E17: 0.55 | F17: 0.26 | G17: 12107.5 | H17: 0.567 | J17: 0 | K17: 1515789 | L17: 21620 | P17: 3331 | Q17: 0 | R17: 44134 | S17: 0 | T17: 0 | U17: 0 | V17: =SUM(T17:U17) -> 0 | W17: 0 | X17: 21620 | Y17: =SUM(W17:X17) -> 21620 | Z17: 0 | AA17: 0 | AB17: 0 | AC17: 23.97 | AD17: 133.73 | AE17: =AD17+AE16 -> 1302.05 | AF17: 14 | AG17: 133.73 | AH17: =AG17+AH16 -> 1301.08 | AI17: 133.73 | AK17: 133.73 | AL17: 235229 | AM17: =AL17-AL16 -> 2991 | AN17: 26886 | AO17: =AN17-AN16 -> 371 | AR17: 2
B18: =B17+1 -> 44785 | C18: =TEXT(B18,"ddd") -> Fri | D18: 0.6 | E18: 0.33 | F18: 0.38 | G18: 10938.5 | H18: 0.566 | J18: 0 | K18: 1531986 | L18: 16197 | P18: 3331 | Q18: 0 | R18: 44134 | S18: 0 | T18: 132 | U18: 0 | V18: =SUM(T18:U18) -> 132 | W18: 0 | X18: 16757 | Y18: =SUM(W18:X18) -> 16757 | Z18: 0.45 | AA18: 0 | AB18: 0 | AC18: 21.41 | AD18: 365.56 | AE18: =AD18+AE17 -> 1667.61 | AF18: 14.44 | AG18: 365.56 | AH18: =AG18+AH17 -> 1666.64 | AI18: 365.56 | AK18: 365.56 | AL18: 238476 | AM18: =AL18-AL17 -> 3247 | AN18: 27086 | AO18: =AN18-AN17 -> 200 | AR18: 2
B19: =B18+1 -> 44786 | C19: =TEXT(B19,"ddd") -> Sat | D19: 0.24 | E19: 0.2 | F19: 0.21 | G19: 5427.5 | H19: 0.57 | J19: 0 | K19: 1561763 | L19: 29777 | P19: 3331 | Q19: 0 | R19: 44134 | S19: 0 | T19: 0 | U19: 0 | V19: =SUM(T19:U19) -> 0 | W19: 0 | X19: 29217 | Y19: =SUM(W19:X19) -> 29217 | Z19: 0 | AA19: 0 | AB19: 0 | AC19: 22.54 | AD19: 359.72 | AE19: =AD19+AE18 -> 2027.33 | AF19: 14.39 | AG19: 360.72 | AH19: =AG19+AH18 -> 2027.36 | AI19: 360.72 | AK19: 360.72 | AL19: 241415 | AM19: =AL19-AL18 -> 2939 | AN19: 27386 | AO19: =AN19-AN18 -> 300 | AR19: 2
