Workbook

Sheet Change Tracker
B2: Note: Recording should be done 1st hour of the day
B3: DAILY BIOGAS USAGE MONITORING | X3: Waste Hauling Operation | AA3: Biogas Operation Utility Consumption | AC3: Remarks
B4: Date | C4: Day | D4: Gas Storage (%) | G4: Quality | H4: Gas Meters (mᶾ) | L4: Gas Flare | O4: Gas Engine Power Meter (kWh) | Q4: Diesel Fuel Consumption | T4: Ope. Hrs | V4: Ope. Hrs w/ Biogas
D5: F1 | E5: F2 | F5: Total | G5: Methane Content | H5: Gas Engine Line Totalizer | J5: Boiler Line Totalizer | L5: Time | N5: Total Volume | Q5: Thermax | R5: Cleaver Brooks | S5: Total | T5: Thermax | U5: Cleaver Brooks | V5: Thermax | W5: Cleaver Brooks | X5: Actual Waste Delivered (MT) | Z5: % DS | AA5: Electricity | AB5: Water
D6: 8350 | E6: 8350 | G6: 0.55 | H6: Totalizer | I6: Output | J6: Totalizer | K6: Output | L6: Start | M6: End | N6: Nm³ | O6: Totalizer | P6: Output | Q6: Li. | R6: Li. | S6: Li. | T6: Hrs | U6: Hrs | V6: Hrs | W6: Hrs | X6: Delivery | Y6: Cummulative | AA6: kWhr | AB6: m³
B7: 44438 | C7: =TEXT(B7,"ddd") -> Mon | D7: =#REF!-'Previous day'!D7 -> #REF! | F7: =SUMPRODUCT($D$6:$E$6,D7:E7) -> #REF! | G7: =#REF!-'Previous day'!G7 -> #REF! | J7: =#REF!-'Previous day'!J7 -> #REF! | K7: =#REF!-'Previous day'!K7 -> #REF! | N7: =#REF!-'Previous day'!N7 -> #REF! | O7: =#REF!-'Previous day'!O7 -> #REF! | P7: =#REF!-'Previous day'!P7 -> #REF! | Q7: =#REF!-'Previous day'!Q7 -> #REF! | R7: =#REF!-'Previous day'!R7 -> #REF! | S7: =#REF!-'Previous day'!S7 -> #REF! | T7: =#REF!-'Previous day'!T7 -> #REF! | U7: =#REF!-'Previous day'!U7 -> #REF! | ... AB7: =#REF!-'Previous day'!AB7 -> #REF!
B8: =B7+1 -> 44439 | C8: =TEXT(B8,"ddd") -> Tue | D8: =#REF!-'Previous day'!D8 -> #REF! | F8: =SUMPRODUCT($D$6:$E$6,D8:E8) -> #REF! | G8: =#REF!-'Previous day'!G8 -> #REF! | J8: =#REF!-'Previous day'!J8 -> #REF! | K8: =#REF!-'Previous day'!K8 -> #REF! | N8: =#REF!-'Previous day'!N8 -> #REF! | O8: =#REF!-'Previous day'!O8 -> #REF! | P8: =#REF!-'Previous day'!P8 -> #REF! | Q8: =#REF!-'Previous day'!Q8 -> #REF! | R8: =#REF!-'Previous day'!R8 -> #REF! | S8: =#REF!-'Previous day'!S8 -> #REF! | T8: =#REF!-'Previous day'!T8 -> #REF! | U8: =#REF!-'Previous day'!U8 -> #REF! | ... AB8: =#REF!-'Previous day'!AB8 -> #REF!
B9: =B8+1 -> 44440 | C9: =TEXT(B9,"ddd") -> Wed | D9: =#REF!-'Previous day'!D9 -> #REF! | F9: =SUMPRODUCT($D$6:$E$6,D9:E9) -> #REF! | G9: =#REF!-'Previous day'!G9 -> #REF! | J9: =#REF!-'Previous day'!J9 -> #REF! | K9: =#REF!-'Previous day'!K9 -> #REF! | L9: 0.29166667 | M9: 0.37152778 | N9: =#REF!-'Previous day'!N9 -> #REF! | O9: =#REF!-'Previous day'!O9 -> #REF! | P9: =#REF!-'Previous day'!P9 -> #REF! | Q9: =#REF!-'Previous day'!Q9 -> #REF! | R9: =#REF!-'Previous day'!R9 -> #REF! | S9: =#REF!-'Previous day'!S9 -> #REF! | T9: =#REF!-'Previous day'!T9 -> #REF! | U9: =#REF!-'Previous day'!U9 -> #REF! | ... AB9: =#REF!-'Previous day'!AB9 -> #REF!
B10: =B9+1 -> 44441 | C10: =TEXT(B10,"ddd") -> Thu | D10: =#REF!-'Previous day'!D10 -> #REF! | F10: =SUMPRODUCT($D$6:$E$6,D10:E10) -> #REF! | G10: =#REF!-'Previous day'!G10 -> #REF! | J10: =#REF!-'Previous day'!J10 -> #REF! | K10: =#REF!-'Previous day'!K10 -> #REF! | N10: =#REF!-'Previous day'!N10 -> #REF! | O10: =#REF!-'Previous day'!O10 -> #REF! | P10: =#REF!-'Previous day'!P10 -> #REF! | Q10: =#REF!-'Previous day'!Q10 -> #REF! | R10: =#REF!-'Previous day'!R10 -> #REF! | S10: =#REF!-'Previous day'!S10 -> #REF! | T10: =#REF!-'Previous day'!T10 -> #REF! | U10: =#REF!-'Previous day'!U10 -> #REF! | ... AB10: =#REF!-'Previous day'!AB10 -> #REF!
B11: =B10+1 -> 44442 | C11: =TEXT(B11,"ddd") -> Fri | D11: =#REF!-'Previous day'!D11 -> #REF! | F11: =SUMPRODUCT($D$6:$E$6,D11:E11) -> #REF! | G11: =#REF!-'Previous day'!G11 -> #REF! | J11: =#REF!-'Previous day'!J11 -> #REF! | K11: =#REF!-'Previous day'!K11 -> #REF! | N11: =#REF!-'Previous day'!N11 -> #REF! | O11: =#REF!-'Previous day'!O11 -> #REF! | P11: =#REF!-'Previous day'!P11 -> #REF! | Q11: =#REF!-'Previous day'!Q11 -> #REF! | R11: =#REF!-'Previous day'!R11 -> #REF! | S11: =#REF!-'Previous day'!S11 -> #REF! | T11: =#REF!-'Previous day'!T11 -> #REF! | U11: =#REF!-'Previous day'!U11 -> #REF! | ... AB11: =#REF!-'Previous day'!AB11 -> #REF!
B12: =B11+1 -> 44443 | C12: =TEXT(B12,"ddd") -> Sat | D12: =#REF!-'Previous day'!D12 -> #REF! | F12: =SUMPRODUCT($D$6:$E$6,D12:E12) -> #REF! | G12: =#REF!-'Previous day'!G12 -> #REF! | J12: =#REF!-'Previous day'!J12 -> #REF! | K12: =#REF!-'Previous day'!K12 -> #REF! | L12: 0.61319444 | M12: 0.67777778 | N12: =#REF!-'Previous day'!N12 -> #REF! | O12: =#REF!-'Previous day'!O12 -> #REF! | P12: =#REF!-'Previous day'!P12 -> #REF! | Q12: =#REF!-'Previous day'!Q12 -> #REF! | R12: =#REF!-'Previous day'!R12 -> #REF! | S12: =#REF!-'Previous day'!S12 -> #REF! | T12: =#REF!-'Previous day'!T12 -> #REF! | U12: =#REF!-'Previous day'!U12 -> #REF! | ... AB12: =#REF!-'Previous day'!AB12 -> #REF!
B13: =B12+1 -> 44444 | C13: =TEXT(B13,"ddd") -> Sun | D13: =#REF!-'Previous day'!D13 -> #REF! | F13: =SUMPRODUCT($D$6:$E$6,D13:E13) -> #REF! | G13: =#REF!-'Previous day'!G13 -> #REF! | J13: =#REF!-'Previous day'!J13 -> #REF! | K13: =#REF!-'Previous day'!K13 -> #REF! | L13: 0.26041667 | M13: 0.54861111 | N13: =#REF!-'Previous day'!N13 -> #REF! | O13: =#REF!-'Previous day'!O13 -> #REF! | P13: =#REF!-'Previous day'!P13 -> #REF! | Q13: =#REF!-'Previous day'!Q13 -> #REF! | R13: =#REF!-'Previous day'!R13 -> #REF! | S13: =#REF!-'Previous day'!S13 -> #REF! | T13: =#REF!-'Previous day'!T13 -> #REF! | U13: =#REF!-'Previous day'!U13 -> #REF! | ... AB13: =#REF!-'Previous day'!AB13 -> #REF!
B14: =B13+1 -> 44445 | C14: =TEXT(B14,"ddd") -> Mon | D14: =#REF!-'Previous day'!D14 -> #REF! | F14: =SUMPRODUCT($D$6:$E$6,D14:E14) -> #REF! | G14: =#REF!-'Previous day'!G14 -> #REF! | J14: =#REF!-'Previous day'!J14 -> #REF! | K14: =#REF!-'Previous day'!K14 -> #REF! | N14: =#REF!-'Previous day'!N14 -> #REF! | O14: =#REF!-'Previous day'!O14 -> #REF! | P14: =#REF!-'Previous day'!P14 -> #REF! | Q14: =#REF!-'Previous day'!Q14 -> #REF! | R14: =#REF!-'Previous day'!R14 -> #REF! | S14: =#REF!-'Previous day'!S14 -> #REF! | T14: =#REF!-'Previous day'!T14 -> #REF! | U14: =#REF!-'Previous day'!U14 -> #REF! | ... AB14: =#REF!-'Previous day'!AB14 -> #REF!
B15: =B14+1 -> 44446 | C15: =TEXT(B15,"ddd") -> Tue | D15: =#REF!-'Previous day'!D15 -> #REF! | F15: =SUMPRODUCT($D$6:$E$6,D15:E15) -> #REF! | G15: =#REF!-'Previous day'!G15 -> #REF! | J15: =#REF!-'Previous day'!J15 -> #REF! | K15: =#REF!-'Previous day'!K15 -> #REF! | N15: =#REF!-'Previous day'!N15 -> #REF! | O15: =#REF!-'Previous day'!O15 -> #REF! | P15: =#REF!-'Previous day'!P15 -> #REF! | Q15: =#REF!-'Previous day'!Q15 -> #REF! | R15: =#REF!-'Previous day'!R15 -> #REF! | S15: =#REF!-'Previous day'!S15 -> #REF! | T15: =#REF!-'Previous day'!T15 -> #REF! | U15: =#REF!-'Previous day'!U15 -> #REF! | ... AB15: =#REF!-'Previous day'!AB15 -> #REF!
B16: =B15+1 -> 44447 | C16: =TEXT(B16,"ddd") -> Wed | D16: =#REF!-'Previous day'!D16 -> #REF! | F16: =SUMPRODUCT($D$6:$E$6,D16:E16) -> #REF! | G16: =#REF!-'Previous day'!G16 -> #REF! | J16: =#REF!-'Previous day'!J16 -> #REF! | K16: =#REF!-'Previous day'!K16 -> #REF! | N16: =#REF!-'Previous day'!N16 -> #REF! | O16: =#REF!-'Previous day'!O16 -> #REF! | P16: =#REF!-'Previous day'!P16 -> #REF! | Q16: =#REF!-'Previous day'!Q16 -> #REF! | R16: =#REF!-'Previous day'!R16 -> #REF! | S16: =#REF!-'Previous day'!S16 -> #REF! | T16: =#REF!-'Previous day'!T16 -> #REF! | U16: =#REF!-'Previous day'!U16 -> #REF! | ... AB16: =#REF!-'Previous day'!AB16 -> #REF!
B17: =B16+1 -> 44448 | C17: =TEXT(B17,"ddd") -> Thu | D17: =#REF!-'Previous day'!D17 -> #REF! | F17: =SUMPRODUCT($D$6:$E$6,D17:E17) -> #REF! | G17: =#REF!-'Previous day'!G17 -> #REF! | J17: =#REF!-'Previous day'!J17 -> #REF! | K17: =#REF!-'Previous day'!K17 -> #REF! | L17: 0.29930556 | M17: 0.31527778 | N17: =#REF!-'Previous day'!N17 -> #REF! | O17: =#REF!-'Previous day'!O17 -> #REF! | P17: =#REF!-'Previous day'!P17 -> #REF! | Q17: =#REF!-'Previous day'!Q17 -> #REF! | R17: =#REF!-'Previous day'!R17 -> #REF! | S17: =#REF!-'Previous day'!S17 -> #REF! | T17: =#REF!-'Previous day'!T17 -> #REF! | U17: =#REF!-'Previous day'!U17 -> #REF! | ... AB17: =#REF!-'Previous day'!AB17 -> #REF!
B18: =B17+1 -> 44449 | C18: =TEXT(B18,"ddd") -> Fri | D18: =#REF!-'Previous day'!D18 -> #REF! | F18: =SUMPRODUCT($D$6:$E$6,D18:E18) -> #REF! | G18: =#REF!-'Previous day'!G18 -> #REF! | J18: =#REF!-'Previous day'!J18 -> #REF! | K18: =#REF!-'Previous day'!K18 -> #REF! | N18: =#REF!-'Previous day'!N18 -> #REF! | O18: =#REF!-'Previous day'!O18 -> #REF! | P18: =#REF!-'Previous day'!P18 -> #REF! | Q18: =#REF!-'Previous day'!Q18 -> #REF! | R18: =#REF!-'Previous day'!R18 -> #REF! | S18: =#REF!-'Previous day'!S18 -> #REF! | T18: =#REF!-'Previous day'!T18 -> #REF! | U18: =#REF!-'Previous day'!U18 -> #REF! | ... AB18: =#REF!-'Previous day'!AB18 -> #REF!
B19: =B18+1 -> 44450 | C19: =TEXT(B19,"ddd") -> Sat | D19: =#REF!-'Previous day'!D19 -> #REF! | F19: =SUMPRODUCT($D$6:$E$6,D19:E19) -> #REF! | G19: =#REF!-'Previous day'!G19 -> #REF! | J19: =#REF!-'Previous day'!J19 -> #REF! | K19: =#REF!-'Previous day'!K19 -> #REF! | L19: 0.67708333 | M19: 0.72222222 | N19: =#REF!-'Previous day'!N19 -> #REF! | O19: =#REF!-'Previous day'!O19 -> #REF! | P19: =#REF!-'Previous day'!P19 -> #REF! | Q19: =#REF!-'Previous day'!Q19 -> #REF! | R19: =#REF!-'Previous day'!R19 -> #REF! | S19: =#REF!-'Previous day'!S19 -> #REF! | T19: =#REF!-'Previous day'!T19 -> #REF! | U19: =#REF!-'Previous day'!U19 -> #REF! | ... AB19: =#REF!-'Previous day'!AB19 -> #REF!
B20: =B19+1 -> 44451 | C20: =TEXT(B20,"ddd") -> Sun | D20: =#REF!-'Previous day'!D20 -> #REF! | F20: =SUMPRODUCT($D$6:$E$6,D20:E20) -> #REF! | G20: =#REF!-'Previous day'!G20 -> #REF! | J20: =#REF!-'Previous day'!J20 -> #REF! | K20: =#REF!-'Previous day'!K20 -> #REF! | N20: =#REF!-'Previous day'!N20 -> #REF! | O20: =#REF!-'Previous day'!O20 -> #REF! | P20: =#REF!-'Previous day'!P20 -> #REF! | Q20: =#REF!-'Previous day'!Q20 -> #REF! | R20: =#REF!-'Previous day'!R20 -> #REF! | S20: =#REF!-'Previous day'!S20 -> #REF! | T20: =#REF!-'Previous day'!T20 -> #REF! | U20: =#REF!-'Previous day'!U20 -> #REF! | ... AB20: =#REF!-'Previous day'!AB20 -> #REF!
B21: =B20+1 -> 44452 | C21: =TEXT(B21,"ddd") -> Mon | D21: =#REF!-'Previous day'!D21 -> #REF! | F21: =SUMPRODUCT($D$6:$E$6,D21:E21) -> #REF! | G21: =#REF!-'Previous day'!G21 -> #REF! | J21: =#REF!-'Previous day'!J21 -> #REF! | K21: =#REF!-'Previous day'!K21 -> #REF! | L21: 0.35069444 | M21: 0.36527778 | N21: =#REF!-'Previous day'!N21 -> #REF! | O21: =#REF!-'Previous day'!O21 -> #REF! | P21: =#REF!-'Previous day'!P21 -> #REF! | Q21: =#REF!-'Previous day'!Q21 -> #REF! | R21: =#REF!-'Previous day'!R21 -> #REF! | S21: =#REF!-'Previous day'!S21 -> #REF! | T21: =#REF!-'Previous day'!T21 -> #REF! | U21: =#REF!-'Previous day'!U21 -> #REF! | ... AB21: =#REF!-'Previous day'!AB21 -> #REF!
B22: =B21+1 -> 44453 | C22: =TEXT(B22,"ddd") -> Tue | D22: =#REF!-'Previous day'!D22 -> #REF! | F22: =SUMPRODUCT($D$6:$E$6,D22:E22) -> #REF! | G22: =#REF!-'Previous day'!G22 -> #REF! | J22: =#REF!-'Previous day'!J22 -> #REF! | K22: =#REF!-'Previous day'!K22 -> #REF! | N22: =#REF!-'Previous day'!N22 -> #REF! | O22: =#REF!-'Previous day'!O22 -> #REF! | P22: =#REF!-'Previous day'!P22 -> #REF! | Q22: =#REF!-'Previous day'!Q22 -> #REF! | R22: =#REF!-'Previous day'!R22 -> #REF! | S22: =#REF!-'Previous day'!S22 -> #REF! | T22: =#REF!-'Previous day'!T22 -> #REF! | U22: =#REF!-'Previous day'!U22 -> #REF! | ... AB22: =#REF!-'Previous day'!AB22 -> #REF!
B23: =B22+1 -> 44454 | C23: =TEXT(B23,"ddd") -> Wed | D23: =#REF!-'Previous day'!D23 -> #REF! | F23: =SUMPRODUCT($D$6:$E$6,D23:E23) -> #REF! | G23: =#REF!-'Previous day'!G23 -> #REF! | J23: =#REF!-'Previous day'!J23 -> #REF! | K23: =#REF!-'Previous day'!K23 -> #REF! | N23: =#REF!-'Previous day'!N23 -> #REF! | O23: =#REF!-'Previous day'!O23 -> #REF! | P23: =#REF!-'Previous day'!P23 -> #REF! | Q23: =#REF!-'Previous day'!Q23 -> #REF! | R23: =#REF!-'Previous day'!R23 -> #REF! | S23: =#REF!-'Previous day'!S23 -> #REF! | T23: =#REF!-'Previous day'!T23 -> #REF! | U23: =#REF!-'Previous day'!U23 -> #REF! | ... AB23: =#REF!-'Previous day'!AB23 -> #REF!
B24: =B23+1 -> 44455 | C24: =TEXT(B24,"ddd") -> Thu | D24: =#REF!-'Previous day'!D24 -> #REF! | F24: =SUMPRODUCT($D$6:$E$6,D24:E24) -> #REF! | G24: =#REF!-'Previous day'!G24 -> #REF! | J24: =#REF!-'Previous day'!J24 -> #REF! | K24: =#REF!-'Previous day'!K24 -> #REF! | N24: =#REF!-'Previous day'!N24 -> #REF! | O24: =#REF!-'Previous day'!O24 -> #REF! | P24: =#REF!-'Previous day'!P24 -> #REF! | Q24: =#REF!-'Previous day'!Q24 -> #REF! | R24: =#REF!-'Previous day'!R24 -> #REF! | S24: =#REF!-'Previous day'!S24 -> #REF! | T24: =#REF!-'Previous day'!T24 -> #REF! | U24: =#REF!-'Previous day'!U24 -> #REF! | ... AB24: =#REF!-'Previous day'!AB24 -> #REF!
B25: =B24+1 -> 44456 | C25: =TEXT(B25,"ddd") -> Fri | D25: =#REF!-'Previous day'!D25 -> #REF! | F25: =SUMPRODUCT($D$6:$E$6,D25:E25) -> #REF! | G25: =#REF!-'Previous day'!G25 -> #REF! | J25: =#REF!-'Previous day'!J25 -> #REF! | K25: =#REF!-'Previous day'!K25 -> #REF! | N25: =#REF!-'Previous day'!N25 -> #REF! | O25: =#REF!-'Previous day'!O25 -> #REF! | P25: =#REF!-'Previous day'!P25 -> #REF! | Q25: =#REF!-'Previous day'!Q25 -> #REF! | R25: =#REF!-'Previous day'!R25 -> #REF! | S25: =#REF!-'Previous day'!S25 -> #REF! | T25: =#REF!-'Previous day'!T25 -> #REF! | U25: =#REF!-'Previous day'!U25 -> #REF! | ... AB25: =#REF!-'Previous day'!AB25 -> #REF!
B26: =B25+1 -> 44457 | C26: =TEXT(B26,"ddd") -> Sat | D26: =#REF!-'Previous day'!D26 -> #REF! | F26: =SUMPRODUCT($D$6:$E$6,D26:E26) -> #REF! | G26: =#REF!-'Previous day'!G26 -> #REF! | J26: =#REF!-'Previous day'!J26 -> #REF! | K26: =#REF!-'Previous day'!K26 -> #REF! | N26: =#REF!-'Previous day'!N26 -> #REF! | O26: =#REF!-'Previous day'!O26 -> #REF! | P26: =#REF!-'Previous day'!P26 -> #REF! | Q26: =#REF!-'Previous day'!Q26 -> #REF! | R26: =#REF!-'Previous day'!R26 -> #REF! | S26: =#REF!-'Previous day'!S26 -> #REF! | T26: =#REF!-'Previous day'!T26 -> #REF! | U26: =#REF!-'Previous day'!U26 -> #REF! | ... AB26: =#REF!-'Previous day'!AB26 -> #REF!
B27: =B26+1 -> 44458 | C27: =TEXT(B27,"ddd") -> Sun | D27: =#REF!-'Previous day'!D27 -> #REF! | F27: =SUMPRODUCT($D$6:$E$6,D27:E27) -> #REF! | G27: =#REF!-'Previous day'!G27 -> #REF! | J27: =#REF!-'Previous day'!J27 -> #REF! | K27: =#REF!-'Previous day'!K27 -> #REF! | N27: =#REF!-'Previous day'!N27 -> #REF! | O27: =#REF!-'Previous day'!O27 -> #REF! | P27: =#REF!-'Previous day'!P27 -> #REF! | Q27: =#REF!-'Previous day'!Q27 -> #REF! | R27: =#REF!-'Previous day'!R27 -> #REF! | S27: =#REF!-'Previous day'!S27 -> #REF! | T27: =#REF!-'Previous day'!T27 -> #REF! | U27: =#REF!-'Previous day'!U27 -> #REF! | ... AB27: =#REF!-'Previous day'!AB27 -> #REF!
B28: =B27+1 -> 44459 | C28: =TEXT(B28,"ddd") -> Mon | D28: =#REF!-'Previous day'!D28 -> #REF! | F28: =SUMPRODUCT($D$6:$E$6,D28:E28) -> #REF! | G28: =#REF!-'Previous day'!G28 -> #REF! | J28: =#REF!-'Previous day'!J28 -> #REF! | K28: =#REF!-'Previous day'!K28 -> #REF! | L28: 0.75416667 | M28: 0.75694444 | N28: =#REF!-'Previous day'!N28 -> #REF! | O28: =#REF!-'Previous day'!O28 -> #REF! | P28: =#REF!-'Previous day'!P28 -> #REF! | Q28: =#REF!-'Previous day'!Q28 -> #REF! | R28: =#REF!-'Previous day'!R28 -> #REF! | S28: =#REF!-'Previous day'!S28 -> #REF! | T28: =#REF!-'Previous day'!T28 -> #REF! | U28: =#REF!-'Previous day'!U28 -> #REF! | ... AB28: =#REF!-'Previous day'!AB28 -> #REF!
B29: =B28+1 -> 44460 | C29: =TEXT(B29,"ddd") -> Tue | D29: =#REF!-'Previous day'!D29 -> #REF! | F29: =SUMPRODUCT($D$6:$E$6,D29:E29) -> #REF! | G29: =#REF!-'Previous day'!G29 -> #REF! | J29: =#REF!-'Previous day'!J29 -> #REF! | K29: =#REF!-'Previous day'!K29 -> #REF! | N29: =#REF!-'Previous day'!N29 -> #REF! | O29: =#REF!-'Previous day'!O29 -> #REF! | P29: =#REF!-'Previous day'!P29 -> #REF! | Q29: =#REF!-'Previous day'!Q29 -> #REF! | R29: =#REF!-'Previous day'!R29 -> #REF! | S29: =#REF!-'Previous day'!S29 -> #REF! | T29: =#REF!-'Previous day'!T29 -> #REF! | U29: =#REF!-'Previous day'!U29 -> #REF! | ... AB29: =#REF!-'Previous day'!AB29 -> #REF!
B30: =B29+1 -> 44461 | C30: =TEXT(B30,"ddd") -> Wed | D30: =#REF!-'Previous day'!D30 -> #REF! | F30: =SUMPRODUCT($D$6:$E$6,D30:E30) -> #REF! | G30: =#REF!-'Previous day'!G30 -> #REF! | J30: =#REF!-'Previous day'!J30 -> #REF! | K30: =#REF!-'Previous day'!K30 -> #REF! | N30: =#REF!-'Previous day'!N30 -> #REF! | O30: =#REF!-'Previous day'!O30 -> #REF! | P30: =#REF!-'Previous day'!P30 -> #REF! | Q30: =#REF!-'Previous day'!Q30 -> #REF! | R30: =#REF!-'Previous day'!R30 -> #REF! | S30: =#REF!-'Previous day'!S30 -> #REF! | T30: =#REF!-'Previous day'!T30 -> #REF! | U30: =#REF!-'Previous day'!U30 -> #REF! | ... AB30: =#REF!-'Previous day'!AB30 -> #REF!
B31: =B30+1 -> 44462 | C31: =TEXT(B31,"ddd") -> Thu | D31: =#REF!-'Previous day'!D31 -> #REF! | F31: =SUMPRODUCT($D$6:$E$6,D31:E31) -> #REF! | G31: =#REF!-'Previous day'!G31 -> #REF! | J31: =#REF!-'Previous day'!J31 -> #REF! | K31: =#REF!-'Previous day'!K31 -> #REF! | N31: =#REF!-'Previous day'!N31 -> #REF! | O31: =#REF!-'Previous day'!O31 -> #REF! | P31: =#REF!-'Previous day'!P31 -> #REF! | Q31: =#REF!-'Previous day'!Q31 -> #REF! | R31: =#REF!-'Previous day'!R31 -> #REF! | S31: =#REF!-'Previous day'!S31 -> #REF! | T31: =#REF!-'Previous day'!T31 -> #REF! | U31: =#REF!-'Previous day'!U31 -> #REF! | ... AB31: =#REF!-'Previous day'!AB31 -> #REF!
B32: =B31+1 -> 44463 | C32: =TEXT(B32,"ddd") -> Fri | D32: =#REF!-'Previous day'!D32 -> #REF! | F32: =SUMPRODUCT($D$6:$E$6,D32:E32) -> #REF! | G32: =#REF!-'Previous day'!G32 -> #REF! | J32: =#REF!-'Previous day'!J32 -> #REF! | K32: =#REF!-'Previous day'!K32 -> #REF! | N32: =#REF!-'Previous day'!N32 -> #REF! | O32: =#REF!-'Previous day'!O32 -> #REF! | P32: =#REF!-'Previous day'!P32 -> #REF! | Q32: =#REF!-'Previous day'!Q32 -> #REF! | R32: =#REF!-'Previous day'!R32 -> #REF! | S32: =#REF!-'Previous day'!S32 -> #REF! | T32: =#REF!-'Previous day'!T32 -> #REF! | U32: =#REF!-'Previous day'!U32 -> #REF! | ... AB32: =#REF!-'Previous day'!AB32 -> #REF!
B33: =B32+1 -> 44464 | C33: =TEXT(B33,"ddd") -> Sat | D33: =#REF!-'Previous day'!D33 -> #REF! | F33: =SUMPRODUCT($D$6:$E$6,D33:E33) -> #REF! | G33: =#REF!-'Previous day'!G33 -> #REF! | J33: =#REF!-'Previous day'!J33 -> #REF! | K33: =#REF!-'Previous day'!K33 -> #REF! | N33: =#REF!-'Previous day'!N33 -> #REF! | O33: =#REF!-'Previous day'!O33 -> #REF! | P33: =#REF!-'Previous day'!P33 -> #REF! | Q33: =#REF!-'Previous day'!Q33 -> #REF! | R33: =#REF!-'Previous day'!R33 -> #REF! | S33: =#REF!-'Previous day'!S33 -> #REF! | T33: =#REF!-'Previous day'!T33 -> #REF! | U33: =#REF!-'Previous day'!U33 -> #REF! | ... AB33: =#REF!-'Previous day'!AB33 -> #REF!
B34: =B33+1 -> 44465 | C34: =TEXT(B34,"ddd") -> Sun | D34: =#REF!-'Previous day'!D34 -> #REF! | F34: =SUMPRODUCT($D$6:$E$6,D34:E34) -> #REF! | G34: =#REF!-'Previous day'!G34 -> #REF! | J34: =#REF!-'Previous day'!J34 -> #REF! | K34: =#REF!-'Previous day'!K34 -> #REF! | N34: =#REF!-'Previous day'!N34 -> #REF! | O34: =#REF!-'Previous day'!O34 -> #REF! | P34: =#REF!-'Previous day'!P34 -> #REF! | Q34: =#REF!-'Previous day'!Q34 -> #REF! | R34: =#REF!-'Previous day'!R34 -> #REF! | S34: =#REF!-'Previous day'!S34 -> #REF! | T34: =#REF!-'Previous day'!T34 -> #REF! | U34: =#REF!-'Previous day'!U34 -> #REF! | ... AB34: =#REF!-'Previous day'!AB34 -> #REF!
B35: =B34+1 -> 44466 | C35: =TEXT(B35,"ddd") -> Mon | D35: =#REF!-'Previous day'!D35 -> #REF! | F35: =SUMPRODUCT($D$6:$E$6,D35:E35) -> #REF! | G35: =#REF!-'Previous day'!G35 -> #REF! | J35: =#REF!-'Previous day'!J35 -> #REF! | K35: =#REF!-'Previous day'!K35 -> #REF! | N35: =#REF!-'Previous day'!N35 -> #REF! | O35: =#REF!-'Previous day'!O35 -> #REF! | P35: =#REF!-'Previous day'!P35 -> #REF! | Q35: =#REF!-'Previous day'!Q35 -> #REF! | R35: =#REF!-'Previous day'!R35 -> #REF! | S35: =#REF!-'Previous day'!S35 -> #REF! | T35: =#REF!-'Previous day'!T35 -> #REF! | U35: =#REF!-'Previous day'!U35 -> #REF! | ... AB35: =#REF!-'Previous day'!AB35 -> #REF!
B36: =B35+1 -> 44467 | C36: =TEXT(B36,"ddd") -> Tue | D36: =#REF!-'Previous day'!D36 -> #REF! | F36: =SUMPRODUCT($D$6:$E$6,D36:E36) -> #REF! | G36: =#REF!-'Previous day'!G36 -> #REF! | J36: =#REF!-'Previous day'!J36 -> #REF! | K36: =#REF!-'Previous day'!K36 -> #REF! | N36: =#REF!-'Previous day'!N36 -> #REF! | O36: =#REF!-'Previous day'!O36 -> #REF! | P36: =#REF!-'Previous day'!P36 -> #REF! | Q36: =#REF!-'Previous day'!Q36 -> #REF! | R36: =#REF!-'Previous day'!R36 -> #REF! | S36: =#REF!-'Previous day'!S36 -> #REF! | T36: =#REF!-'Previous day'!T36 -> #REF! | U36: =#REF!-'Previous day'!U36 -> #REF! | ... AB36: =#REF!-'Previous day'!AB36 -> #REF!
B37: =B36+1 -> 44468 | C37: =TEXT(B37,"ddd") -> Wed | D37: =#REF!-'Previous day'!D37 -> #REF! | F37: =SUMPRODUCT($D$6:$E$6,D37:E37) -> #REF! | G37: =#REF!-'Previous day'!G37 -> #REF! | J37: =#REF!-'Previous day'!J37 -> #REF! | K37: =#REF!-'Previous day'!K37 -> #REF! | N37: =#REF!-'Previous day'!N37 -> #REF! | O37: =#REF!-'Previous day'!O37 -> #REF! | P37: =#REF!-'Previous day'!P37 -> #REF! | Q37: =#REF!-'Previous day'!Q37 -> #REF! | R37: =#REF!-'Previous day'!R37 -> #REF! | S37: =#REF!-'Previous day'!S37 -> #REF! | T37: =#REF!-'Previous day'!T37 -> #REF! | U37: =#REF!-'Previous day'!U37 -> #REF! | ... AB37: =#REF!-'Previous day'!AB37 -> #REF!
B38: =B37+1 -> 44469 | C38: =TEXT(B38,"ddd") -> Thu | D38: =#REF!-'Previous day'!D38 -> #REF! | F38: =SUMPRODUCT($D$6:$E$6,D38:E38) -> #REF! | G38: =#REF!-'Previous day'!G38 -> #REF! | J38: =#REF!-'Previous day'!J38 -> #REF! | K38: =#REF!-'Previous day'!K38 -> #REF! | N38: =#REF!-'Previous day'!N38 -> #REF! | O38: =#REF!-'Previous day'!O38 -> #REF! | P38: =#REF!-'Previous day'!P38 -> #REF! | Q38: =#REF!-'Previous day'!Q38 -> #REF! | R38: =#REF!-'Previous day'!R38 -> #REF! | S38: =#REF!-'Previous day'!S38 -> #REF! | T38: =#REF!-'Previous day'!T38 -> #REF! | U38: =#REF!-'Previous day'!U38 -> #REF! | ... AB38: =#REF!-'Previous day'!AB38 -> #REF!
B39: TOTAL / AVERAGE | D39: =#REF!-'Previous day'!D39 -> #REF! | E39: =#REF!-'Previous day'!E39 -> #REF! | F39: =#REF!-'Previous day'!F39 -> #REF! | G39: =#REF!-'Previous day'!G39 -> #REF! | H39: =#REF!-'Previous day'!H39 -> #REF! | I39: =#REF!-'Previous day'!I39 -> #REF! | J39: =#REF!-'Previous day'!J39 -> #REF! | K39: =#REF!-'Previous day'!K39 -> #REF! | ... AC39: =#REF!-'Previous day'!AC39 -> #REF!

Sheet Previous day
B2: Note: Recording should be done 1st hour of the day
B3: DAILY BIOGAS USAGE MONITORING | X3: Waste Hauling Operation | AA3: Biogas Operation Utility Consumption | AC3: Remarks
B4: Date | C4: Day | D4: Gas Storage (%) | G4: Quality | H4: Gas Meters (mᶾ) | L4: Gas Flare | O4: Gas Engine Power Meter (kWh) | Q4: Diesel Fuel Consumption | T4: Ope. Hrs | V4: Ope. Hrs w/ Biogas
D5: F1 | E5: F2 | F5: Total | G5: Methane Content | H5: Gas Engine Line Totalizer | J5: Boiler Line Totalizer | L5: Time | N5: Total Volume | Q5: Thermax | R5: Cleaver Brooks | S5: Total | T5: Thermax | U5: Cleaver Brooks | V5: Thermax | W5: Cleaver Brooks | X5: Actual Waste Delivered (MT) | Z5: % DS | AA5: Electricity | AB5: Water
D6: 8350 | E6: 8350 | G6: 0.55 | H6: Totalizer | I6: Output | J6: Totalizer | K6: Output | L6: Start | M6: End | N6: Nm³ | O6: Totalizer | P6: Output | Q6: Li. | R6: Li. | S6: Li. | T6: Hrs | U6: Hrs | V6: Hrs | W6: Hrs | X6: Delivery | Y6: Cummulative | AA6: kWhr | AB6: m³
B7: 44438 | C7: =TEXT(B7,"ddd") -> Mon | D7: 0.43 | F7: =SUMPRODUCT($D$6:$E$6,D7:E7) -> 3590.5 | G7: 0.551 | J7: 3344 | K7: 3344 | Q7: 3388 | R7: 1440 | S7: =SUM(Q7:R7) -> 4828 | T7: 9.4 | U7: 12 | V7: 9.4 | W7: 9.11 | X7: 59.038 | Y7: =X7 -> 59.038 | AA7: 16 | AB7: 2 | AC7: 1S
B8: =B7+1 -> 44439 | C8: =TEXT(B8,"ddd") -> Tue | D8: 0.98 | F8: =SUMPRODUCT($D$6:$E$6,D8:E8) -> 8183 | G8: 0.555 | J8: 6702 | K8: =J8-J7 -> 3358 | Q8: 7679 | R8: 5060 | S8: =SUM(Q8:R8) -> 12739 | T8: 21 | U8: 20 | V8: 21 | W8: 6.9 | X8: 227.29 | Y8: =X8+Y7 -> 286.328 | AA8: 18 | AB8: 2 | AC8: 2S
B9: =B8+1 -> 44440 | C9: =TEXT(B9,"ddd") -> Wed | D9: 0.38 | F9: =SUMPRODUCT($D$6:$E$6,D9:E9) -> 3173 | G9: 0.613 | J9: 15033 | K9: =J9-J8 -> 8331 | L9: 0.29166667 | M9: 0.37152778 | N9: 780 | Q9: 8279 | R9: 1870 | S9: =SUM(Q9:R9) -> 10149 | T9: 21 | U9: 20.9 | V9: 21 | W9: 22.3 | X9: 178.848 | Y9: =X9+Y8 -> 465.176 | AA9: 29 | AB9: 6 | AC9: 2S
B10: =B9+1 -> 44441 | C10: =TEXT(B10,"ddd") -> Thu | D10: 0.31 | F10: =SUMPRODUCT($D$6:$E$6,D10:E10) -> 2588.5 | G10: 0.554 | J10: 20175 | K10: =J10-J9 -> 5142 | Q10: 4823 | R10: 2040 | S10: =SUM(Q10:R10) -> 6863 | T10: 12.4 | U10: 17.2 | V10: 12.4 | W10: 12.4 | X10: 132.498 | Y10: =X10+Y9 -> 597.674 | AA10: 39 | AB10: 3 | AC10: 1S
B11: =B10+1 -> 44442 | C11: =TEXT(B11,"ddd") -> Fri | D11: 0.46 | F11: =SUMPRODUCT($D$6:$E$6,D11:E11) -> 3841 | G11: 0.562 | J11: 28496 | K11: =J11-J10 -> 8321 | Q11: 8786 | R11: 2360 | S11: =SUM(Q11:R11) -> 11146 | T11: 22 | U11: 22.3 | V11: 22 | W11: 20.15 | X11: 280.984 | Y11: =X11+Y10 -> 878.658 | AA11: 40 | AB11: 2 | AC11: 2S
B12: =B11+1 -> 44443 | C12: =TEXT(B12,"ddd") -> Sat | D12: 1 | F12: =SUMPRODUCT($D$6:$E$6,D12:E12) -> 8350 | G12: 0.589 | J12: 29766 | K12: =J12-J11 -> 1270 | L12: 0.61319444 | M12: 0.67777778 | N12: 624 | Q12: 1173 | R12: 1385 | S12: =SUM(Q12:R12) -> 2558 | T12: 3.3 | U12: 6.7 | V12: 3.3 | W12: 2.68 | X12: 5.668 | Y12: =X12+Y11 -> 884.326 | AA12: 34 | AB12: 3 | AC12: Non-canning
B13: =B12+1 -> 44444 | C13: =TEXT(B13,"ddd") -> Sun | D13: 1 | F13: =SUMPRODUCT($D$6:$E$6,D13:E13) -> 8350 | G13: 0.571 | J13: 34096 | K13: =J13-J12 -> 4330 | L13: 0.26041667 | M13: 0.54861111 | N13: 3308 | Q13: 3391 | R13: 1015 | S13: =SUM(Q13:R13) -> 4406 | T13: 8.8 | U13: 11.6 | V13: 8.8 | W13: 10.62 | X13: 84.344 | Y13: =X13+Y12 -> 968.67 | AA13: 33 | AB13: 4 | AC13: 1S
B14: =B13+1 -> 44445 | C14: =TEXT(B14,"ddd") -> Mon | D14: 0.78 | F14: =SUMPRODUCT($D$6:$E$6,D14:E14) -> 6513 | G14: 0.562 | J14: 43336 | K14: =J14-J13 -> 9240 | Q14: 8017 | R14: 1500 | S14: =SUM(Q14:R14) -> 9517 | T14: 21 | U14: 20.4 | V14: 21 | W14: 23 | X14: 265.374 | Y14: =X14+Y13 -> 1234.044 | Z14: 0.13 | AA14: 30 | AB14: 3 | AC14: 2S
B15: =B14+1 -> 44446 | C15: =TEXT(B15,"ddd") -> Tue | D15: 0.83 | F15: =SUMPRODUCT($D$6:$E$6,D15:E15) -> 6930.5 | G15: 0.559 | J15: 51855 | K15: =J15-J14 -> 8519 | Q15: 8138 | R15: 1570 | S15: =SUM(Q15:R15) -> 9708 | T15: 20.8 | U15: 21.5 | V15: 20.8 | W15: 23.2 | X15: 164.62 | Y15: =X15+Y14 -> 1398.664 | Z15: 0.0817 | AA15: 31 | AB15: 2 | AC15: 2S
B16: =B15+1 -> 44447 | C16: =TEXT(B16,"ddd") -> Wed | D16: 0.83 | F16: =SUMPRODUCT($D$6:$E$6,D16:E16) -> 6930.5 | G16: 0.557 | J16: 57753 | K16: =J16-J15 -> 5898 | Q16: 5315 | R16: 1620 | S16: =SUM(Q16:R16) -> 6935 | T16: 14.3 | U16: 18.5 | V16: 14.3 | W16: 14.42 | X16: 149.432 | Y16: =X16+Y15 -> 1548.096 | Z16: 0.1183 | AA16: 35 | AB16: 2 | AC16: 1S
B17: =B16+1 -> 44448 | C17: =TEXT(B17,"ddd") -> Thu | D17: 0.3 | F17: =SUMPRODUCT($D$6:$E$6,D17:E17) -> 2505 | G17: 0.565 | J17: 65969 | K17: =J17-J16 -> 8216 | L17: 0.29930556 | M17: 0.31527778 | N17: 138 | Q17: 7517 | R17: 1940 | S17: =SUM(Q17:R17) -> 9457 | T17: 18.3 | U17: 21.3 | V17: 18.3 | W17: 21 | X17: 253 | Y17: =X17+Y16 -> 1801.096 | Z17: 0.1072 | AA17: 35 | AB17: 3 | AC17: 2S
B18: =B17+1 -> 44449 | C18: =TEXT(B18,"ddd") -> Fri | D18: 0.45 | F18: =SUMPRODUCT($D$6:$E$6,D18:E18) -> 3757.5 | G18: 0.563 | J18: 75077 | K18: =J18-J17 -> 9108 | Q18: 8304 | R18: 1870 | S18: =SUM(Q18:R18) -> 10174 | T18: 21.6 | U18: 21.5 | V18: 21.6 | W18: 22.54 | X18: 252.1 | Y18: =X18+Y17 -> 2053.196 | Z18: 0.1231 | AA18: 40 | AB18: 3 | AC18: 2S
B19: =B18+1 -> 44450 | C19: =TEXT(B19,"ddd") -> Sat | D19: 0.68 | F19: =SUMPRODUCT($D$6:$E$6,D19:E19) -> 5678 | G19: 0.558 | J19: 77261 | K19: =J19-J18 -> 2184 | L19: 0.67708333 | M19: 0.72222222 | N19: 443 | Q19: 1437 | R19: 1050 | S19: =SUM(Q19:R19) -> 2487 | T19: 4 | U19: 8.5 | V19: 4 | W19: 4.52 | X19: 0 | Y19: =X19+Y18 -> 2053.196 | AA19: 37 | AB19: 4 | AC19: Non-canning
B20: =B19+1 -> 44451 | C20: =TEXT(B20,"ddd") -> Sun | D20: 0.75 | F20: =SUMPRODUCT($D$6:$E$6,D20:E20) -> 6262.5 | J20: 77261 | K20: =J20-J19 -> 0 | X20: 0 | Y20: =X20+Y19 -> 2053.196 | Z20: 0.1242 | AA20: 33 | AB20: 2 | AC20: Non-canning
B21: =B20+1 -> 44452 | C21: =TEXT(B21,"ddd") -> Mon | D21: 0.8 | F21: =SUMPRODUCT($D$6:$E$6,D21:E21) -> 6680 | G21: 0.55 | J21: 85285 | K21: =J21-J20 -> 8024 | L21: 0.35069444 | M21: 0.36527778 | N21: 136 | Q21: 5730 | R21: 1990 | S21: =SUM(Q21:R21) -> 7720 | T21: 15.6 | U21: 18.8 | V21: 15.6 | W21: 19.5 | X21: 79.2 | Y21: =X21+Y20 -> 2132.396 | Z21: 0.1119 | AA21: 36 | AB21: 3 | AC21: 2S
B22: =B21+1 -> 44453 | C22: =TEXT(B22,"ddd") -> Tue | D22: 0.82 | F22: =SUMPRODUCT($D$6:$E$6,D22:E22) -> 6847 | G22: 0.571 | J22: 93506 | K22: =J22-J21 -> 8221 | Q22: 7274 | R22: 1925 | S22: =SUM(Q22:R22) -> 9199 | T22: 20.3 | U22: 20.5 | V22: 20.3 | W22: 22.1 | X22: 156.4 | Y22: =X22+Y21 -> 2288.796 | AA22: 28 | AB22: 2 | AC22: 2S
B23: =B22+1 -> 44454 | C23: =TEXT(B23,"ddd") -> Wed | D23: 0.81 | F23: =SUMPRODUCT($D$6:$E$6,D23:E23) -> 6763.5 | G23: 0.568 | J23: 95100 | K23: =J23-J22 -> 1594 | Q23: 3951 | R23: 3520 | S23: =SUM(Q23:R23) -> 7471 | T23: 10 | U23: 14 | V23: 10 | W23: 3 | X23: 99.5 | Y23: =X23+Y22 -> 2388.296 | AA23: 33 | AB23: 1 | AC23: 1S
B24: =B23+1 -> 44455 | C24: =TEXT(B24,"ddd") -> Thu | D24: 0.8 | F24: =SUMPRODUCT($D$6:$E$6,D24:E24) -> 6680 | G24: 0.568 | J24: 95100 | K24: =J24-J23 -> 0 | Q24: 8010 | R24: 6510 | S24: =SUM(Q24:R24) -> 14520 | T24: 23 | U24: 23 | V24: 23 | X24: 158.3 | Y24: =X24+Y23 -> 2546.596 | Z24: 0.1126 | AA24: 39 | AB24: 4 | AC24: 2S
B25: =B24+1 -> 44456 | C25: =TEXT(B25,"ddd") -> Fri | D25: 0.85 | F25: =SUMPRODUCT($D$6:$E$6,D25:E25) -> 7097.5 | J25: 95100 | K25: =J25-J24 -> 0 | Q25: 5763 | R25: 5800 | S25: =SUM(Q25:R25) -> 11563 | T25: 16.6 | U25: 20 | V25: 16.6 | X25: 77.4 | Y25: =X25+Y24 -> 2623.996 | Z25: 0.1036 | AA25: 45 | AB25: 1 | AC25: 1S
B26: =B25+1 -> 44457 | C26: =TEXT(B26,"ddd") -> Sat | D26: 0.93 | F26: =SUMPRODUCT($D$6:$E$6,D26:E26) -> 7765.5 | J26: 95100 | K26: =J26-J25 -> 0 | Y26: =X26+Y25 -> 2623.996 | AA26: 35 | AB26: 1 | AC26: Non-canning
B27: =B26+1 -> 44458 | C27: =TEXT(B27,"ddd") -> Sun | D27: 0.96 | F27: =SUMPRODUCT($D$6:$E$6,D27:E27) -> 8016 | J27: 95100 | K27: =J27-J26 -> 0 | Y27: =X27+Y26 -> 2623.996 | AA27: 30 | AB27: 2 | AC27: Non-canning
B28: =B27+1 -> 44459 | C28: =TEXT(B28,"ddd") -> Mon | D28: 0.97 | F28: =SUMPRODUCT($D$6:$E$6,D28:E28) -> 8099.5 | G28: 0.559 | J28: 95100 | K28: =J28-J27 -> 0 | L28: 0.75416667 | M28: 0.75694444 | N28: 17 | Q28: 4558 | S28: =SUM(Q28:R28) -> 4558 | T28: 8.4 | V28: 8.4 | X28: 11 | Y28: =X28+Y27 -> 2634.996 | AA28: 31 | AB28: 3 | AC28: 1S
B29: =B28+1 -> 44460 | C29: =TEXT(B29,"ddd") -> Tue | D29: 0.6715 | F29: =SUMPRODUCT($D$6:$E$6,D29:E29) -> 5607.025 | G29: 0.565 | J29: 100184 | K29: =J29-J28 -> 5084 | Q29: 7654 | R29: 1690 | S29: =SUM(Q29:R29) -> 9344 | T29: 20 | U29: 18 | V29: 20 | X29: 92.2 | Y29: =X29+Y28 -> 2727.196 | AA29: 84 | AB29: 11 | AC29: 2S
B30: =B29+1 -> 44461 | C30: =TEXT(B30,"ddd") -> Wed | D30: 0.5 | F30: =SUMPRODUCT($D$6:$E$6,D30:E30) -> 4175 | G30: 0.556 | J30: 105987 | K30: =J30-J29 -> 5803 | Q30: 5681 | R30: 2240 | S30: =SUM(Q30:R30) -> 7921 | T30: 15.3 | U30: 17.9 | V30: 15.3 | W30: 13 | X30: 95.4 | Y30: =X30+Y29 -> 2822.596 | AA30: 36 | AB30: 3 | AC30: 1S
B31: =B30+1 -> 44462 | C31: =TEXT(B31,"ddd") -> Thu | D31: 0.4 | F31: =SUMPRODUCT($D$6:$E$6,D31:E31) -> 3340 | G31: 0.554 | J31: 111055 | K31: =J31-J30 -> 5068 | Q31: 4114 | R31: 2150 | S31: =SUM(Q31:R31) -> 6264 | T31: 11.2 | U31: 16.6 | V31: 11.2 | W31: 12.11 | X31: 65.8 | Y31: =X31+Y30 -> 2888.396 | Z31: 0.1237 | AA31: 80 | AB31: 6 | AC31: 1S
B32: =B31+1 -> 44463 | C32: =TEXT(B32,"ddd") -> Fri | D32: 0.67 | F32: =SUMPRODUCT($D$6:$E$6,D32:E32) -> 5594.5 | J32: 111055 | K32: =J32-J31 -> 0 | Y32: =X32+Y31 -> 2888.396 | AA32: 90 | AB32: 3 | AC32: Non-canning
B33: =B32+1 -> 44464 | C33: =TEXT(B33,"ddd") -> Sat | D33: 0.82 | F33: =SUMPRODUCT($D$6:$E$6,D33:E33) -> 6847 | G33: 0.553 | J33: 111055 | K33: =J33-J32 -> 0 | Y33: =X33+Y32 -> 2888.396 | AA33: 66 | AB33: 2 | AC33: Non-canning
B34: =B33+1 -> 44465 | C34: =TEXT(B34,"ddd") -> Sun | D34: 0.43 | F34: =SUMPRODUCT($D$6:$E$6,D34:E34) -> 3590.5 | G34: 0.553 | J34: 114243 | K34: =J34-J33 -> 3188 | Q34: 3156 | R34: 1300 | S34: =SUM(Q34:R34) -> 4456 | T34: 8.7 | U34: 11.3 | V34: 8.7 | W34: 8.8 | X34: 66.9 | Y34: =X34+Y33 -> 2955.296 | AA34: 154 | AB34: 3 | AC34: 1S
B35: =B34+1 -> 44466 | C35: =TEXT(B35,"ddd") -> Mon | D35: 0.1831 | F35: =SUMPRODUCT($D$6:$E$6,D35:E35) -> 1528.885 | G35: 0.558 | J35: 123660 | K35: =J35-J34 -> 9417 | Q35: 8280 | R35: 1785 | S35: =SUM(Q35:R35) -> 10065 | T35: 20.2 | U35: 20.1 | V35: 20.2 | W35: 20.81 | X35: 112.5 | Y35: =X35+Y34 -> 3067.796 | Z35: 0.1307 | AA35: 281 | AB35: 2 | AC35: 2S
B36: =B35+1 -> 44467 | C36: =TEXT(B36,"ddd") -> Tue | D36: 0.1577 | F36: =SUMPRODUCT($D$6:$E$6,D36:E36) -> 1316.795 | G36: 0.552 | J36: 133863 | K36: =J36-J35 -> 10203 | Q36: 9085 | R36: 1800 | S36: =SUM(Q36:R36) -> 10885 | T36: 20 | U36: 20.1 | V36: 20 | W36: 21.55 | X36: 175.1 | Y36: =X36+Y35 -> 3242.896 | Z36: 0.1126 | AA36: 269 | AB36: 3 | AC36: 2S
B37: =B36+1 -> 44468 | S37: =SUM(Q37:R37) -> 0
B38: =B37+1 -> 44469 | C38: =TEXT(B38,"ddd") -> Thu | F38: =SUMPRODUCT($D$6:$E$6,D38:E38) -> 0 | S38: =SUM(Q38:R38) -> 0
B39: TOTAL / AVERAGE | K39: =SUM(K7:K38) -> 133863 | S39: =SUM(Q39:R39) -> 0 | Y39: =Y38 -> 0 | Z39: =AVERAGE(Z7:Z38) -> 0.11496667

Sheet Template (3)
B2: Note: Recording should be done 1st hour of the day
B3: DAILY BIOGAS USAGE MONITORING | U3: Waste Hauling Operation | W3: Biogas Operation Utility Consumption | AC3: Remarks/ Shifts
B4: Date | C4: Day | D4: Quality | E4: Gas Meters (Nmᶾ) | M4: Gas Flare | P4: Gas Engine 1 Power Meter (kWh) | R4: Gas Engine 2 Power Meter (kWh) | T4: Diesel Usage
D5: Methane Content | E5: Gas Engine Line Totalizer | G5: Thermax Gas Totalizer 1 | I5: Thermax Gas Totalizer 2 | K5: CB Gas Totalizer | M5: Time | O5: Total Volume | U5: Actual Waste Delivered (MT) | W5: Electricity @ Biogas plant, kWhr | Y5: Electricity @ DPO cannery, kWhr | AA5: Water, m3
D6: 55% Min | E6: Totalizer | F6: Output | G6: Totalizer | H6: Output | I6: Totalizer | J6: Output | K6: Totalizer | L6: Output | M6: Start | N6: End | O6: Nm³ | P6: Totalizer | Q6: Output | R6: Totalizer | S6: Output | T6: Output | U6: Delivered | V6: Rejected | W6: Totalizer | X6: Consumed | Y6: Totalizer | Z6: Consumed | AA6: Totalizer | AB6: Consumed
B7: Previous
B8: 45474 | C8: =TEXT(B8,"ddd") -> Mon
B9: =B8+1 -> 45475 | C9: =TEXT(B9,"ddd") -> Tue
B10: =B9+1 -> 45476 | C10: =TEXT(B10,"ddd") -> Wed
B11: =B10+1 -> 45477 | C11: =TEXT(B11,"ddd") -> Thu
B12: =B11+1 -> 45478 | C12: =TEXT(B12,"ddd") -> Fri
B13: =B12+1 -> 45479 | C13: =TEXT(B13,"ddd") -> Sat
B14: =B13+1 -> 45480 | C14: =TEXT(B14,"ddd") -> Sun
B15: =B14+1 -> 45481 | C15: =TEXT(B15,"ddd") -> Mon
B16: =B15+1 -> 45482 | C16: =TEXT(B16,"ddd") -> Tue
B17: =B16+1 -> 45483 | C17: =TEXT(B17,"ddd") -> Wed
B18: =B17+1 -> 45484 | C18: =TEXT(B18,"ddd") -> Thu
B19: =B18+1 -> 45485 | C19: =TEXT(B19,"ddd") -> Fri
B20: =B19+1 -> 45486 | C20: =TEXT(B20,"ddd") -> Sat
... B38: =B37+1 -> 45504 | C38: =TEXT(B38,"ddd") -> Wed
B39: Total/Average | G39: =SUM(G8:G38) -> 0 | H39: =SUM(H8:H38) -> 0 | I39: =SUM(I8:I38) -> 0 | J39: =SUM(J8:J38) -> 0 | K39: =SUM(K8:K38) -> 0 | L39: =SUM(L8:L38) -> 0 | M39: =SUM(M8:M38) -> 0 | N39: =SUM(N8:N38) -> 0 | ... S39: =SUM(S8:S38) -> 0 | U39: =SUM(U8:U38) -> 0 | V39: =SUM(V8:V38) -> 0 | W39: =SUM(W8:W38) -> 0 | X39: =SUM(X8:X38) -> 0 | Y39: =SUM(Y8:Y38) -> 0 | Z39: =SUM(Z8:Z38) -> 0 | AA39: =SUM(AA8:AA38) -> 0 | AB39: =SUM(AB8:AB38) -> 0

Sheet Template
B2: Note: Recording should be done 1st hour of the day
B3: DAILY BIOGAS USAGE MONITORING | AA3: Gas Storage [%] | AE3: Biogas Operation Utility Consumption | AK3: Remarks/ Shifts
B4: Date | C4: Day | D4: Quality | E4: Gas Meters (Nmᶾ) | M4: Gas Flare | R4: Gas Engine 1 Power Meter (kWh) | T4: Gas Engine 2 Power Meter (kWh) | V4: Deisel Consumption 1 | X4: Deisel Consumption 2 | Z4: Diesel Usage
D5: Methane Content | E5: Gas Engine Line Totalizer | G5: Thermax Gas Totalizer 1 | I5: Thermax Gas Totalizer 2 | K5: CB Gas Totalizer | M5: Time | O5: Totalizer | Q5: Total Volume | AA5: Actual Waste Delivered (MT) | AE5: Electricity @ Biogas plant, kWhr | AG5: Electricity @ DPO cannery, kWhr | AI5: Water, m3
G6: 5216835 | H6: 19296 | I6: 13751980 | J6: 1960 | R6: 1981802 | S6: 0 | T6: 7865075 | U6: 19347 | V6: 741235 | W6: 0 | X6: 1058377 | Y6: 0 | Z6: 0 | AA6: 0.68477249 | AB6: -0.46808212 | AC6: -0.62499996 | AD6: -3409.3851 | AE6: 4624927 | AF6: 4356 | AG6: 760085 | AH6: 1244 | AI6: 115191 | AJ6: 302
D7: 55% Min | E7: Totalizer | F7: Output | G7: Totalizer | H7: Output | I7: Totalizer | J7: Output | K7: Totalizer | L7: Output | M7: Start | N7: End | Q7: Nm³ | R7: Totalizer | S7: Output | T7: Totalizer | U7: Output | V7: Totalizer | W7: Output | X7: Totalizer | Y7: Output | Z7: Output | AA7: 8350 | AB7: 8350 | AC7: 8350 | AD7: =SUM(AA7:AC7) -> 25050 | AE7: Totalizer | AF7: Consumed | AG7: Totalizer | AH7: Consumed | AI7: Totalizer | AJ7: Consumed
B8: Previous | R8: 1981802 | AD8: 2070.1706
B9: 45962 | C9: =TEXT(B9,"ddd") -> Sat | G9: 5232773 | H9: =G9-G6 -> 15938 | I9: 13761455 | J9: =I9-I6 -> 9475 | M9: 0716h | N9: 0900h | O9: 1903996 | P9: 1904793 | Q9: =P9-O9 -> 797 | R9: 1981802 | S9: =R9-R6 -> 0 | T9: 7885502 | U9: =T9-T6 -> 20427 | V9: 741235 | W9: =V9-V6 -> 0 | X9: 1058377 | Y9: =X9-X6 -> 0 | Z9: =W9+Y9 -> 0 | AA9: 0.6633844 | AB9: -0.46664742 | AC9: 0 | AD9: =SUMPRODUCT($AA$7:$AB$7:$AC$7,AA9:AC9) -> 1642.7538 | AE9: 4629334 | AF9: =AE9-AE6 -> 4407 | AG9: 761283 | AH9: =AG9-AG6 -> 1198 | AI9: 115277 | AJ9: =AI9-AI6 -> 86
B10: =B9+1 -> 45963 | C10: =TEXT(B10,"ddd") -> Sun | G10: 5238066 | H10: =G10-G9 -> 5293 | I10: 13766956 | J10: =I10-I9 -> 5501 | R10: 1981802 | S10: =R10-R9 -> 0 | T10: 7901146 | U10: =T10-T9 -> 15644 | V10: 741235 | W10: =V10-V9 -> 0 | X10: 1058377 | Y10: =X10-X9 -> 0 | Z10: =W10+Y10 -> 0 | AA10: 0.80345947 | AB10: -0.46703098 | AC10: 0 | AD10: =SUMPRODUCT($AA$7:$AB$7:$AC$7,AA10:AC10) -> 2809.1779 | AE10: 4629334 | AF10: =AE10-AE9 -> 0 | AG10: 761283 | AH10: =AG10-AG9 -> 0 | AI10: 115471 | AJ10: =AI10-AI9 -> 194
B11: =B10+1 -> 45964 | C11: =TEXT(B11,"ddd") -> Mon | G11: 5245946 | H11: =G11-G10 -> 7880 | I11: 13772465 | J11: =I11-I10 -> 5509 | M11: 0542h | N11: 0933h | O11: 1915007 | P11: 1918120 | Q11: =P11-O11 -> 3113 | R11: 1981802 | S11: =R11-R10 -> 0 | T11: 7904729 | U11: =T11-T10 -> 3583 | V11: 741235 | W11: =V11-V10 -> 0 | X11: 1058377 | Y11: =X11-X10 -> 0 | Z11: =W11+Y11 -> 0 | AA11: 0.67159088 | AB11: -0.47257713 | AC11: 0 | AD11: =SUMPRODUCT($AA$7:$AB$7:$AC$7,AA11:AC11) -> 1661.7648 | AE11: 4636451 | AF11: =AE11-AE10 -> 7117 | AG11: 763414 | AH11: =AG11-AG10 -> 2131 | AI11: 115596 | AJ11: =AI11-AI10 -> 125
B12: =B11+1 -> 45965 | C12: =TEXT(B12,"ddd") -> Tue | G12: 5260317 | H12: =G12-G11 -> 14371 | I12: 13772871 | J12: =I12-I11 -> 406 | R12: 1981802 | S12: =R12-R11 -> 0 | T12: 7904729 | U12: =T12-T11 -> 0 | V12: 741235 | W12: =V12-V11 -> 0 | X12: 1058377 | Y12: =X12-X11 -> 0 | Z12: =W12+Y12 -> 0 | AA12: 0.23118454 | AB12: -0.46150131 | AC12: 0 | AD12: =SUMPRODUCT($AA$7:$AB$7:$AC$7,AA12:AC12) -> -1923.145 | AE12: 4640001 | AF12: =AE12-AE11 -> 3550 | AG12: 764231 | AH12: =AG12-AG11 -> 817 | AI12: 115678 | AJ12: =AI12-AI11 -> 82
B13: =B12+1 -> 45966 | C13: =TEXT(B13,"ddd") -> Wed | G13: 5260317 | H13: =G13-G12 -> 0 | I13: 13772871 | J13: =I13-I12 -> 0 | R13: 1981802 | S13: =R13-R12 -> 0 | T13: 7904729 | U13: =T13-T12 -> 0 | V13: 741235 | W13: =V13-V12 -> 0 | X13: 1058377 | Y13: =X13-X12 -> 0 | Z13: =W13+Y13 -> 0 | AA13: 0.36591339 | AB13: -0.46838367 | AC13: 0 | AD13: =SUMPRODUCT($AA$7:$AB$7:$AC$7,AA13:AC13) -> -855.62684 | AE13: 4644143 | AF13: =AE13-AE12 -> 4142 | AG13: 765085 | AH13: =AG13-AG12 -> 854 | AI13: 115888 | AJ13: =AI13-AI12 -> 210
B14: =B13+1 -> 45967 | C14: =TEXT(B14,"ddd") -> Thu | G14: 5273842 | H14: =G14-G13 -> 13525 | I14: 13782908 | J14: =I14-I13 -> 10037 | R14: 1981802 | S14: =R14-R13 -> 0 | T14: 7904729 | U14: =T14-T13 -> 0 | V14: 741235 | W14: =V14-V13 -> 0 | X14: 1058377 | Y14: =X14-X13 -> 0 | Z14: =W14+Y14 -> 0 | AA14: 0.52158264 | AB14: -0.47259216 | AC14: 0 | AD14: =SUMPRODUCT($AA$7:$AB$7:$AC$7,AA14:AC14) -> 409.07051 | AE14: 4648121 | AF14: =AE14-AE13 -> 3978 | AG14: 765899 | AH14: =AG14-AG13 -> 814 | AI14: 116142 | AJ14: =AI14-AI13 -> 254
B15: =B14+1 -> 45968 | C15: =TEXT(B15,"ddd") -> Fri | G15: 5274667 | H15: =G15-G14 -> 825 | I15: 13795510 | J15: =I15-I14 -> 12602 | R15: 1981802 | S15: =R15-R14 -> 0 | T15: 7904729 | U15: =T15-T14 -> 0 | V15: 741235 | W15: =V15-V14 -> 0 | X15: 1058377 | Y15: =X15-X14 -> 0 | Z15: =W15+Y15 -> 0 | AA15: 0.70469284 | AB15: -0.47135002 | AC15: 0 | AD15: =SUMPRODUCT($AA$7:$AB$7:$AC$7,AA15:AC15) -> 1948.4125 | AE15: 4652414 | AF15: =AE15-AE14 -> 4293 | AG15: 766685 | AH15: =AG15-AG14 -> 786 | AI15: 116366 | AJ15: =AI15-AI14 -> 224
B16: =B15+1 -> 45969 | C16: =TEXT(B16,"ddd") -> Sat | G16: 5274667 | H16: =G16-G15 -> 0 | I16: 13808320 | J16: =I16-I15 -> 12810 | R16: 1981802 | S16: =R16-R15 -> 0 | T16: 7904729 | U16: =T16-T15 -> 0 | V16: 741235 | W16: =V16-V15 -> 0 | X16: 1058377 | Y16: =X16-X15 -> 0 | Z16: =W16+Y16 -> 0 | AA16: 0.56344833 | AB16: -0.47232742 | AC16: 0 | AD16: =SUMPRODUCT($AA$7:$AB$7:$AC$7,AA16:AC16) -> 760.8596 | AE16: 4656687 | AF16: =AE16-AE15 -> 4273 | AG16: 767528 | AH16: =AG16-AG15 -> 843 | AI16: 116566 | AJ16: =AI16-AI15 -> 200
B17: =B16+1 -> 45970 | C17: =TEXT(B17,"ddd") -> Sun | G17: 5284902 | H17: =G17-G16 -> 10235 | I17: 13815594 | J17: =I17-I16 -> 7274 | R17: 1981802 | S17: =R17-R16 -> 0 | T17: 7904729 | U17: =T17-T16 -> 0 | V17: 741235 | W17: =V17-V16 -> 0 | X17: 1058377 | Y17: =X17-X16 -> 0 | Z17: =W17+Y17 -> 0 | AA17: 0.70632553 | AB17: -0.47313396 | AC17: 0 | AD17: =SUMPRODUCT($AA$7:$AB$7:$AC$7,AA17:AC17) -> 1947.1496 | AE17: 4660901 | AF17: =AE17-AE16 -> 4214 | AG17: 768371 | AH17: =AG17-AG16 -> 843 | AI17: 116753 | AJ17: =AI17-AI16 -> 187 | AK17: =AJ17-AJ16 -> -13
B18: =B17+1 -> 45971 | C18: =TEXT(B18,"ddd") -> Mon | G18: 5289211 | H18: =G18-G17 -> 4309 | I18: 13819704 | J18: =I18-I17 -> 4110 | M18: 0009h | N18: 1300h | O18: 1940365 | P18: 1950699 | Q18: =P18-O18 -> 10334 | R18: 1981802 | S18: =R18-R17 -> 0 | T18: 7904741 | U18: =T18-T17 -> 12 | V18: 741235 | W18: =V18-V17 -> 0 | X18: 1058377 | Y18: =X18-X17 -> 0 | Z18: =W18+Y18 -> 0 | AA18: 0.96290237 | AB18: -0.47434689 | AC18: 0 | AD18: =SUMPRODUCT($AA$7:$AB$7:$AC$7,AA18:AC18) -> 4079.4383 | AE18: 4663964 | AF18: =AE18-AE17 -> 3063 | AG18: 769164 | AH18: =AG18-AG17 -> 793 | AI18: 117063 | AJ18: =AI18-AI17 -> 310
B19: =B18+1 -> 45972 | C19: =TEXT(B19,"ddd") -> Tue | G19: 5302645 | H19: =G19-G18 -> 13434 | I19: 13819944 | J19: =I19-I18 -> 240 | R19: 1981802 | S19: =R19-R18 -> 0 | T19: 7904741 | U19: =T19-T18 -> 0 | V19: 741235 | W19: =V19-V18 -> 0 | X19: 1058377 | Y19: =X19-X18 -> 0 | Z19: =W19+Y19 -> 0 | AA19: 0.43665756 | AB19: -0.46001106 | AC19: 0 | AD19: =SUMPRODUCT($AA$7:$AB$7:$AC$7,AA19:AC19) -> -195.00173 | AE19: 4667700 | AF19: =AE19-AE18 -> 3736 | AG19: 769841 | AH19: =AG19-AG18 -> 677 | AI19: 117628 | AJ19: =AI19-AI18 -> 565
B20: =B19+1 -> 45973 | C20: =TEXT(B20,"ddd") -> Wed | G20: 5320955 | H20: =G20-G19 -> 18310 | I20: 13820429 | J20: =I20-I19 -> 485 | R20: 1981802 | S20: =R20-R19 -> 0 | T20: 7904741 | U20: =T20-T19 -> 0 | V20: 741235 | W20: =V20-V19 -> 0 | X20: 1058377 | Y20: =X20-X19 -> 0 | Z20: =W20+Y20 -> 0 | AA20: 0.72297028 | AB20: -0.46048183 | AC20: 0 | AD20: =SUMPRODUCT($AA$7:$AB$7:$AC$7,AA20:AC20) -> 2191.7786 | AE20: 4670993 | AF20: =AE20-AE19 -> 3293 | AG20: 770743 | AH20: =AG20-AG19 -> 902 | AI20: 117814 | AJ20: =AI20-AI19 -> 186
B21: =B20+1 -> 45974 | C21: =TEXT(B21,"ddd") -> Thu | G21: 5339129 | H21: =G21-G20 -> 18174 | I21: 13821485 | J21: =I21-I20 -> 1056 | R21: 1981802 | S21: =R21-R20 -> 0 | T21: 7904741 | U21: =T21-T20 -> 0 | V21: 741235 | W21: =V21-V20 -> 0 | X21: 1058377 | Y21: =X21-X20 -> 0 | Z21: =W21+Y21 -> 0 | AA21: 0.73109421 | AB21: -0.46961548 | AC21: -0.62499996 | AD21: =SUMPRODUCT($AA$7:$AB$7:$AC$7,AA21:AC21) -> -3035.4023 | AE21: 4674414 | AF21: =AE21-AE20 -> 3421 | AG21: 771594 | AH21: =AG21-AG20 -> 851 | AI21: 118080 | AJ21: =AI21-AI20 -> 266
B22: =B21+1 -> 45975 | C22: =TEXT(B22,"ddd") -> Fri | G22: 5344930 | H22: =G22-G21 -> 5801 | I22: 13834699 | J22: =I22-I21 -> 13214 | R22: 1981802 | S22: =R22-R21 -> 0 | T22: 7904741 | U22: =T22-T21 -> 0 | V22: 741235 | W22: =V22-V21 -> 0 | X22: 1058377 | Y22: =X22-X21 -> 0 | Z22: =W22+Y22 -> 0 | AA22: 0.9404866 | AB22: -0.45930313 | AC22: -0.62499996 | AD22: =SUMPRODUCT($AA$7:$AB$7:$AC$7,AA22:AC22) -> -1200.8677 | AE22: 4678270 | AF22: =AE22-AE21 -> 3856 | AG22: 772440 | AH22: =AG22-AG21 -> 846 | AI22: 118381 | AJ22: =AI22-AI21 -> 301
B23: =B22+1 -> 45976 | C23: =TEXT(B23,"ddd") -> Sat | G23: 5361186 | H23: =G23-G22 -> 16256 | I23: 13842213 | J23: =I23-I22 -> 7514 | M23: 0905h | N23: 1155h | O23: 1951616 | P23: 1953668 | Q23: =P23-O23 -> 2052 | R23: 1981802 | S23: =R23-R22 -> 0 | T23: 7904741 | U23: =T23-T22 -> 0 | V23: 741235 | W23: =V23-V22 -> 0 | X23: 1058377 | Y23: =X23-X22 -> 0 | Z23: =W23+Y23 -> 0 | AA23: 0.85289291 | AB23: -0.45553051 | AC23: -0.62499996 | AD23: =SUMPRODUCT($AA$7:$AB$7:$AC$7,AA23:AC23) -> -1900.7736 | AE23: 4682048 | AF23: =AE23-AE22 -> 3778 | AG23: 773319 | AH23: =AG23-AG22 -> 879 | AI23: 118619 | AJ23: =AI23-AI22 -> 238
B24: =B23+1 -> 45977 | C24: =TEXT(B24,"ddd") -> Sun | G24: 5369129 | H24: =G24-G23 -> 7943 | I24: 13845760 | J24: =I24-I23 -> 3547 | M24: 1008h | N24: 1155h | O24: 1953784 | P24: 1954521 | Q24: =P24-O24 -> 737 | R24: 1981802 | S24: =R24-R23 -> 0 | T24: 7904763 | U24: =T24-T23 -> 22 | V24: 741235 | W24: =V24-V23 -> 0 | X24: 1058377 | Y24: =X24-X23 -> 0 | Z24: =W24+Y24 -> 0 | AA24: 0.83585083 | AB24: -0.47126312 | AC24: -0.62499996 | AD24: =SUMPRODUCT($AA$7:$AB$7:$AC$7,AA24:AC24) -> -2174.4423 | AE24: 4685949 | AF24: =AE24-AE23 -> 3901 | AG24: 774221 | AH24: =AG24-AG23 -> 902 | AI24: 118802 | AJ24: =AI24-AI23 -> 183
B25: =B24+1 -> 45978 | C25: =TEXT(B25,"ddd") -> Mon | G25: 5377257 | H25: =G25-G24 -> 8128 | I25: 13853007 | J25: =I25-I24 -> 7247 | M25: 1513h | N25: 0513h | O25: 1954526 | P25: 1961031 | Q25: =P25-O25 -> 6505 | R25: 1981802 | S25: =R25-R24 -> 0 | T25: 7904763 | U25: =T25-T24 -> 0 | V25: 741235 | W25: =V25-V24 -> 0 | X25: 1058377 | Y25: =X25-X24 -> 0 | Z25: =W25+Y25 -> 0 | AA25: 1.0102075 | AB25: -0.47142879 | AC25: -0.62499996 | AD25: =SUMPRODUCT($AA$7:$AB$7:$AC$7,AA25:AC25) -> -719.94727 | AE25: 4689757 | AF25: =AE25-AE24 -> 3808 | AG25: 774844 | AH25: =AG25-AG24 -> 623 | AI25: 118846 | AJ25: =AI25-AI24 -> 44
B26: =B25+1 -> 45979 | C26: =TEXT(B26,"ddd") -> Tue | G26: 5385745 | H26: =G26-G25 -> 8488 | I26: 13853871 | J26: =I26-I25 -> 864 | R26: 1981802 | S26: =R26-R25 -> 0 | T26: 7904763 | U26: =T26-T25 -> 0 | V26: 741235 | W26: =V26-V25 -> 0 | X26: 1058377 | Y26: =X26-X25 -> 0 | Z26: =W26+Y26 -> 0 | AA26: 0.66122528 | AB26: 0.01764374 | AC26: -0.13915543 | AD26: =SUMPRODUCT($AA$7:$AB$7:$AC$7,AA26:AC26) -> 4506.6085 | AE26: 4693369 | AF26: =AE26-AE25 -> 3612 | AG26: 775638 | AH26: =AG26-AG25 -> 794 | AI26: 118865 | AJ26: =AI26-AI25 -> 19
B27: =B26+1 -> 45980 | C27: =TEXT(B27,"ddd") -> Wed | G27: 5404535 | H27: =G27-G26 -> 18790 | I27: 13853871 | J27: =I27-I26 -> 0 | R27: 1981802 | S27: =R27-R26 -> 0 | T27: 7904763 | U27: =T27-T26 -> 0 | V27: 741235 | W27: =V27-V26 -> 0 | X27: 1058377 | Y27: =X27-X26 -> 0 | Z27: =W27+Y27 -> 0 | AA27: 0.69600632 | AB27: 0.25696747 | AC27: 0.65397873 | AD27: =SUMPRODUCT($AA$7:$AB$7:$AC$7,AA27:AC27) -> 13418.054 | AE27: 4697371 | AF27: =AE27-AE26 -> 4002 | AG27: 776425 | AH27: =AG27-AG26 -> 787 | AI27: 119010 | AJ27: =AI27-AI26 -> 145
B28: =B27+1 -> 45981 | C28: =TEXT(B28,"ddd") -> Thu | G28: 5431490 | H28: =G28-G27 -> 26955 | I28: 13858917 | J28: =I28-I27 -> 5046 | R28: 1981802 | S28: =R28-R27 -> 0 | T28: 7904763 | U28: =T28-T27 -> 0 | V28: 741235 | W28: =V28-V27 -> 0 | X28: 1058377 | Y28: =X28-X27 -> 0 | Z28: =W28+Y28 -> 0 | AA28: -0.30938808 | AB28: 0.89272423 | AC28: 0.65937759 | AD28: =SUMPRODUCT($AA$7:$AB$7:$AC$7,AA28:AC28) -> 10376.66 | AE28: 4700702 | AF28: =AE28-AE27 -> 3331 | AG28: 777290 | AH28: =AG28-AG27 -> 865 | AI28: 119197 | AJ28: =AI28-AI27 -> 187 | AK28: =AJ28-AJ27 -> 42
B29: =B28+1 -> 45982 | C29: =TEXT(B29,"ddd") -> Fri | G29: 5455323 | H29: =G29-G28 -> 23833 | I29: 13860808 | J29: =I29-I28 -> 1891 | R29: 1981802 | S29: =R29-R28 -> 0 | T29: 7904763 | U29: =T29-T28 -> 0 | V29: 741235 | W29: =V29-V28 -> 0 | X29: 1058377 | Y29: =X29-X28 -> 0 | Z29: =W29+Y29 -> 0 | AA29: -0.30937199 | AB29: 0.39012817 | AC29: 0.87481049 | AD29: =SUMPRODUCT($AA$7:$AB$7:$AC$7,AA29:AC29) -> 7978.9817 | AE29: 4704882 | AF29: =AE29-AE28 -> 4180 | AG29: 778233 | AH29: =AG29-AG28 -> 943 | AI29: 119391 | AJ29: =AI29-AI28 -> 194
B30: =B29+1 -> 45983 | C30: =TEXT(B30,"ddd") -> Sat | G30: 5480345 | H30: =G30-G29 -> 25022 | I30: 13860808 | J30: =I30-I29 -> 0 | R30: 1981802 | S30: =R30-R29 -> 0 | T30: 7904763 | U30: =T30-T29 -> 0 | V30: 741235 | W30: =V30-V29 -> 0 | X30: 1058377 | Y30: =X30-X29 -> 0 | Z30: =W30+Y30 -> 0 | AA30: 0.83287125 | AB30: 0.98902122 | AC30: 0.79709686 | AD30: =SUMPRODUCT($AA$7:$AB$7:$AC$7,AA30:AC30) -> 21868.561 | AE30: 4709104 | AF30: =AE30-AE29 -> 4222 | AG30: 779141 | AH30: =AG30-AG29 -> 908 | AI30: 119608 | AJ30: =AI30-AI29 -> 217
B31: =B30+1 -> 45984 | C31: =TEXT(B31,"ddd") -> Sun | G31: 5493913 | H31: =G31-G30 -> 13568 | I31: 13867582 | J31: =I31-I30 -> 6774 | R31: 1981802 | S31: =R31-R30 -> 0 | T31: 7910535 | U31: =T31-T30 -> 5772 | V31: 741235 | W31: =V31-V30 -> 0 | X31: 1058377 | Y31: =X31-X30 -> 0 | Z31: =W31+Y31 -> 0 | AA31: 0.91891556 | AB31: 0.62368309 | AC31: 0.86833313 | AD31: =SUMPRODUCT($AA$7:$AB$7:$AC$7,AA31:AC31) -> 20131.28 | AE31: 4713698 | AF31: =AE31-AE30 -> 4594 | AG31: 780041 | AH31: =AG31-AG30 -> 900 | AI31: 119902 | AJ31: =AI31-AI30 -> 294
B32: =B31+1 -> 45985 | C32: =TEXT(B32,"ddd") -> Mon | H32: =G32-G31 -> -5493913 | J32: =I32-I31 -> -13867582 | R32: 1981802 | S32: =R32-R31 -> 0 | T32: 7922890 | U32: =T32-T31 -> 12355 | W32: =V32-V31 -> -741235 | Y32: =X32-X31 -> -1058377 | Z32: =W32+Y32 -> -1799612 | AA32: 0.86837814 | AB32: 0.79583092 | AC32: 0.77588654 | AD32: =SUMPRODUCT($AA$7:$AB$7:$AC$7,AA32:AC32) -> 20374.798 | AF32: =AE32-AE31 -> -4713698 | AH32: =AG32-AG31 -> -780041 | AJ32: =AI32-AI31 -> -119902
B33: =B32+1 -> 45986 | C33: =TEXT(B33,"ddd") -> Tue | H33: =G33-G32 -> 0 | J33: =I33-I32 -> 0 | R33: 1981802 | S33: =R33-R32 -> 0 | U33: =T33-T32 -> -7922890 | W33: =V33-V32 -> 0 | Y33: =X33-X32 -> 0 | Z33: =W33+Y33 -> 0 | AA33: 0.93445084 | AB33: 0.50150009 | AC33: 0.4289201 | AD33: =SUMPRODUCT($AA$7:$AB$7:$AC$7,AA33:AC33) -> 15571.673 | AF33: =AE33-AE32 -> 0 | AH33: =AG33-AG32 -> 0 | AJ33: =AI33-AI32 -> 0
B34: =B33+1 -> 45987 | C34: =TEXT(B34,"ddd") -> Wed | H34: =G34-G33 -> 0 | J34: =I34-I33 -> 0 | R34: 1981802 | S34: =R34-R33 -> 0 | U34: =T34-T33 -> 0 | W34: =V34-V33 -> 0 | Y34: =X34-X33 -> 0 | Z34: =W34+Y34 -> 0 | AD34: =SUMPRODUCT($AA$7:$AB$7:$AC$7,AA34:AC34) -> 0 | AF34: =AE34-AE33 -> 0 | AH34: =AG34-AG33 -> 0 | AJ34: =AI34-AI33 -> 0
B35: =B34+1 -> 45988 | C35: =TEXT(B35,"ddd") -> Thu | H35: =G35-G34 -> 0 | J35: =I35-I34 -> 0 | U35: =T35-T34 -> 0 | W35: =V35-V34 -> 0 | Y35: =X35-X34 -> 0 | Z35: =W35+Y35 -> 0 | AD35: =SUMPRODUCT($AA$7:$AB$7:$AC$7,AA35:AC35) -> 0 | AF35: =AE35-AE34 -> 0 | AH35: =AG35-AG34 -> 0 | AJ35: =AI35-AI34 -> 0
B36: =B35+1 -> 45989 | C36: =TEXT(B36,"ddd") -> Fri | H36: =G36-G35 -> 0 | J36: =I36-I35 -> 0 | U36: =T36-T35 -> 0 | W36: =V36-V35 -> 0 | Y36: =X36-X35 -> 0 | Z36: =W36+Y36 -> 0 | AF36: =AE36-AE35 -> 0 | AH36: =AG36-AG35 -> 0 | AJ36: =AI36-AI35 -> 0
B37: =B36+1 -> 45990 | C37: =TEXT(B37,"ddd") -> Sat | H37: =G37-G36 -> 0 | J37: =I37-I36 -> 0 | U37: =T37-T36 -> 0 | W37: =V37-V36 -> 0 | Y37: =X37-X36 -> 0 | Z37: =W37+Y37 -> 0 | AF37: =AE37-AE36 -> 0 | AH37: =AG37-AG36 -> 0 | AJ37: =AI37-AI36 -> 0
B38: =B37+1 -> 45991 | C38: =TEXT(B38,"ddd") -> Sun | H38: =G38-G37 -> 0 | J38: =I38-I37 -> 0 | U38: =T38-T37 -> 0 | W38: =V38-V37 -> 0 | Y38: =X38-X37 -> 0 | Z38: =W38+Y38 -> 0 | AF38: =AE38-AE37 -> 0 | AH38: =AG38-AG37 -> 0 | AJ38: =AI38-AI37 -> 0
B39: =B38+1 -> 45992 | C39: =TEXT(B39,"ddd") -> Mon | H39: =G39-G38 -> 0 | J39: =I39-I38 -> 0 | U39: =T39-T38 -> 0 | W39: =V39-V38 -> 0 | Y39: =X39-X38 -> 0 | Z39: =W39+Y39 -> 0 | AF39: =AE39-AE38 -> 0 | AH39: =AG39-AG38 -> 0 | AJ39: =AI39-AI38 -> 0
B40: Total/Average | G40: =SUM(G9:G39) -> 122701290 | H40: =SUM(H9:H39) -> -5216835 | I40: =SUM(I9:I39) -> 317862048 | J40: =SUM(J9:J39) -> -13751980 | K40: =SUM(K9:K39) -> 0 | L40: =SUM(L9:L39) -> 0 | M40: =SUM(M9:M39) -> 0 | N40: =SUM(N9:N39) -> 0 | Q40: =SUM(Q9:Q39) -> 23538 | R40: =SUM(R9:R39) -> 51526852 | S40: =SUM(S9:S39) -> 0 | T40: =SUM(T9:T39) -> 189714963 | U40: =SUM(U9:U39) -> -7865075 | V40: =SUM(V9:V39) -> 17048405 | W40: =SUM(W9:W39) -> -741235 | X40: =SUM(X9:X39) -> 24342671 | ... AA40: =SUM(AA9:AA39) -> 16.017732 | AD40: =SUM(AD9:AD39) -> 119671.81 | AE40: =SUM(AE9:AE39) -> 107429607 | AF40: =SUM(AF9:AF39) -> -4624927 | AG40: =SUM(AG9:AG39) -> 17726713 | AH40: =SUM(AH9:AH39) -> -760085 | AI40: =SUM(AI9:AI39) -> 2704943 | AJ40: =SUM(AJ9:AJ39) -> -115191

Sheet Template (2)
B2: Note: Recording should be done 1st hour of the day
B3: DAILY BIOGAS USAGE MONITORING | Z3: Waste Hauling Operation | AC3: Biogas Operation Utility Consumption | AI3: Remarks/ Shifts
B4: Date | C4: Day | D4: Gas Storage (%) | G4: Quality | H4: Gas Meters (Nmᶾ) | N4: Gas Flare | Q4: Gas Engine Power Meter (kWh) | S4: Diesel Fuel Consumption | V4: Ope. Hrs | X4: Ope. Hrs w/ Biogas
D5: F1 | E5: F2 | F5: Total | G5: Methane Content | H5: Gas Engine Line Totalizer | J5: Thermax Gas Totalizer | L5: CB Gas Totalizer | N5: Time | P5: Total Volume | S5: Thermax | T5: Cleaver Brooks | U5: Total | V5: Thermax | W5: Cleaver Brooks | X5: Thermax | Y5: Cleaver Brooks | Z5: Actual Waste Delivered (MT) | AB5: DS | AC5: Electricity @ Biogas plant, kWhr | AE5: Electricity @ DUVO cannery, kWhr | AG5: Water, m3
D6: 8350 | E6: 8350 | F6: =D6+E6 -> 16700 | G6: 55% Min | H6: Totalizer | I6: Output | J6: Totalizer | K6: Output | L6: Totalizer | M6: Output | N6: Start | O6: End | P6: Nm³ | Q6: Totalizer | R6: Output | S6: Li. | T6: Li. | U6: Li. | V6: Hrs | W6: Hrs | X6: Hrs | Y6: Hrs | Z6: Delivery | AA6: Cummulative | AB6: % | AC6: Totalizer | AD6: Consumed | AE6: Totalizer | AF6: Consumed | AG6: Totalizer | AH6: Consumed
B7: 45017 | C7: =TEXT(B7,"ddd") -> Sat | D7: 0.83427505 | E7: 0 | F7: =SUMPRODUCT($D$6:$E$6,D7:E7) -> 6966.1967 | I7: 0 | J7: 1859688 | K7: 0 | L7: 138250 | Q7: 1829505 | R7: =Q7-#REF! -> #REF! | U7: - | Z7: 86.33 | AA7: =Z7 -> 86.33 | AC7: 645772 | AD7: =AC7-#REF! -> #REF! | AE7: 37797 | AF7: =AE7-#REF! -> #REF! | AG7: 12704 | AH7: =AG7-#REF! -> #REF!
B8: =B7+1 -> 45018 | C8: =TEXT(B8,"ddd") -> Sun | D8: 0.67081329 | E8: 0 | F8: =SUMPRODUCT($D$6:$E$6,D8:E8) -> 5601.291 | I8: =H8-H7 -> 0 | J8: 1859688 | K8: =J8-J7 -> 0 | L8: 138250 | M8: =L8-L7 -> 0 | Q8: 1829505 | R8: =Q8-Q7 -> 0 | U8: - | Z8: 162.07 | AA8: =AA7+Z8 -> 248.4 | AC8: 647325 | AD8: =AC8-AC7 -> 1553 | AE8: 38080 | AF8: =AE8-AE7 -> 283 | AG8: 12754 | AH8: =AG8-AG7 -> 50
B9: =B8+1 -> 45019 | C9: =TEXT(B9,"ddd") -> Mon | D9: 0.43256351 | E9: 0 | F9: =SUMPRODUCT($D$6:$E$6,D9:E9) -> 3611.9053 | I9: =H9-H8 -> 0 | J9: 1859688 | K9: =J9-J8 -> 0 | L9: 138250 | M9: =L9-L8 -> 0 | Q9: 1829505 | R9: =Q9-Q8 -> 0 | U9: - | Z9: 263.11 | AA9: =AA8+Z9 -> 511.51 | AC9: 649134 | AD9: =AC9-AC8 -> 1809 | AE9: 38371 | AF9: =AE9-AE8 -> 291 | AG9: 12803 | AH9: =AG9-AG8 -> 49
B10: =B9+1 -> 45020 | C10: =TEXT(B10,"ddd") -> Tue | D10: 0.60171482 | E10: 0 | F10: =SUMPRODUCT($D$6:$E$6,D10:E10) -> 5024.3187 | I10: =H10-H9 -> 0 | J10: 1859688 | K10: =J10-J9 -> 0 | L10: 138250 | M10: =L10-L9 -> 0 | Q10: 1829505 | R10: =Q10-Q9 -> 0 | U10: - | AA10: =AA9+Z10 -> 511.51 | AC10: 650576 | AD10: =AC10-AC9 -> 1442 | AE10: 38680 | AF10: =AE10-AE9 -> 309 | AG10: 12851 | AH10: =AG10-AG9 -> 48
B11: =B10+1 -> 45021 | C11: =TEXT(B11,"ddd") -> Wed | D11: 0.27517223 | E11: 0 | F11: =SUMPRODUCT($D$6:$E$6,D11:E11) -> 2297.6881 | I11: =H11-H10 -> 0 | J11: 1862698 | K11: =J11-J10 -> 3010 | L11: 138250 | M11: =L11-L10 -> 0 | Q11: 1829505 | R11: =Q11-Q10 -> 0 | U11: - | Z11: 224.62 | AA11: =AA10+Z11 -> 736.13 | AC11: 652695 | AD11: =AC11-AC10 -> 2119 | AE11: 39006 | AF11: =AE11-AE10 -> 326 | AG11: 12968 | AH11: =AG11-AG10 -> 117
B12: =B11+1 -> 45022 | C12: =TEXT(B12,"ddd") -> Thu | D12: 0.58496235 | E12: 0 | F12: =SUMPRODUCT($D$6:$E$6,D12:E12) -> 4884.4356 | I12: =H12-H11 -> 0 | J12: 1866302 | K12: =J12-J11 -> 3604 | L12: 138250 | M12: =L12-L11 -> 0 | Q12: 1829505 | R12: =Q12-Q11 -> 0 | U12: - | Z12: 245.19 | AA12: =AA11+Z12 -> 981.32 | AC12: 654733 | AD12: =AC12-AC11 -> 2038 | AE12: 39303 | AF12: =AE12-AE11 -> 297 | AG12: 13079 | AH12: =AG12-AG11 -> 111
B13: =B12+1 -> 45023 | C13: =TEXT(B13,"ddd") -> Fri | D13: 0.40554119 | E13: 0 | F13: =SUMPRODUCT($D$6:$E$6,D13:E13) -> 3386.2689 | I13: =H13-H12 -> 0 | J13: 1869934 | K13: =J13-J12 -> 3632 | L13: 138250 | M13: =L13-L12 -> 0 | Q13: 1829505 | R13: =Q13-Q12 -> 0 | U13: - | Z13: 214.36 | AA13: =AA12+Z13 -> 1195.68 | AC13: 656769 | AD13: =AC13-AC12 -> 2036 | AE13: 39647 | AF13: =AE13-AE12 -> 344 | AG13: 13191 | AH13: =AG13-AG12 -> 112
B14: =B13+1 -> 45024 | C14: =TEXT(B14,"ddd") -> Sat | D14: 0.52471218 | E14: 0 | F14: =SUMPRODUCT($D$6:$E$6,D14:E14) -> 4381.3467 | I14: =H14-H13 -> 0 | J14: 1871099 | K14: =J14-J13 -> 1165 | L14: 138250 | M14: =L14-L13 -> 0 | Q14: 1829505 | R14: =Q14-Q13 -> 0 | U14: - | Z14: 177.42 | AA14: =AA13+Z14 -> 1373.1 | AC14: 658568 | AD14: =AC14-AC13 -> 1799 | AE14: 39989 | AF14: =AE14-AE13 -> 342 | AG14: 13233 | AH14: =AG14-AG13 -> 42
B15: =B14+1 -> 45025 | C15: =TEXT(B15,"ddd") -> Sun | D15: 0.60012897 | E15: 0 | F15: =SUMPRODUCT($D$6:$E$6,D15:E15) -> 5011.0769 | I15: =H15-H14 -> 0 | J15: 1871099 | K15: =J15-J14 -> 0 | L15: 138250 | M15: =L15-L14 -> 0 | Q15: 1829505 | R15: =Q15-Q14 -> 0 | U15: - | Z15: 235.27 | AA15: =AA14+Z15 -> 1608.37 | AC15: 660461 | AD15: =AC15-AC14 -> 1893 | AE15: 40279 | AF15: =AE15-AE14 -> 290 | AG15: 13358 | AH15: =AG15-AG14 -> 125
B16: =B15+1 -> 45026 | C16: =TEXT(B16,"ddd") -> Mon | D16: 0.65862457 | E16: 0 | F16: =SUMPRODUCT($D$6:$E$6,D16:E16) -> 5499.5152 | I16: =H16-H15 -> 0 | J16: 1871099 | K16: =J16-J15 -> 0 | L16: 138250 | M16: =L16-L15 -> 0 | Q16: 1829505 | R16: =Q16-Q15 -> 0 | U16: - | Z16: 198.79 | AA16: =AA15+Z16 -> 1807.16 | AC16: 662082 | AD16: =AC16-AC15 -> 1621 | AE16: 40553 | AF16: =AE16-AE15 -> 274 | AG16: 13409 | AH16: =AG16-AG15 -> 51
B17: =B16+1 -> 45027 | C17: =TEXT(B17,"ddd") -> Tue | D17: 0.25498112 | E17: 0 | F17: =SUMPRODUCT($D$6:$E$6,D17:E17) -> 2129.0924 | I17: =H17-H16 -> 0 | J17: 1875681 | K17: =J17-J16 -> 4582 | L17: 138250 | M17: =L17-L16 -> 0 | Q17: 1829505 | R17: =Q17-Q16 -> 0 | U17: - | AA17: =AA16+Z17 -> 1807.16 | AC17: 663826 | AD17: =AC17-AC16 -> 1744 | AE17: 40821 | AF17: =AE17-AE16 -> 268 | AG17: 13482 | AH17: =AG17-AG16 -> 73
B18: =B17+1 -> 45028 | C18: =TEXT(B18,"ddd") -> Wed | D18: 0.82637161 | E18: 0 | F18: =SUMPRODUCT($D$6:$E$6,D18:E18) -> 6900.2029 | I18: =H18-H17 -> 0 | J18: 1875870 | K18: =J18-J17 -> 189 | L18: 138250 | M18: =L18-L17 -> 0 | Q18: 1829505 | R18: =Q18-Q17 -> 0 | U18: - | Z18: 199.13 | AC18: 665606 | AD18: =AC18-AC17 -> 1780 | AE18: 41053 | AF18: =AE18-AE17 -> 232 | AG18: 13565 | AH18: =AG18-AG17 -> 83
B19: =B18+1 -> 45029 | C19: =TEXT(B19,"ddd") -> Thu | D19: 0.6408316 | E19: 0 | F19: =SUMPRODUCT($D$6:$E$6,D19:E19) -> 5350.9439 | I19: =H19-H18 -> 0 | J19: 1881648 | K19: =J19-J18 -> 5778 | L19: 138250 | M19: =L19-L18 -> 0 | Q19: 1829505 | R19: =Q19-Q18 -> 0 | U19: - | Z19: 153.57 | AC19: 667284 | AD19: =AC19-AC18 -> 1678 | AE19: 41267 | AF19: =AE19-AE18 -> 214 | AG19: 13607 | AH19: =AG19-AG18 -> 42
