Workbook

Sheet Mar actual FM vol
B2: Substrate Supply
B4: Monthly SCA Minimum | C4: =62000/12 -> 5166.6667 | D4: (mtons)
B5: Delivered | C5: =SUM(D34:H34) -> 2906.789 | D5: (mtons)
B6: Rejected | C6: =SUM(D36:H36) -> 0 | D6: (mtons)
C26: =477/5167 -> 0.092316625 | E26: =E27/5167 -> 0.29998065 | F26: =F27/5167 -> 0.55196439 | G26: =G27/5167 -> 0.7892394
C27: =477 -> 477 | E27: =477+1073 -> 1550 | F27: =1550+1302 -> 2852 | G27: =2852+1226 -> 4078
D32: WEEK 1 | E32: WEEK 2 | F32: WEEk 3 | G32: WEEK 4
D33: Mar1-9 | E33: Mar10-16 | F33: Mar17-23 | G33: Mar24-31
B34: Delivered (DUVO) | C34: (mtons) | D34: =[1]Mar2024!$H$42 -> 1323.519 | E34: =[1]Mar2024!$H$43 -> 1583.27
B35: Divert to Buyers | D35: =[1]Mar2024!$I$42 -> 1017.83 | E35: =[1]Mar2024!$I$43 -> 311.012
B36: Divert to Buyers | C36: (mtons) | D36: 0 | E36: 0 | F36: 0 | G36: 0 | H36: 0
B37: Total Available | C37: (mtons) | G37: =G34+G35+G36 -> 0 | H37: =H34+H35+H36 -> 0
B38: Accumulative | D38: =D37 -> 0 | E38: =D38+E37 -> 0 | F38: =E38+F37 -> 0 | G38: =F38+G37 -> 0 | H38: =G38+H37 -> 0
B39: Target to Reach SCA Minimum | C39: (mtons) | D39: =C4/5 -> 1033.3333 | E39: =(C4-D38)/4 -> 1291.6667 | F39: =(C$4-E38)/3 -> 1722.2222 | G39: =(C$4-F38)/2 -> 2583.3333 | H39: =($C$4-G38) -> 5166.6667
C40: shortffall as of | D40: =C4-D37 -> 5166.6667 | E40: =D40-E37 -> 5166.6667 | F40: =E40-F37 -> 5166.6667 | G40: =F40-G37 -> 5166.6667 | H40: =G40-H37 -> 5166.6667
B45: Power Generation
B47: Monthly SCA Minimum | C47: =4953600/12 -> 412800 | D47: (kWh)
B48: Delivered | C48: =SUM(D75:H75) -> 136085 | D48: (kWh)
B49: Target to Reach SCA Minimum | C49: =C47-C48 -> 276715 | D49: (kWh)
D73: WEEK 1 | E73: WEEK 2 | F73: WEEk 3 | G73: WEEK 4 | H73: WEEK 5
D74: Mar1-9 | E74: Mar10-16 | F74: Mar17-23 | G74: Mar24-31
B75: Delivered | C75: (kWh) | D75: =[1]Mar2024!$J$42 -> 72734 | E75: =[1]Mar2024!$J$43 -> 63351 | G75: =[2]Dec2023!$I$45 -> 0 | I75: =SUM(D75:H75) -> 136085
B76: Accumulative | C76: (kWh) | D76: =D75 -> 72734 | E76: =D76+E75 -> 136085 | F76: =E76+F75 -> 136085 | G76: =F76+G75 -> 136085 | H76: =G76+H75 -> 136085
B77: Target to Reach SCA Minimum | C77: (kWh) | D77: =C47/5 -> 82560 | E77: =(C47-D77)/4 -> 82560 | F77: =($C$47-E76)/3 -> 92238.333 | G77: =($C$47-F76)/2 -> 138357.5 | H77: =($C$47-G76)/1 -> 276715
B80: Biogas Utilization
B82: Monthly SCA Minimum | C82: =4140528/12 -> 345044 | D82: (Nm3)
B83: Delivered | C83: =SUM(D113:H113) -> 129703.81 | D83: (Nm3)
B84: Target to Reach SCA Minimum | C84: =C82-C83 -> 215340.19 | D84: (Nm3)
D108: WEEK 1 | E108: WEEK 2 | F108: WEEK 3 | G108: WEEK 4 | H108: WEEK 5 | I108: Over-all
D109: Mar1-9 | E109: Mar10-16 | F109: Mar17-23 | G109: Mar24-31
B110: Delivered to Boilers | C110: (Nm3) | D110: =[1]Mar2024!$N$42 -> 15993 | E110: =[1]Mar2024!$N$43 -> 46342 | I110: =SUM(D110:H110) -> 62335
B111: Delivered to Engine | C111: (Nm3) | D111: =[1]Mar2024!$M$42 -> 36006.931 | E111: =[1]Mar2024!$M$43 -> 31361.881 | I111: =SUM(D111:H111) -> 67368.812
B112: Flared | C112: (Nm3) | D112: =[1]Mar2024!$O$42 -> 0 | E112: =[1]Mar2024!$O$43 -> 0 | I112: =SUM(D112:H112) -> 0
B113: Total Produced | C113: (Nm3) | D113: =SUM(D110:D112) -> 51999.931 | E113: =SUM(E110:E112) -> 77703.881 | F113: =SUM(F110:F112) -> 0 | G113: =SUM(G110:G112) -> 0 | H113: =SUM(H110:H112) -> 0 | I113: =SUM(D113:H113) -> 129703.81
B114: Accumulative | C114: (Nm3) | D114: =D113 -> 51999.931 | E114: =D114+E113 -> 129703.81 | F114: =E114+F113 -> 129703.81 | G114: =F114+G113 -> 129703.81 | H114: =G114+H113 -> 129703.81
B115: Target to Reach SCA Minimum | C115: (Nm3) | D115: =$C$82/5 -> 69008.8 | E115: =($C$82-D114)/4 -> 73261.017 | F115: =($C$82-E114)/3 -> 71780.063 | G115: =($C$82-F114)/2 -> 107670.09 | H115: =C82-H114 -> 215340.19 | I115: =C82 -> 345044
B118: Percent Utilization of Substrates
B120: Considering Original Weight
D121: 105 | E121: Nm3/ton
D122: Mar1-9 | E122: Mar10-16 | F122: Mar17-23 | G122: Mar24-31 | I122: Over-all
...

Sheet Mar actual FM volVer2
B2: Substrate Supply
B4: Monthly SCA Minimum | C4: =(62000-36999)/4 -> 6250.25 | D4: (mtons)
B5: Annual SCA Minimum | C5: 62000 | D5: (mtons)
B6: Delivered | C6: =SUM(D35:H35) -> 2906.789 | D6: (mtons)
B7: Rejected | C7: =SUM(D37:H37) -> 0 | D7: (mtons)
C27: =477/5167 -> 0.092316625 | E27: =E28/5167 -> 0.29998065 | F27: =F28/5167 -> 0.55196439 | G27: =G28/5167 -> 0.7892394
C28: =477 -> 477 | E28: =477+1073 -> 1550 | F28: =1550+1302 -> 2852 | G28: =2852+1226 -> 4078
D33: WEEK 1 | E33: WEEK 2 | F33: WEEk 3 | G33: WEEK 4
D34: Mar1-9 | E34: Mar10-16 | F34: Mar17-23 | G34: Mar24-31
B35: Delivered (DUVO) | C35: (mtons) | D35: =[1]Mar2024!$H$42 -> 1323.519 | E35: =[1]Mar2024!$H$43 -> 1583.27 | J35: =D35/C4 -> 0.21175457
B36: Divert to Buyers | D36: =[1]Mar2024!$I$42 -> 1017.83 | E36: =[1]Mar2024!$I$43 -> 311.012
B37: Divert to Buyers | C37: (mtons) | D37: 0 | E37: 0 | F37: 0 | G37: 0 | H37: 0
B38: Total Available | C38: (mtons) | G38: =G35+G36+G37 -> 0 | H38: =H35+H36+H37 -> 0
B39: Accumulative | D39: =D38 -> 0 | E39: =D39+E38 -> 0 | F39: =E39+F38 -> 0 | G39: =F39+G38 -> 0 | H39: =G39+H38 -> 0
B40: Target to Reach SCA Minimum | C40: (mtons) | D40: =C4/5 -> 1250.05 | E40: =(C4-D39)/4 -> 1562.5625 | F40: =(C$4-E39)/3 -> 2083.4167 | G40: =(C$4-F39)/2 -> 3125.125 | H40: =($C$4-G39) -> 6250.25
C41: shortffall as of | D41: =C4-D38 -> 6250.25 | E41: =D41-E38 -> 6250.25 | F41: =E41-F38 -> 6250.25 | G41: =F41-G38 -> 6250.25 | H41: =G41-H38 -> 6250.25
B46: Power Generation
B48: Monthly SCA Minimum | C48: =(4953600-305990)/4 -> 1161902.5 | D48: (kWh)
B49: Annual SCA Minimum | C49: 4953600 | D49: (kWh)
B50: Delivered | C50: =SUM(D77:H77) -> 136085 | D50: (kWh)
B51: Target to Reach SCA Minimum | C51: =C48-C50 -> 1025817.5 | D51: (kWh)
D75: WEEK 1 | E75: WEEK 2 | F75: WEEk 3 | G75: WEEK 4 | H75: WEEK 5
D76: Mar1-9 | E76: Mar10-16 | F76: Mar17-23 | G76: Mar24-31
B77: Delivered | C77: (kWh) | D77: =[1]Mar2024!$J$42 -> 72734 | E77: =[1]Mar2024!$J$43 -> 63351 | G77: =[2]Dec2023!$I$45 -> 0 | I77: =SUM(D77:H77) -> 136085
B78: Accumulative | C78: (kWh) | D78: =D77 -> 72734 | E78: =D78+E77 -> 136085 | F78: =E78+F77 -> 136085 | G78: =F78+G77 -> 136085 | H78: =G78+H77 -> 136085
B79: Target to Reach SCA Minimum | C79: (kWh) | D79: =C48/5 -> 232380.5 | E79: =(C48-D79)/4 -> 232380.5 | F79: =($C$48-E78)/3 -> 341939.17 | G79: =($C$48-F78)/2 -> 512908.75 | H79: =($C$48-G78)/1 -> 1025817.5
B82: Biogas Utilization
B84: Monthly SCA Minimum | C84: =(4140528-2484001)/4 -> 414131.75 | D84: (Nm3)
B85: Annual SCA Minimum | C85: 4140528 | D85: (Nm3)
B86: Delivered | C86: =SUM(D116:H116) -> 129703.81 | D86: (Nm3)
B87: Target to Reach SCA Minimum | C87: =C84-C86 -> 284427.94 | D87: (Nm3)
D111: WEEK 1 | E111: WEEK 2 | F111: WEEK 3 | G111: WEEK 4 | H111: WEEK 5 | I111: Over-all
D112: Mar1-9 | E112: Mar10-16 | F112: Mar17-23 | G112: Mar24-31
B113: Delivered to Boilers | C113: (Nm3) | D113: =[1]Mar2024!$N$42 -> 15993 | E113: =[1]Mar2024!$N$43 -> 46342 | I113: =SUM(D113:H113) -> 62335 | K113: =I113/D116 -> 1.1987516
B114: Delivered to Engine | C114: (Nm3) | D114: =[1]Mar2024!$M$42 -> 36006.931 | E114: =[1]Mar2024!$M$43 -> 31361.881 | I114: =SUM(D114:H114) -> 67368.812
B115: Flared | C115: (Nm3) | D115: =[1]Mar2024!$O$42 -> 0 | E115: =[1]Mar2024!$O$43 -> 0 | I115: =SUM(D115:H115) -> 0
B116: Total Produced | C116: (Nm3) | D116: =SUM(D113:D115) -> 51999.931 | E116: =SUM(E113:E115) -> 77703.881 | F116: =SUM(F113:F115) -> 0 | G116: =SUM(G113:G115) -> 0 | H116: =SUM(H113:H115) -> 0 | I116: =SUM(D116:H116) -> 129703.81
B117: Accumulative | C117: (Nm3) | D117: =D116 -> 51999.931 | E117: =D117+E116 -> 129703.81 | F117: =E117+F116 -> 129703.81 | G117: =F117+G116 -> 129703.81 | H117: =G117+H116 -> 129703.81
B118: Target to Reach SCA Minimum | C118: (Nm3) | D118: =$C$84/5 -> 82826.35 | E118: =($C$84-D117)/4 -> 90532.955 | F118: =($C$84-E117)/3 -> 94809.313 | G118: =($C$84-F117)/2 -> 142213.97 | H118: =C84-H117 -> 284427.94 | I118: =C84 -> 414131.75
B121: Percent Utilization of Substrates
...

Sheet May actual FM vol
B2: Substrate Supply
B4: Monthly SCA Minimum | C4: =(62000-24055+4168+4544)/2 -> 23328.5 | D4: (mtons) | E4: > Running SCA Based on DUVO delivered pulp only
B5: Annual SCA Minimum | C5: 62000 | D5: (mtons)
B6: Delivered | C6: =SUM(D35:H35) -> 426.56 | D6: (mtons)
B7: Rejected | C7: =SUM(D37:H37) -> 0 | D7: (mtons)
D33: WEEK 1 (May1-4) | E33: WEEK 2 (May5-11) | F33: WEEk 3 (May12-18) | G33: WEEk 4 (May19-25) | H33: WEEK 5 (May26-31)
B35: Delivered (DUVO) | C35: (mtons) | D35: 12.39 | E35: 414.17
B36: Divert from Pol | D36: 51.49 | E36: 102.92 | I36: =170*11 -> 1870
B38: Total Available | C38: (mtons) | D38: =D36+D35 -> 63.88 | E38: =E36+E35 -> 517.09 | F38: =F35 -> 0 | G38: =G35 -> 0 | H38: =H35 -> 0 | I38: =SUM(D38:H38) -> 580.97
B39: Accumulative | D39: =D38 -> 63.88 | E39: =D39+E38 -> 580.97 | F39: =E39+F38 -> 580.97 | G39: =F39+G38 -> 580.97 | H39: =G39+H38 -> 580.97 | I39: =I38-I36 -> -1289.03
B40: Target to Reach SCA Minimum | C40: (mtons) | D40: =C4/5 -> 4665.7 | E40: =(C4-D39)/4 -> 5816.155 | F40: =(C$4-E39)/3 -> 7582.51 | G40: =(C$4-F39)/2 -> 11373.765 | H40: =($C$4-G39) -> 22747.53
C41: shortffall as of | D41: =C4-D38 -> 23264.62 | E41: =D41-E38 -> 22747.53 | F41: =E41-F38 -> 22747.53 | G41: =F41-G38 -> 22747.53 | H41: =G41-H38 -> 22747.53
B46: Power Generation
B48: Monthly SCA Minimum | C48: =(4953600-(305990+227497+112081))/2 -> 2154016 | D48: (kWh)
B49: Annual SCA Minimum | C49: 4953600 | D49: (kWh)
B50: Delivered | C50: =SUM(D76:H76) -> 81343 | D50: (kWh)
B51: Target to Reach SCA Minimum | C51: =C48-C50 -> 2072673 | D51: (kWh)
D75: WEEK 1 (May1-4) | E75: WEEK 2 (May5-11) | F75: WEEk 3 (May12-18) | G75: WEEk 4 (May19-25) | H75: WEEK 5 (May26-31)
B76: Delivered | C76: (kWh) | D76: 39342 | E76: 42001
B77: Accumulative | C77: (kWh) | D77: =D76 -> 39342 | E77: =D77+E76 -> 81343 | F77: =E77+F76 -> 81343 | G77: =F77+G76 -> 81343 | H77: =G77+G76 -> 81343 | I77: =H77/C48 -> 0.037763415
B78: Target to Reach SCA Minimum | C78: (kWh) | D78: =C48/5 -> 430803.2 | E78: =(C48-D77)/4 -> 528668.5 | F78: =($C$48-E77)/3 -> 690891 | G78: =($C$48-F77)/2 -> 1036336.5 | H78: =(C48-G78)/1 -> 1117679.5
B81: Biogas Utilization
B83: Monthly SCA Minimum | C83: =(4140528-(2484001+148391+302350))/2 -> 602893 | D83: (Nm3)
B84: Annual SCA Minimum | C84: 4140528 | D84: (Nm3)
B85: Delivered | C85: =SUM(D114:H114) -> 117942 | D85: (Nm3)
B86: Target to Reach SCA Minimum | C86: =C83-C85 -> 484951 | D86: (Nm3)
D110: WEEK 1 (May1-4) | E110: WEEK 2 (May5-11) | F110: WEEk 3 (May12-18) | G110: WEEk 4 (May19-25) | H110: WEEK 5 (May26-31)
B111: Delivered to Boilers | C111: (Nm3) | D111: 23322 | E111: 54533 | I111: =SUM(D111:H111) -> 77855
B112: Delivered to Engine | C112: (Nm3) | D112: 19294 | E112: 20793 | I112: =SUM(D112:H112) -> 40087
B113: Flared | C113: (Nm3) | I113: =SUM(D113:H113) -> 0
B114: Total Produced | C114: (Nm3) | D114: =SUM(D111:D113) -> 42616 | E114: =SUM(E111:E113) -> 75326 | F114: =SUM(F111:F113) -> 0 | G114: =SUM(G111:G113) -> 0 | H114: =SUM(H111:H113) -> 0
B115: Accumulative | C115: (Nm3) | D115: =D114 -> 42616 | E115: =D115+E114 -> 117942 | F115: =E115+F114 -> 117942 | G115: =F115+G114 -> 117942 | H115: =G115+H114 -> 117942
B116: Target to Reach SCA min | C116: (Nm3) | D116: =$C$83/5 -> 120578.6 | E116: =($C$83-D115)/4 -> 140069.25 | F116: =($C$83-E115)/3 -> 161650.33 | G116: =($C$83-F115)/2 -> 242475.5 | H116: =($C$83-G115)/1 -> 484951
B119: Percent Utilization of Substrates
B121: Considering Original Weight
D122: 105 | E122: Nm3/ton
D123: Wk 1 (May1-4) | E123: Wk 2 (May5-11) | F123: Wk 3 (May12-18) | G123: Wk 4 (May19-25) | H123: Wk 5 (May26-31) | I123: Over-all
B125: Available Substrate | C125: (Nm3) | D125: 416 | E125: 872 | I125: =SUM(D125:H125) -> 1288
B126: SCA Gas Equivalent | C126: (Nm3) | D126: =D129*D125 -> 43680 | E126: =E129*E125 -> 91560 | F126: =F129*F125 -> 0 | G126: =G129*G125 -> 0 | H126: =H129*H125 -> 0 | I126: =I129*I125 -> 135240
B127: Actual Gas Produced | C127: (Nm3) | D127: =D114 -> 42616 | E127: =E114 -> 75326 | F127: =F114 -> 0 | G127: =G114 -> 0 | H127: =H114 -> 0 | I127: =SUM(D127:H127) -> 117942
...

Sheet Dec
B2: Substrate Supply - Y3
B4: Annual SCA Minimum | C4: 143000 | D4: (mtons)
B5: Running Monthly Minimum to meet SCA Guaranty | C5: =(C4-C7)/7 -> 15378.429 | D5: (mtons)
B6: Delivered | C6: =SUM(D36:G36) -> 9710.35 | D6: (mtons)
B7: YTD total | C7: 35351 | D7: (mtons)
B8: Rejected | C8: =SUM(D38:G38) -> 0 | D8: (mtons)
D34: WEEK 1 (Dec1-7) | E34: WEEK 2 (Dec8-14) | F34: WEEk 3 (Dec15-21) | G34: WEEk 4 (Dec22-31)
B36: Delivered (DUVO) | C36: (mtons) | D36: 2093 | E36: 2267.49 | F36: 2410.3 | G36: 2939.56
B37: Diverted
B39: Total Available | C39: (mtons) | D39: =D37+D36 -> 2093 | E39: =IF(E37+E36="",0,E37+E36) -> 2267.49 | F39: =F36 -> 2410.3 | G39: =G36 -> 2939.56
B40: Monthly Accumulative | D40: =D39 -> 2093 | E40: =E39+D40 -> 4360.49 | F40: =F39+E40 -> 6770.79 | G40: =G39+F40 -> 9710.35
B41: Target to Reach SCA Minimum | C41: (mtons) | D41: =(C5/31)*7 -> 3472.5484 | E41: =((C5/31)*14)-D40 -> 4852.0968 | F41: =((C5/31)*21)-E40 -> 6057.1552 | G41: =((C5/31)*31)-F40 -> 8607.6386
B47: Power Generation - Y3
B49: Annual SCA Minimum | C49: 9907200 | D49: (kWh)
B50: Monthly SCA Minimum | C50: =(C49-C52)/7 -> 1153958.9 | D50: (kWh)
B51: Delivered | C51: =SUM(D78:G78) -> 817937 | D51: (kWh)
B52: YTD Total | C52: 1829488 | D52: (kWh)
B53: Target to Reach SCA Minimum | C53: =C50-C51 -> 336021.86 | D53: (kWh)
E60: (kWh)
D77: WEEK 1 (Dec1-7) | E77: WEEK 2 (Dec8-14) | F77: WEEk 3 (Dec15-21) | G77: WEEk 4 (Dec22-31)
B78: Delivered | C78: (kWh) | D78: 207561 | E78: 204464 | F78: 207039 | G78: 198873
B79: Accumulative | C79: (kWh) | D79: =D78 -> 207561 | E79: =D79+E78 -> 412025 | F79: =E79+F78 -> 619064 | G79: =F79+G78 -> 817937
B80: Target to Reach SCA Minimum | C80: (kWh) | D80: =C50/4 -> 288489.71 | E80: =(C50-D79)/3 -> 315465.95 | F80: =($C$50-E79)/2 -> 370966.93 | G80: =(C50-F79)/1 -> 534894.86
B84: Biogas Utilization - Y3
B86: Annual SCA Minimum | C86: 10000000 | D86: (Nm3)
B87: Monthly SCA Minimum | C87: =(C86-C89)/7 -> 1203413 | D87: (Nm3)
B88: Delivered | C88: =SUM(D115:G115,D117:G117) -> 616747 | D88: (Nm3)
B89: YTD Total | C89: 1576109 | D89: (Nm3)
B90: Target to Reach SCA Minimum | C90: =C87-C88 -> 586666 | D90: (Nm3)
D114: WEEK 1 (Dec1-7) | E114: WEEK 2 (Dec8-14) | F114: WEEk 3 (Dec15-21) | G114: WEEk 4 (Dec22-31)
B115: Delivered to Boilers | C115: (Nm3) | D115: 97252 | E115: 121037 | F115: 174921 | G115: 215191
B116: Delivered to Engine | C116: (Nm3) | D116: =D78*0.47 -> 97553.67 | E116: =E78*0.47 -> 96098.08 | F116: =F78*0.47 -> 97308.33 | G116: =G78*0.47 -> 93470.31
B117: Flared | C117: (Nm3) | E117: 2105 | G117: 6241
B118: Total Produced | C118: (Nm3) | D118: =D115+D117 -> 97252 | E118: =E115+E117 -> 123142 | F118: =SUM(F115:F117) -> 272229.33 | G118: =SUM(G115:G117) -> 314902.31
B119: Accumulative | C119: (Nm3) | D119: =D118 -> 97252 | E119: =D119+E118 -> 220394 | F119: =E119+F118 -> 492623.33 | G119: =F119+G118 -> 807525.64
B120: Target Gas vs Delivered Substrates | C120: (Nm3) | D120: =D36*101*0.7842 -> 165774.39 | E120: =E36*101*0.7842 -> 179594.73 | F120: =F36*101*0.7842 -> 190905.88 | G120: =G36*101*0.7842 -> 232825.5
B121: Target to Reach SCA min | C121: (Nm3) | D121: =$C$87/4 -> 300853.25 | E121: =($C$87-D119)/3 -> 368720.33 | F121: =($C$87-E119)/2 -> 491509.5 | G121: =($C$87-F119)/1 -> 710789.67
B124: Percent Utilization of Substrates - Y3
B126: Considering Original Weight
D127: 101 | E127: Nm3/ton
...

Sheet Jan
B2: Substrate Supply - Y3
B4: Annual SCA Minimum | C4: 143000 | D4: (mtons)
B5: Running Monthly Minimum to meet SCA Guaranty | C5: =(C4-C7)/6 -> 16323.167 | D5: (mtons)
B6: Delivered | C6: =SUM(D36:G36) -> 9589.1 | D6: (mtons)
B7: YTD total | C7: =35351+9710 -> 45061 | D7: (mtons)
B8: Rejected | C8: =SUM(D38:G38) -> 0 | D8: (mtons)
D34: WEEK 1 (Jan1-11) | E34: WEEK 2 (Jan12-18) | F34: WEEk 3 (Jan19-25) | G34: WEEk 4 (Jan26-31)
B36: Delivered (DUVO) | C36: (mtons) | D36: 3453.98 | E36: 1987.72 | F36: 2311.76 | G36: 1835.64
B37: Diverted
B39: Total Available | C39: (mtons) | D39: =D37+D36 -> 3453.98 | E39: =IF(E37+E36="",0,E37+E36) -> 1987.72 | F39: =F36 -> 2311.76 | G39: =G36 -> 1835.64
B40: Monthly Accumulative | D40: =D39 -> 3453.98 | E40: =E39+D40 -> 5441.7 | F40: =F39+E40 -> 7753.46 | G40: =G39+F40 -> 9589.1
B41: Target to Reach SCA Minimum | C41: (mtons) | D41: =(C5/31)*7 -> 3685.8763 | E41: =((C5/31)*14)-D40 -> 3917.7727 | F41: =((C5/31)*21)-E40 -> 5615.929 | G41: =((C5/31)*31)-F40 -> 8569.7067
B47: Power Generation - Y3
B49: Annual SCA Minimum | C49: 9907200 | D49: (kWh)
B50: Monthly SCA Minimum | C50: =(C49-C52)/6 -> 1209962.5 | D50: (kWh)
B51: Delivered | C51: =SUM(D78:G78) -> 596387 | D51: (kWh)
B52: YTD Total | C52: =1829488+817937 -> 2647425 | D52: (kWh)
B53: Target to Reach SCA Minimum | C53: =C50-C51 -> 613575.5 | D53: (kWh)
E60: (kWh)
D77: =D34 -> WEEK 1 (Jan1-11) | E77: =E34 -> WEEK 2 (Jan12-18) | F77: =F34 -> WEEk 3 (Jan19-25) | G77: =G34 -> WEEk 4 (Jan26-31)
B78: Delivered | C78: (kWh) | D78: 234896 | E78: 53486 | F78: 173215 | G78: 134790
B79: Accumulative | C79: (kWh) | D79: =D78 -> 234896 | E79: =D79+E78 -> 288382 | F79: =E79+F78 -> 461597 | G79: =F79+G78 -> 596387
B80: Target to Reach SCA Minimum | C80: (kWh) | D80: =C50/4 -> 302490.62 | E80: =(C50-D79)/3 -> 325022.17 | F80: =($C$50-E79)/2 -> 460790.25 | G80: =(C50-F79)/1 -> 748365.5
B84: Biogas Utilization - Y3
B86: Annual SCA Minimum | C86: 10000000 | D86: (Nm3)
B87: Monthly SCA Minimum | C87: =(C86-C89)/6 -> 1301190.7 | D87: (Nm3)
B88: Delivered | C88: =SUM(D115:G115,D117:G117) -> 808557 | D88: (Nm3)
B89: YTD Total | C89: =1576109+616747 -> 2192856 | D89: (Nm3)
B90: Target to Reach SCA Minimum | C90: =C87-C88 -> 492633.67 | D90: (Nm3)
D114: =D77 -> WEEK 1 (Jan1-11) | E114: =E77 -> WEEK 2 (Jan12-18) | F114: =F77 -> WEEk 3 (Jan19-25) | G114: =G77 -> WEEk 4 (Jan26-31)
B115: Delivered to Boilers | C115: (Nm3) | D115: 285984 | E115: 182163 | F115: 145287 | G115: 155496
B116: Delivered to Engine | C116: (Nm3) | D116: =D78*0.47 -> 110401.12 | E116: =E78*0.47 -> 25138.42 | F116: =F78*0.47 -> 81411.05 | G116: =G78*0.47 -> 63351.3
B117: Flared | C117: (Nm3) | D117: 12742 | E117: 19766 | F117: 7119
B118: Total Produced | C118: (Nm3) | D118: =D115+D117 -> 298726 | E118: =E115+E117 -> 201929 | F118: =SUM(F115:F117) -> 233817.05 | G118: =SUM(G115:G117) -> 218847.3
B119: Accumulative | C119: (Nm3) | D119: =D118 -> 298726 | E119: =D119+E118 -> 500655 | F119: =E119+F118 -> 734472.05 | G119: =F119+G118 -> 953319.35
B120: Target Gas based on Delivered Substrates | C120: (Nm3) | D120: =D36*101*0.7842 -> 273569.72 | E120: =E36*101*0.7842 -> 157435.77 | F120: =F36*101*0.7842 -> 183101.1 | G120: =G36*101*0.7842 -> 145390.4
B121: Target to Reach SCA min | C121: (Nm3) | D121: =$C$87/4 -> 325297.67 | E121: =($C$87-D119)/3 -> 334154.89 | F121: =($C$87-E119)/2 -> 400267.83 | G121: =($C$87-F119)/1 -> 566718.62
B124: Percent Utilization of Substrates - Y3
B126: Considering Original Weight
D127: 101 | E127: Nm3/ton
...

Sheet Feb
B2: Substrate Supply - Y3
B4: Annual SCA Minimum | C4: 143000 | D4: (mtons)
B5: Running Monthly Minimum to meet SCA Guaranty | C5: =(C4-C7)/5 -> 17670 | D5: (mtons)
B6: Delivered | C6: =SUM(D36:G36) -> 6797.42 | D6: (mtons)
B7: YTD total | C7: =35351+9710+9589 -> 54650 | D7: (mtons)
B8: Rejected | C8: =SUM(D38:G38) -> 0 | D8: (mtons)
D34: WEEK 1 (Feb1-8) | E34: WEEK 2 (Feb9-15) | F34: WEEk 3 (Feb16-22) | G34: WEEk 4 (Feb23-28)
B36: Delivered (DPO) | C36: (mtons) | D36: 1822.01 | E36: 1793.46 | F36: 1719.49 | G36: 1462.46
B37: Diverted
B39: Total Available | C39: (mtons) | D39: =D37+D36 -> 1822.01 | E39: =IF(E37+E36="",0,E37+E36) -> 1793.46 | F39: =F36 -> 1719.49 | G39: =G36 -> 1462.46
B40: Monthly Accumulative | D40: =D39 -> 1822.01 | E40: =E39+D40 -> 3615.47 | F40: =F39+E40 -> 5334.96 | G40: =G39+F40 -> 6797.42
B41: Target to Reach SCA Minimum | C41: (mtons) | D41: =(C5/31)*7 -> 3990 | E41: =((C5/31)*14)-D40 -> 6157.99 | F41: =((C5/31)*21)-E40 -> 8354.53 | G41: =((C5/31)*31)-F40 -> 12335.04
B47: Power Generation - Y3
B49: Annual SCA Minimum | C49: 9907200 | D49: (kWh)
B50: Monthly SCA Minimum | C50: =(C49-C52)/5 -> 1332677.6 | D50: (kWh)
B51: Delivered | C51: =SUM(D78:G78) -> 557424 | D51: (kWh)
B52: YTD Total | C52: =1829488+817937+596387 -> 3243812 | D52: (kWh)
B53: Target to Reach SCA Minimum | C53: =C50-C51 -> 775253.6 | D53: (kWh)
E60: (kWh)
D77: =D34 -> WEEK 1 (Feb1-8) | E77: =E34 -> WEEK 2 (Feb9-15) | F77: =F34 -> WEEk 3 (Feb16-22) | G77: =G34 -> WEEk 4 (Feb23-28)
B78: Delivered | C78: (kWh) | D78: 80667 | E78: 163084 | F78: 173423 | G78: 140250
B79: Accumulative | C79: (kWh) | D79: =D78 -> 80667 | E79: =D79+E78 -> 243751 | F79: =E79+F78 -> 417174 | G79: =F79+G78 -> 557424
B80: Target to Reach SCA Minimum | C80: (kWh) | D80: =C50/4 -> 333169.4 | E80: =(C50-D79)/3 -> 417336.87 | F80: =($C$50-E79)/2 -> 544463.3 | G80: =(C50-F79)/1 -> 915503.6
B84: Biogas Utilization - Y3
B86: Annual SCA Minimum | C86: 10000000 | D86: (Nm3)
B87: Monthly SCA Minimum | C87: =(C86-C89)/5 -> 1399717.4 | D87: (Nm3)
B88: Delivered | C88: =SUM(D115:G115,D117:G117) -> 512424 | D88: (Nm3)
B89: YTD Total | C89: =1576109+616747+808557 -> 3001413 | D89: (Nm3)
B90: Target to Reach SCA Minimum | C90: =C87-C88 -> 887293.4 | D90: (Nm3)
D114: =D77 -> WEEK 1 (Feb1-8) | E114: =E77 -> WEEK 2 (Feb9-15) | F114: =F77 -> WEEk 3 (Feb16-22) | G114: =G77 -> WEEk 4 (Feb23-28)
B115: Delivered to Boilers | C115: (Nm3) | D115: 141882 | E115: 137632 | F115: 124817 | G115: 99417
B116: Delivered to Engine | C116: (Nm3) | D116: =D78*0.47 -> 37913.49 | E116: =E78*0.47 -> 76649.48 | F116: =F78*0.47 -> 81508.81 | G116: =G78*0.47 -> 65917.5
B117: Flared | C117: (Nm3) | D117: 8676
B118: Total Produced | C118: (Nm3) | D118: =D115+D117 -> 150558 | E118: =E115+E117 -> 137632 | F118: =SUM(F115:F117) -> 206325.81 | G118: =SUM(G115:G117) -> 165334.5
B119: Accumulative | C119: (Nm3) | D119: =D118 -> 150558 | E119: =D119+E118 -> 288190 | F119: =E119+F118 -> 494515.81 | G119: =F119+G118 -> 659850.31
B120: Target Gas based on Delivered Substrates | C120: (Nm3) | D120: =D36*101*0.7842 -> 144310.84 | E120: =E36*101*0.7842 -> 142049.56 | F120: =F36*101*0.7842 -> 136190.83 | G120: =G36*101*0.7842 -> 115832.97
B121: Target to Reach SCA min | C121: (Nm3) | D121: =$C$87/4 -> 349929.35 | E121: =($C$87-D119)/3 -> 416386.47 | F121: =($C$87-E119)/2 -> 555763.7 | G121: =($C$87-F119)/1 -> 905201.59
B124: Percent Utilization of Substrates - Y3
B126: Considering Original Weight
D127: 101 | E127: Nm3/ton
...

Sheet Mar
B2: Substrate Supply - Y3
B4: Annual SCA Minimum | C4: 143000 | D4: (mtons)
B5: Running Monthly Minimum to meet SCA Guaranty | C5: =(C4-C7)/4 -> 19347.055 | D5: (mtons)
B6: Delivered | C6: =SUM(D36:G36) -> 6540.16 | D6: (mtons)
B7: YTD total | C7: =65611.78 -> 65611.78 | D7: (mtons)
B8: Rejected | C8: =SUM(D38:G38) -> 0 | D8: (mtons)
D34: WEEK 1 (Mar1-8) | E34: WEEK 2 (Mar9-15) | F34: WEEk 3 (Mar16-22) | G34: WEEk 4 (Mar23-31)
B36: Delivered (DPO) | C36: (mtons) | D36: 1848.86 | E36: 1560.11 | F36: 1715.53 | G36: 1415.66
B37: Diverted
B39: Total Available | C39: (mtons) | D39: =D37+D36 -> 1848.86 | E39: =IF(E37+E36="",0,E37+E36) -> 1560.11 | F39: =F36 -> 1715.53 | G39: =G36 -> 1415.66
B40: Monthly Accumulative | D40: =D39 -> 1848.86 | E40: =E39+D40 -> 3408.97 | F40: =F39+E40 -> 5124.5 | G40: =G39+F40 -> 6540.16
B41: Target to Reach SCA Minimum | C41: (mtons) | D41: =(C5/31)*7 -> 4368.6898 | E41: =((C5/31)*14)-D40 -> 6888.5197 | F41: =((C5/31)*21)-E40 -> 9697.0995 | G41: =((C5/31)*31)-F40 -> 14222.555
B47: Power Generation - Y3
B49: Annual SCA Minimum | C49: 9907200 | D49: (kWh)
B50: Monthly SCA Minimum | C50: =(C49-C52)/4 -> 1529687.2 | D50: (kWh)
B51: Delivered | C51: =SUM(D78:G78) -> 599535 | D51: (kWh)
B52: YTD Total | C52: =3788451 -> 3788451 | D52: (kWh)
B53: Target to Reach SCA Minimum | C53: =C50-C51 -> 930152.25 | D53: (kWh)
E60: (kWh)
D77: =D34 -> WEEK 1 (Mar1-8) | E77: =E34 -> WEEK 2 (Mar9-15) | F77: =F34 -> WEEk 3 (Mar16-22) | G77: =G34 -> WEEk 4 (Mar23-31)
B78: Delivered | C78: (kWh) | D78: 162800 | E78: 139997 | F78: 151839 | G78: 144899
B79: Accumulative | C79: (kWh) | D79: =D78 -> 162800 | E79: =D79+E78 -> 302797 | F79: =E79+F78 -> 454636 | G79: =F79+G78 -> 599535
B80: Target to Reach SCA Minimum | C80: (kWh) | D80: =C50/4 -> 382421.81 | E80: =(C50-D79)/3 -> 455629.08 | F80: =($C$50-E79)/2 -> 613445.12 | G80: =(C50-F79)/1 -> 1075051.2
B84: Biogas Utilization - Y3
B86: Annual SCA Minimum | C86: 10000000 | D86: (Nm3)
B87: Monthly SCA Minimum | C87: =(C86-C89)/4 -> 1620903 | D87: (Nm3)
B88: Delivered | C88: =SUM(D115:G115,D117:G117) -> 407206 | D88: (Nm3)
B89: YTD Total | C89: =3516388 -> 3516388 | D89: (Nm3)
B90: Target to Reach SCA Minimum | C90: =C87-C88 -> 1213697 | D90: (Nm3)
D114: =D77 -> WEEK 1 (Mar1-8) | E114: =E77 -> WEEK 2 (Mar9-15) | F114: =F77 -> WEEk 3 (Mar16-22) | G114: =G77 -> WEEk 4 (Mar23-31)
B115: Delivered to Boilers | C115: (Nm3) | D115: 116823 | E115: 98963 | F115: 103165 | G115: 88255
B116: Delivered to Engine | C116: (Nm3) | D116: =D78*0.47 -> 76516 | E116: =E78*0.47 -> 65798.59 | F116: =F78*0.47 -> 71364.33 | G116: =G78*0.47 -> 68102.53
B117: Flared | C117: (Nm3)
B118: Total Produced | C118: (Nm3) | D118: =D115+D117 -> 116823 | E118: =E115+E117 -> 98963 | F118: =SUM(F115:F117) -> 174529.33 | G118: =SUM(G115:G117) -> 156357.53
B119: Accumulative | C119: (Nm3) | D119: =D118 -> 116823 | E119: =D119+E118 -> 215786 | F119: =E119+F118 -> 390315.33 | G119: =F119+G118 -> 546672.86
B120: Target Gas based on Delivered Substrates | C120: (Nm3) | D120: =D36*101*0.7842 -> 146437.48 | E120: =E36*101*0.7842 -> 123567.26 | F120: =F36*101*0.7842 -> 135877.18 | G120: =G36*101*0.7842 -> 112126.22
B121: Target to Reach SCA min | C121: (Nm3) | D121: =$C$87/4 -> 405225.75 | E121: =($C$87-D119)/3 -> 501360 | F121: =($C$87-E119)/2 -> 702558.5 | G121: =($C$87-F119)/1 -> 1230587.7
B124: Percent Utilization of Substrates - Y3
B126: Considering Original Weight
D127: 101 | E127: Nm3/ton
...

Sheet Apr(SCA)
B2: Substrate Supply - Y3
B4: Annual SCA Minimum | C4: 143000 | D4: (mtons)
B5: Running Monthly Minimum to meet SCA Guaranty | C5: =(C4-0)/12 -> 11916.667 | D5: (mtons)
B6: Delivered | C6: =SUM(D36:G36) -> 5453.78 | D6: (mtons)
B7: YTD total | C7: =C6 -> 5453.78 | D7: (mtons)
B8: Rejected | C8: =SUM(D38:G38) -> 0 | D8: (mtons)
D34: WEEK 1 (Apr1-5) | E34: WEEK 2 (Apr6-12) | F34: WEEK 3 (Apr13-19) | G34: WEEK 4 (Apr20-26) | H34: WEEk 5 (Apr27-30)
B36: Delivered (DPO) | C36: (mtons) | D36: 1112.79 | E36: 1301.55 | F36: 1569.69 | G36: 1469.75 | H36: 947.86
B37: Diverted
B39: Total Available | C39: (mtons) | D39: =D37+D36 -> 1112.79 | E39: =IF(E37+E36="",0,E37+E36) -> 1301.55 | F39: =F36 -> 1569.69 | G39: =G36 -> 1469.75 | H39: =H36 -> 947.86
B40: Monthly Accumulative | D40: =D39 -> 1112.79 | E40: =E39+D40 -> 2414.34 | F40: =F39+E40 -> 3984.03 | G40: =G39+F40 -> 5453.78 | H40: =H39+G40 -> 6401.64
B41: Target to Reach SCA Minimum | C41: (mtons) | D41: =(C5/30)*5 -> 1986.1111 | E41: =((C5/30)*12)-D40 -> 3653.8767 | F41: =((C5/30)*19)-E40 -> 5132.8822 | G41: =((C5/30)*26)-F40 -> 6343.7478 | H41: =((C5/30)*30)-G40 -> 6462.8867
B47: Power Generation - Y3
B49: Annual SCA Minimum | C49: 9907200 | D49: (kWh)
B50: Monthly SCA Minimum | C50: =(C49-0)/12 -> 825600 | D50: (kWh)
B51: Delivered | C51: =SUM(D78:G78) -> 444787 | D51: (kWh)
B52: YTD Total | C52: =C51 -> 444787 | D52: (kWh)
B53: Target to Reach SCA Minimum | C53: =C50-C51 -> 380813 | D53: (kWh)
E60: (kWh)
D77: =D34 -> WEEK 1 (Apr1-5) | E77: =E34 -> WEEK 2 (Apr6-12) | F77: =F34 -> WEEK 3 (Apr13-19) | G77: =G34 -> WEEK 4 (Apr20-26) | H77: =H34 -> WEEk 5 (Apr27-30)
B78: Delivered | C78: (kWh) | D78: 71832 | E78: 145087 | F78: 139215 | G78: 88653 | H78: 87345
B79: Accumulative | C79: (kWh) | D79: =D78 -> 71832 | E79: =D79+E78 -> 216919 | F79: =E79+F78 -> 356134 | G79: =F79+G78 -> 444787 | H79: =G79+H78 -> 532132
B80: Target to Reach SCA Minimum | C80: (kWh) | D80: =(C50/30)*5 -> 137600 | E80: =(($C50/30)*12)-D79 -> 258408 | F80: =(($C50/30)*19)-E79 -> 305961 | G80: =(($C50/30)*26)-F79 -> 359386 | H80: =(($C50/30)*30)-G79 -> 380813
B83: Biogas Utilization - Y3
B85: Annual SCA Minimum | C85: 10000000 | D85: (Nm3)
B86: Monthly SCA Minimum | C86: =(C85-0)/12 -> 833333.33 | D86: (Nm3)
B87: Delivered | C87: =SUM(D114:G114,D116:G116) -> 256874 | D87: (Nm3)
B88: YTD Total | C88: =C87 -> 256874 | D88: (Nm3)
B89: Target to Reach SCA Minimum | C89: =C86-C87 -> 576459.33 | D89: (Nm3)
D113: =D77 -> WEEK 1 (Apr1-5) | E113: =E77 -> WEEK 2 (Apr6-12) | F113: =F77 -> WEEK 3 (Apr13-19) | G113: =G77 -> WEEK 4 (Apr20-26) | H113: =H77 -> WEEk 5 (Apr27-30)
B114: Delivered to Boilers | C114: (Nm3) | D114: 62099 | E114: 57133 | F114: 78237 | G114: 59405 | H114: 54840
B115: Delivered to Engine | C115: (Nm3) | D115: =D78*0.47 -> 33761.04 | E115: =E78*0.47 -> 68190.89 | F115: =F78*0.47 -> 65431.05 | G115: =G78*0.47 -> 41666.91 | H115: =H78*0.47 -> 41052.15
B116: Flared | C116: (Nm3)
B117: Total Produced | C117: (Nm3) | D117: =D114+D116 -> 62099 | E117: =E114+E116 -> 57133 | F117: =SUM(F114:F116) -> 143668.05 | G117: =SUM(G114:G116) -> 101071.91 | H117: =SUM(H114:H116) -> 95892.15
B118: Accumulative | C118: (Nm3) | D118: =D117 -> 62099 | E118: =D118+E117 -> 119232 | F118: =E118+F117 -> 262900.05 | G118: =F118+G117 -> 363971.96 | H118: =G118+H117 -> 459864.11
B119: Target Gas based on Delivered Substrates | C119: (Nm3) | D119: =D36*101*0.7842 -> 88137.642 | E119: =E36*101*0.7842 -> 103088.23 | F119: =F36*101*0.7842 -> 124326.04 | G119: =G36*101*0.7842 -> 116410.37 | H119: =H36*101*0.7842 -> 75074.493
B120: Target to Reach SCA min | C120: (Nm3) | D120: =(($C$86/30)*5) -> 138888.89 | E120: =(($C$86/30)*12)-D118 -> 271234.33 | F120: =(($C$86/30)*19)-E118 -> 408545.78 | G120: =(($C$86/30)*26)-F118 -> 459322.17 | H120: =(($C$86/30)*30)-G118 -> 469361.37
B123: Percent Utilization of Substrates - Y3
B125: Considering Original Weight
D126: 101 | E126: Nm3/ton
...

Sheet Apr(Act)
B2: Substrate Supply - Y3
B4: Annual SCA Minimum | C4: 143000 | D4: (mtons)
B5: Running Monthly Minimum to meet SCA Guaranty | C5: =(C4-0)/12 -> 11916.667 | D5: (mtons)
B6: Delivered | C6: =SUM(D36:H36) -> 6401.78 | D6: (mtons)
B7: YTD total | C7: =C6 -> 6401.78 | D7: (mtons)
B8: Rejected | C8: =SUM(D38:G38) -> 0 | D8: (mtons)
D34: WEEK 1 (Apr1-5) | E34: WEEK 2 (Apr6-12) | F34: WEEK 3 (Apr13-19) | G34: WEEK 4 (Apr20-26) | H34: WEEk 5 (Apr27-30)
B36: Delivered (DPO) | C36: (mtons) | D36: 1112.79 | E36: 1301.55 | F36: 1569.69 | G36: 1469.75 | H36: 948
B37: Diverted
B39: Total Available | C39: (mtons) | D39: =D37+D36 -> 1112.79 | E39: =IF(E37+E36="",0,E37+E36) -> 1301.55 | F39: =F36 -> 1569.69 | G39: =G36 -> 1469.75 | H39: =H36 -> 948
B40: Monthly Accumulative | D40: =D39 -> 1112.79 | E40: =E39+D40 -> 2414.34 | F40: =F39+E40 -> 3984.03 | G40: =G39+F40 -> 5453.78 | H40: =H39+G40 -> 6401.78
B41: Target to Reach SCA Minimum | C41: (mtons) | D41: =(C5/30)*5 -> 1986.1111 | E41: =((C5/30)*12)-D40 -> 3653.8767 | F41: =((C5/30)*19)-E40 -> 5132.8822 | G41: =((C5/30)*26)-F40 -> 6343.7478 | H41: =((C5/30)*30)-G40 -> 6462.8867
B47: Power Generation - Y3
B49: Annual SCA Minimum | C49: 9907200 | D49: (kWh)
B50: Monthly SCA Minimum | C50: =(C49-0)/12 -> 825600 | D50: (kWh)
B51: Delivered | C51: =SUM(D78:H78) -> 532132 | D51: (kWh)
B52: YTD Total | C52: =C51 -> 532132 | D52: (kWh)
B53: Target to Reach SCA Minimum | C53: =C50-C51 -> 293468 | D53: (kWh)
E60: (kWh)
D77: =D34 -> WEEK 1 (Apr1-5) | E77: =E34 -> WEEK 2 (Apr6-12) | F77: =F34 -> WEEK 3 (Apr13-19) | G77: =G34 -> WEEK 4 (Apr20-26) | H77: =H34 -> WEEk 5 (Apr27-30)
B78: Delivered | C78: (kWh) | D78: 71832 | E78: 145087 | F78: 139215 | G78: 88653 | H78: 87345
B79: Accumulative | C79: (kWh) | D79: =D78 -> 71832 | E79: =D79+E78 -> 216919 | F79: =E79+F78 -> 356134 | G79: =F79+G78 -> 444787 | H79: =G79+H78 -> 532132
B80: Target to Reach SCA Minimum | C80: (kWh) | D80: =(C50/30)*5 -> 137600 | E80: =(($C50/30)*12)-D79 -> 258408 | F80: =(($C50/30)*19)-E79 -> 305961 | G80: =(($C50/30)*26)-F79 -> 359386 | H80: =(($C50/30)*30)-G79 -> 380813
B83: Biogas Utilization - Y3
B85: Annual SCA Minimum | C85: 10000000 | D85: (Nm3)
B86: Monthly SCA Minimum | C86: =(C85-0)/12 -> 833333.33 | D86: (Nm3)
B87: Delivered | C87: =SUM(D114:H114) -> 311714 | D87: (Nm3)
B88: YTD Total | C88: =C87 -> 311714 | D88: (Nm3)
B89: Target to Reach SCA Minimum | C89: =C86-C87 -> 521619.33 | D89: (Nm3)
D113: =D77 -> WEEK 1 (Apr1-5) | E113: =E77 -> WEEK 2 (Apr6-12) | F113: =F77 -> WEEK 3 (Apr13-19) | G113: =G77 -> WEEK 4 (Apr20-26) | H113: =H77 -> WEEk 5 (Apr27-30)
B114: Delivered to Boilers | C114: (Nm3) | D114: 62099 | E114: 57133 | F114: 78237 | G114: 59405 | H114: 54840
B115: Delivered to Engine | C115: (Nm3) | D115: =D78*0.47 -> 33761.04 | E115: =E78*0.47 -> 68190.89 | F115: =F78*0.47 -> 65431.05 | G115: =G78*0.47 -> 41666.91 | H115: =H78*0.47 -> 41052.15
B116: CO2 Testing | C116: (Nm3) | D116: 9758.69 | E116: 20204.64 | F116: 19915.86 | G116: 6315.23
B117: Flared | C117: (Nm3) | F117: 15492.2 | G117: 42086.2
B118: Total Produced | C118: (Nm3) | D118: =SUM(D114:D117) -> 105618.73 | E118: =SUM(E114:E117) -> 145528.53 | F118: =SUM(F114:F117) -> 179076.11 | G118: =SUM(G114:G117) -> 149473.34 | H118: =SUM(H114:H117) -> 95892.15
B119: Accumulative | C119: (Nm3) | D119: =D118 -> 105618.73 | E119: =D119+E118 -> 251147.26 | F119: =E119+F118 -> 430223.37 | G119: =F119+G118 -> 579696.71 | H119: =G119+H118 -> 675588.86
B120: Target Gas based on Delivered Substrates | C120: (Nm3) | D120: =D36*101*0.7842 -> 88137.642 | E120: =E36*101*0.7842 -> 103088.23 | F120: =F36*101*0.7842 -> 124326.04 | G120: =G36*101*0.7842 -> 116410.37 | H120: =H36*101*0.7842 -> 75085.582
B121: Target to Reach SCA min | C121: (Nm3) | D121: =(($C$86/30)*5) -> 138888.89 | E121: =(($C$86/30)*12)-D119 -> 227714.6 | F121: =(($C$86/30)*19)-E119 -> 276630.52 | G121: =(($C$86/30)*26)-F119 -> 291998.85 | H121: =(($C$86/30)*30)-G119 -> 253636.62
B124: Percent Utilization of Substrates - Y3
B126: Considering Original Weight
...

Sheet May
B2: Substrate Supply - Y3
B4: Annual SCA Minimum | C4: 143000 | D4: (mtons)
B5: Running Monthly Minimum to meet SCA Guaranty | C5: =(C4-'Apr(Act)'!C7)/11 -> 12418.02 | D5: (mtons)
B6: Delivered | C6: =SUM(D39:G39) -> 7584.68 | D6: (mtons)
B7: YTD total | C7: ='Apr(Act)'!C7+May!C6 -> 13986.46 | D7: (mtons)
B8: Rejected | C8: =SUM(D38:G38) -> 0 | D8: (mtons)
D34: WEEK 1 (May1-10) | E34: WEEK 2 (May11-17) | F34: WEEK 3 (May18-24) | G34: WEEK 4 (May25-31)
B36: Delivered (DPO) | C36: (mtons) | D36: 2578.79 | E36: 1821.93 | F36: 1602.63 | G36: 1581.33
B37: Diverted
B39: Total Available | C39: (mtons) | D39: =D37+D36 -> 2578.79 | E39: =IF(E37+E36="",0,E37+E36) -> 1821.93 | F39: =IF(F37+F36="",0,F37+F36) -> 1602.63 | G39: =IF(G37+G36="",0,G37+G36) -> 1581.33
B40: Monthly Accumulative | D40: =D39 -> 2578.79 | E40: =E39+D40 -> 4400.72 | F40: =F39+E40 -> 6003.35 | G40: =G39+F40 -> 7584.68
B41: Target to Reach SCA Minimum | C41: (mtons) | D41: =(C5/31)*10 -> 4005.8129 | E41: =((C5/31)*17)-D40 -> 4231.0919 | F41: =((C5/31)*24)-E40 -> 5213.231 | G41: =((C5/31)*31)-F40 -> 6414.67
B47: Power Generation - Y3
B49: Annual SCA Minimum | C49: 9907200 | D49: (kWh)
B50: Monthly SCA Minimum | C50: =(C49-'Apr(Act)'!C52)/11 -> 852278.91 | D50: (kWh)
B51: Delivered | C51: =SUM(D78:G78) -> 529726 | D51: (kWh)
B52: YTD Total | C52: ='Apr(Act)'!C52+C51 -> 1061858 | D52: (kWh)
B53: Target to Reach SCA Minimum | C53: =C50-C51 -> 322552.91 | D53: (kWh)
E60: (kWh)
D77: =D34 -> WEEK 1 (May1-10) | E77: =E34 -> WEEK 2 (May11-17) | F77: =F34 -> WEEK 3 (May18-24) | G77: =G34 -> WEEK 4 (May25-31)
B78: Delivered | C78: (kWh) | D78: 160262 | E78: 142232 | F78: 148272 | G78: 78960
B79: Accumulative | C79: (kWh) | D79: =D78 -> 160262 | E79: =D79+E78 -> 302494 | F79: =E79+F78 -> 450766 | G79: =F79+G78 -> 529726
B80: Target to Reach SCA Minimum | C80: (kWh) | D80: =(C50/31)*10 -> 274928.68 | E80: =(($C50/31)*17)-D79 -> 307116.76 | F80: =(($C50/31)*24)-E79 -> 357334.83 | G80: =(($C50/31)*31)-F79 -> 401512.91
B83: Biogas Utilization - Y3
B85: Annual SCA Minimum | C85: 10000000 | D85: (Nm3)
B86: Monthly SCA Minimum | C86: =(C85-'Apr(Act)'!C88)/11 -> 880753.27 | D86: (Nm3)
B87: Delivered | C87: =SUM(D114:G114) -> 540137 | D87: (Nm3)
B88: YTD Total | C88: ='Apr(Act)'!C88+C87 -> 851851 | D88: (Nm3)
B89: Target to Reach SCA Minimum | C89: =C86-C87 -> 340616.27 | D89: (Nm3)
D113: =D77 -> WEEK 1 (May1-10) | E113: =E77 -> WEEK 2 (May11-17) | F113: =F77 -> WEEK 3 (May18-24) | G113: =G77 -> WEEK 4 (May25-31)
B114: Delivered to Boilers | C114: (Nm3) | D114: 192085 | E114: 122065 | F114: 91943 | G114: 134044
B115: Delivered to Engine | C115: (Nm3) | D115: =D78*0.47 -> 75323.14 | E115: =E78*0.47 -> 66849.04 | F115: =F78*0.47 -> 69687.84 | G115: =G78*0.47 -> 37111.2
B116: CO2 Testing | C116: (Nm3)
B117: Flared | C117: (Nm3) | D117: 5144 | G117: 30159
B118: Total Produced | C118: (Nm3) | D118: =SUM(D114:D117) -> 272552.14 | E118: =SUM(E114:E117) -> 188914.04 | F118: =SUM(F114:F117) -> 161630.84 | G118: =SUM(G114:G117) -> 201314.2
B119: Accumulative | C119: (Nm3) | D119: =D114 -> 192085 | E119: =D119+E114 -> 314150 | F119: =E119+F114 -> 406093 | G119: =F119+G114 -> 540137
B120: Target Gas based on Delivered Substrates | C120: (Nm3) | D120: =D36*101*0.7842 -> 204251 | E120: =E36*101*0.7842 -> 144304.51 | F120: =F36*101*0.7842 -> 126935.03 | G120: =G36*101*0.7842 -> 125247.98
B121: Target to Reach SCA min | C121: (Nm3) | D121: =(($C$86/31)*10) -> 284113.96 | E121: =(($C$86/31)*17)-D119 -> 290908.73 | F121: =(($C$86/31)*24)-E119 -> 367723.5 | G121: =(($C$86/31)*31)-F119 -> 474660.27
B124: Percent Utilization of Substrates - Y3
B126: Considering Original Weight
...

Sheet Jun
B2: Substrate Supply - Y3
B4: Annual SCA Minimum | C4: 143000 | D4: (mtons)
B5: Running Monthly Minimum to meet SCA Guaranty | C5: =(C4-May!C7)/10 -> 12901.354 | D5: (mtons)
B6: Delivered | C6: =SUM(D39:G39) -> 6994.14 | D6: (mtons)
B7: YTD total | C7: =May!C7+Jun!C6 -> 20980.6 | D7: (mtons)
B8: Rejected | C8: =SUM(D38:G38) -> 0 | D8: (mtons)
D34: WEEK 1 (Jun1-7) | E34: WEEK 2 (Jun8-14) | F34: WEEK 3 (Jun15-21) | G34: WEEK 4 (June22-30)
B36: Delivered (DPO) | C36: (mtons) | D36: 1800.43 | E36: 2016.87 | F36: 1621.82 | G36: 1460.96
B37: Diverted (Surallah) | F37: 94.06
B39: Total Available | C39: (mtons) | D39: =D37+D36 -> 1800.43 | E39: =IF(E37+E36="",0,E37+E36) -> 2016.87 | F39: =IF(F37+F36="",0,F37+F36) -> 1715.88 | G39: =IF(G37+G36="",0,G37+G36) -> 1460.96
B40: Monthly Accumulative | D40: =D39 -> 1800.43 | E40: =E39+D40 -> 3817.3 | F40: =F39+E40 -> 5533.18 | G40: =G39+F40 -> 6994.14
B41: Target to Reach SCA Minimum | C41: (mtons) | D41: =(C5/30)*7 -> 3010.3159 | E41: =((C5/30)*14)-D40 -> 4220.2019 | F41: =((C5/30)*21)-E40 -> 5213.6478 | G41: =((C5/30)*30)-F40 -> 7368.174
B47: Power Generation - Y3
B49: Annual SCA Minimum | C49: 9907200 | D49: (kWh)
B50: Monthly SCA Minimum | C50: =(C49-May!C52)/10 -> 884534.2 | D50: (kWh)
B51: Delivered | C51: =SUM(D78:G78) -> 652382 | D51: (kWh)
B52: YTD Total | C52: =May!C52+Jun!C51 -> 1714240 | D52: (kWh)
B53: Target to Reach SCA Minimum | C53: =C50-C51 -> 232152.2 | D53: (kWh)
E60: (kWh)
D77: =D34 -> WEEK 1 (Jun1-7) | E77: =E34 -> WEEK 2 (Jun8-14) | F77: =F34 -> WEEK 3 (Jun15-21) | G77: =G34 -> WEEK 4 (June22-30)
B78: Delivered | C78: (kWh) | D78: 160822 | E78: 169164 | F78: 173171 | G78: 149225
B79: Accumulative | C79: (kWh) | D79: =D78 -> 160822 | E79: =D79+E78 -> 329986 | F79: =E79+F78 -> 503157 | G79: =F79+G78 -> 652382
B80: Target to Reach SCA Minimum | C80: (kWh) | D80: =(C50/30)*7 -> 206391.31 | E80: =(($C50/30)*14)-D79 -> 251960.63 | F80: =(($C50/30)*21)-E79 -> 289187.94 | G80: =(($C50/30)*30)-F79 -> 381377.2
B83: Biogas Utilization - Y3
B85: Annual SCA Minimum | C85: 10000000 | D85: (Nm3)
B86: Monthly SCA Minimum | C86: =(C85-May!C88)/10 -> 914814.9 | D86: (Nm3)
B87: Delivered | C87: =SUM(D114:G114) -> 459563 | D87: (Nm3)
B88: YTD Total | C88: =May!C88+Jun!C87 -> 1311414 | D88: (Nm3)
B89: Target to Reach SCA Minimum | C89: =C86-C87 -> 455251.9 | D89: (Nm3)
D113: =D77 -> WEEK 1 (Jun1-7) | E113: =E77 -> WEEK 2 (Jun8-14) | F113: =F77 -> WEEK 3 (Jun15-21) | G113: =G77 -> WEEK 4 (June22-30)
B114: Delivered to Boilers | C114: (Nm3) | D114: 124400 | E114: 126024 | F114: 107468 | G114: 101671
B115: Delivered to Engine | C115: (Nm3) | D115: =D78*0.47 -> 75586.34 | E115: =E78*0.47 -> 79507.08 | F115: =F78*0.47 -> 81390.37 | G115: =G78*0.47 -> 70135.75
B116: CO2 Testing | C116: (Nm3)
B117: Flared | C117: (Nm3) | F117: 9023 | G117: 3014
B118: Total Produced | C118: (Nm3) | D118: =SUM(D114:D117) -> 199986.34 | E118: =SUM(E114:E117) -> 205531.08 | F118: =SUM(F114:F117) -> 197881.37 | G118: =SUM(G114:G117) -> 174820.75
B119: Accumulative | C119: (Nm3) | D119: =D114 -> 124400 | E119: =D119+E114 -> 250424 | F119: =E119+F114 -> 357892 | G119: =F119+G114 -> 459563
B120: Target Gas based on Delivered Substrates | C120: (Nm3) | D120: =D36*101*0.7842 -> 142601.62 | E120: =E36*101*0.7842 -> 159744.57 | F120: =F36*101*0.7842 -> 128454.96 | G120: =G36*101*0.7842 -> 115714.17
B121: Target to Reach SCA min | C121: (Nm3) | D121: =(($C$86/30)*7) -> 213456.81 | E121: =(($C$86/30)*14)-D119 -> 302513.62 | F121: =(($C$86/30)*21)-E119 -> 389946.43 | G121: =(($C$86/30)*30)-F119 -> 556922.9
B124: Percent Utilization of Substrates - Y3
B126: Considering Original Weight
...

Sheet Jul
B2: Substrate Supply - Y3
B4: Annual SCA Minimum | C4: 143000 | D4: (mtons)
B5: Running Monthly Minimum to meet SCA Guaranty | C5: =(C4-Jun!C7)/9 -> 13557.711 | D5: (mtons)
B6: Delivered | C6: =SUM(D39:H39) -> 6552.41 | D6: (mtons)
B7: YTD total | C7: =Jun!C7+Jul!C6 -> 27533.01 | D7: (mtons)
B8: Rejected | C8: =SUM(D38:G38) -> 0 | D8: (mtons)
D34: WEEK 1 (Jul1-5) | E34: WEEK 2 (Jul6-12) | F34: WEEK 3 (Jul13-19) | G34: WEEK 4 (Jul20-26) | H34: WEEK 5 (Jul27-31)
B36: Delivered (DPO) | C36: (mtons) | D36: 942.07 | E36: 2020.91 | F36: 1376.38 | G36: 1366.86 | H36: 846.19
B37: Diverted
B39: Total Available | C39: (mtons) | D39: =D37+D36 -> 942.07 | E39: =IF(E37+E36="",0,E37+E36) -> 2020.91 | F39: =IF(F37+F36="",0,F37+F36) -> 1376.38 | G39: =IF(G37+G36="",0,G37+G36) -> 1366.86 | H39: =IF(H37+H36="",0,H37+H36) -> 846.19
B40: Monthly Accumulative | D40: =D39 -> 942.07 | E40: =E39+D40 -> 2962.98 | F40: =F39+E40 -> 4339.36 | G40: =G39+F40 -> 5706.22 | H40: =H39+G40 -> 6552.41
B41: Target to Reach SCA Minimum | C41: (mtons) | D41: =(C5/31)*5 -> 2186.7276 | E41: =((C5/31)*12)-D40 -> 4306.0762 | F41: =((C5/31)*19)-E40 -> 5346.5849 | G41: =((C5/31)*26)-F40 -> 7031.6235 | H41: =((C5/31)*31)-G40 -> 7851.4911
B47: Power Generation - Y3
B49: Annual SCA Minimum | C49: 9907200 | D49: (kWh)
B50: Monthly SCA Minimum | C50: =(C49-Jun!C52)/9 -> 910328.89 | D50: (kWh)
B51: Delivered | C51: =SUM(D78:H78) -> 343289 | D51: (kWh)
B52: YTD Total | C52: =Jun!C52+Jul!C51 -> 2057529 | D52: (kWh)
B53: Target to Reach SCA Minimum | C53: =C50-C51 -> 567039.89 | D53: (kWh)
E60: (kWh)
D77: =D34 -> WEEK 1 (Jul1-5) | E77: =E34 -> WEEK 2 (Jul6-12) | F77: =F34 -> WEEK 3 (Jul13-19) | G77: =G34 -> WEEK 4 (Jul20-26) | H77: =H34 -> WEEK 5 (Jul27-31)
B78: Delivered | C78: (kWh) | D78: 31902 | E78: 36711 | F78: 91966 | G78: 97886 | H78: 84824
B79: Accumulative | C79: (kWh) | D79: =D78 -> 31902 | E79: =D79+E78 -> 68613 | F79: =E79+F78 -> 160579 | G79: =F79+G78 -> 258465 | H79: =G79+H78 -> 343289
B80: Target to Reach SCA Minimum | C80: (kWh) | D80: =(C50/31)*5 -> 146827.24 | E80: =(($C50/31)*12)-D79 -> 320483.38 | F80: =(($C50/31)*19)-E79 -> 489330.51 | G80: =(($C50/31)*26)-F79 -> 602922.65 | H80: =(($C50/31)*31)-G79 -> 651863.89
B83: Biogas Utilization - Y3
B85: Annual SCA Minimum | C85: 10000000 | D85: (Nm3)
B86: Monthly SCA Minimum | C86: =(C85-May!C88)/10 -> 914814.9 | D86: (Nm3)
B87: Delivered | C87: =SUM(D114:H114) -> 423485 | D87: (Nm3)
B88: YTD Total | C88: =Jun!C88+Jul!C87 -> 1734899 | D88: (Nm3)
B89: Target to Reach SCA Minimum | C89: =C86-C87 -> 491329.9 | D89: (Nm3)
D113: =D77 -> WEEK 1 (Jul1-5) | E113: =E77 -> WEEK 2 (Jul6-12) | F113: =F77 -> WEEK 3 (Jul13-19) | G113: =G77 -> WEEK 4 (Jul20-26) | H113: =H77 -> WEEK 5 (Jul27-31)
B114: Delivered to Boilers | C114: (Nm3) | D114: 58901 | E114: 147832 | F114: 108594 | G114: 78273 | H114: 29885
B115: Delivered to Engine | C115: (Nm3) | D115: =D78*0.47 -> 14993.94 | E115: =E78*0.47 -> 17254.17 | F115: =F78*0.47 -> 43224.02 | G115: =G78*0.47 -> 46006.42 | H115: =H78*0.47 -> 39867.28
B116: CO2 Testing | C116: (Nm3)
B117: Flared | C117: (Nm3) | E117: =1216+1221+1155+1124+1144 -> 5860 | H117: 1444
B118: Total Produced | C118: (Nm3) | D118: =SUM(D114:D117) -> 73894.94 | E118: =SUM(E114:E117) -> 170946.17 | F118: =SUM(F114:F117) -> 151818.02 | G118: =SUM(G114:G117) -> 124279.42 | H118: =SUM(H114:H117) -> 71196.28
B119: Accumulative | C119: (Nm3) | D119: =D114 -> 58901 | E119: =D119+E114 -> 206733 | F119: =E119+F114 -> 315327 | G119: =F119+G114 -> 393600 | H119: =G119+H114 -> 423485
B120: Target Gas based on Delivered Substrates | C120: (Nm3) | D120: =D36*101*0.7842 -> 74615.901 | E120: =E36*101*0.7842 -> 160064.56 | F120: =F36*101*0.7842 -> 109015.08 | G120: =G36*101*0.7842 -> 108261.05 | H120: =H36*101*0.7842 -> 67021.802
B121: Target to Reach SCA min | C121: (Nm3) | D121: =(($C$86/31)*5) -> 147550.79 | E121: =(($C$86/31)*12)-D119 -> 295220.9 | F121: =(($C$86/31)*19)-E119 -> 353960 | G121: =(($C$86/31)*26)-F119 -> 451937.11 | H121: =(($C$86/31)*31)-G119 -> 521214.9
B124: Percent Utilization of Substrates - Y3
B126: Considering Original Weight
...

Sheet Aug
B2: Substrate Supply - Y3
B4: Annual SCA Minimum | C4: 143000 | D4: (mtons)
B5: Running Monthly Minimum to meet SCA Guaranty | C5: =(C4-Jul!C7)/8 -> 14433.374 | D5: (mtons)
B6: Delivered | C6: =SUM(D39:G39) -> 7594.33 | D6: (mtons)
B7: YTD total | C7: =Jul!C7+Aug!C6 -> 35127.34 | D7: (mtons)
B8: Rejected | C8: =SUM(D38:G38) -> 0 | D8: (mtons)
D34: WEEK 1 (Aug1-9) | E34: WEEK 2 (Aug10-16) | F34: WEEK 3 (Aug17-23) | G34: WEEK 4 (Aug24-31)
B36: Delivered (DPO) | C36: (mtons) | D36: 2217.01 | E36: 1745.6 | F36: 1794.13 | G36: 1837.59
B37: Diverted
B39: Total Available | C39: (mtons) | D39: =D37+D36 -> 2217.01 | E39: =IF(E37+E36="",0,E37+E36) -> 1745.6 | F39: =IF(F37+F36="",0,F37+F36) -> 1794.13 | G39: =IF(G37+G36="",0,G37+G36) -> 1837.59
B40: Monthly Accumulative | D40: =D39 -> 2217.01 | E40: =E39+D40 -> 3962.61 | F40: =F39+E40 -> 5756.74 | G40: =G39+F40 -> 7594.33
B41: Target to Reach SCA Minimum | C41: (mtons) | D41: =(C5/31)*9 -> 4190.3343 | E41: =((C5/31)*16)-D40 -> 5232.4732 | F41: =((C5/31)*23)-E40 -> 6746.0221 | G41: =((C5/31)*31)-F40 -> 8676.6337
B47: Power Generation - Y3
B49: Annual SCA Minimum | C49: 9907200 | D49: (kWh)
B50: Monthly SCA Minimum | C50: =(C49-Jul!C52)/8 -> 981208.88 | D50: (kWh)
B51: Delivered | C51: =SUM(D78:G78) -> 401543 | D51: (kWh)
B52: YTD Total | C52: =Jul!C52+Aug!C51 -> 2459072 | D52: (kWh)
B53: Target to Reach SCA Minimum | C53: =C50-C51 -> 579665.88 | D53: (kWh)
E60: (kWh)
D77: =D34 -> WEEK 1 (Aug1-9) | E77: =E34 -> WEEK 2 (Aug10-16) | F77: =F34 -> WEEK 3 (Aug17-23) | G77: =G34 -> WEEK 4 (Aug24-31)
B78: Delivered | C78: (kWh) | D78: 62417 | E78: 137693 | F78: 61750 | G78: 139683
B79: Accumulative | C79: (kWh) | D79: =D78 -> 62417 | E79: =D79+E78 -> 200110 | F79: =E79+F78 -> 261860 | G79: =F79+G78 -> 401543
B80: Target to Reach SCA Minimum | C80: (kWh) | D80: =(C50/31)*9 -> 284867.09 | E80: =(($C50/31)*16)-D79 -> 444013.39 | F80: =(($C50/31)*23)-E79 -> 527883.68 | G80: =(($C50/31)*31)-F79 -> 719348.88
B83: Biogas Utilization - Y3
B85: Annual SCA Minimum | C85: 10000000 | D85: (Nm3)
B86: Monthly SCA Minimum | C86: =(C85-Jul!C88)/8 -> 1033137.6 | D86: (Nm3)
B87: Delivered | C87: =SUM(D114:G114) -> 503878 | D87: (Nm3)
B88: YTD Total | C88: =Jul!C88+Aug!C87 -> 2238777 | D88: (Nm3)
B89: Target to Reach SCA Minimum | C89: =C86-C87 -> 529259.62 | D89: (Nm3)
D113: =D77 -> WEEK 1 (Aug1-9) | E113: =E77 -> WEEK 2 (Aug10-16) | F113: =F77 -> WEEK 3 (Aug17-23) | G113: =G77 -> WEEK 4 (Aug24-31)
B114: Delivered to Boilers | C114: (Nm3) | D114: 138448 | E114: 128514 | F114: 124782 | G114: 112134
B115: Delivered to Engine | C115: (Nm3) | D115: =D78*0.47 -> 29335.99 | E115: =E78*0.47 -> 64715.71 | F115: =F78*0.47 -> 29022.5 | G115: =G78*0.47 -> 65651.01
B116: CO2 Testing | C116: (Nm3)
B117: Flared | C117: (Nm3) | D117: 20724 | F117: 18468 | G117: 18535
B118: Total Produced | C118: (Nm3) | D118: =SUM(D114:D117) -> 188507.99 | E118: =SUM(E114:E117) -> 193229.71 | F118: =SUM(F114:F117) -> 172272.5 | G118: =SUM(G114:G117) -> 196320.01
B119: Accumulative | C119: (Nm3) | D119: =D114 -> 138448 | E119: =D119+E114 -> 266962 | F119: =E119+F114 -> 391744 | G119: =F119+G114 -> 503878
B120: Target Gas based on Delivered Substrates | C120: (Nm3) | D120: =D36*101*0.7842 -> 175596.5 | E120: =E36*101*0.7842 -> 138258.85 | F120: =F36*101*0.7842 -> 142102.63 | G120: =G36*101*0.7842 -> 145544.85
B121: Target to Reach SCA min | C121: (Nm3) | D121: =(($C$86/31)*9) -> 299943.18 | E121: =(($C$86/31)*16)-D119 -> 394784.32 | F121: =(($C$86/31)*23)-E119 -> 499559.46 | G121: =(($C$86/31)*31)-F119 -> 641393.63
B124: Percent Utilization of Substrates - Y3
B126: Considering Original Weight
...

Sheet Sep
B2: Substrate Supply - Y3
B4: Annual SCA Minimum | C4: 143000 | D4: (mtons)
B5: Running Monthly Minimum to meet SCA Guaranty | C5: =(C4-Aug!C7)/7 -> 15410.38 | D5: (mtons)
B6: Delivered | C6: =SUM(D39:G39) -> 6634.4 | D6: (mtons)
B7: YTD total | C7: =Aug!C7+Sep!C6 -> 41761.74 | D7: (mtons)
B8: Rejected | C8: =SUM(D38:G38) -> 0 | D8: (mtons)
D34: WEEK 1 (Sep1-6) | E34: WEEK 2 (Sep7-13) | F34: WEEK 3 (Sep14-20) | G34: WEEK 4 (Sep21-30)
B36: Delivered (DPO) | C36: (mtons) | D36: 1725.57 | E36: 1454.34 | F36: 1239.49 | G36: 2215
B37: Diverted
B39: Total Available | C39: (mtons) | D39: =D37+D36 -> 1725.57 | E39: =IF(E37+E36="",0,E37+E36) -> 1454.34 | F39: =IF(F37+F36="",0,F37+F36) -> 1239.49 | G39: =IF(G37+G36="",0,G37+G36) -> 2215
B40: Monthly Accumulative | D40: =D39 -> 1725.57 | E40: =E39+D40 -> 3179.91 | F40: =F39+E40 -> 4419.4 | G40: =G39+F40 -> 6634.4
B41: Target to Reach SCA Minimum | C41: (mtons) | D41: =(C5/30)*6 -> 3082.076 | E41: =((C5/30)*13)-D40 -> 4952.2613 | F41: =((C5/30)*20)-E40 -> 7093.6767 | G41: =((C5/30)*30)-F40 -> 10990.98
B47: Power Generation - Y3
B49: Annual SCA Minimum | C49: 9907200 | D49: (kWh)
B50: Monthly SCA Minimum | C50: =(C49-Aug!C52)/7 -> 1064018.3 | D50: (kWh)
B51: Delivered | C51: =SUM(D78:G78) -> 300717 | D51: (kWh)
B52: YTD Total | C52: =Aug!C52+Sep!C51 -> 2759789 | D52: (kWh)
B53: Target to Reach SCA Minimum | C53: =C50-C51 -> 763301.29 | D53: (kWh)
E60: (kWh)
D77: =D34 -> WEEK 1 (Sep1-6) | E77: =E34 -> WEEK 2 (Sep7-13) | F77: =F34 -> WEEK 3 (Sep14-20) | G77: =G34 -> WEEK 4 (Sep21-30)
B78: Delivered | C78: (kWh) | D78: 129032 | E78: 63165 | F78: 45299 | G78: 63221
B79: Accumulative | C79: (kWh) | D79: =D78 -> 129032 | E79: =D79+E78 -> 192197 | F79: =E79+F78 -> 237496 | G79: =F79+G78 -> 300717
B80: Target to Reach SCA Minimum | C80: (kWh) | D80: =(C50/30)*6 -> 212803.66 | E80: =(($C50/30)*13)-D79 -> 332042.59 | F80: =(($C50/30)*20)-E79 -> 517148.52 | G80: =(($C50/31)*31)-F79 -> 826522.29
B83: Biogas Utilization - Y3
B85: Annual SCA Minimum | C85: 10000000 | D85: (Nm3)
B86: Monthly SCA Minimum | C86: =(C85-Aug!C88)/7 -> 1108746.1 | D86: (Nm3)
B87: Delivered | C87: =SUM(D114:G114) -> 473052 | D87: (Nm3)
B88: YTD Total | C88: =Aug!C88+Sep!C87 -> 2711829 | D88: (Nm3)
B89: Target to Reach SCA Minimum | C89: =C86-C87 -> 635694.14 | D89: (Nm3)
D113: =D77 -> WEEK 1 (Sep1-6) | E113: =E77 -> WEEK 2 (Sep7-13) | F113: =F77 -> WEEK 3 (Sep14-20) | G113: =G77 -> WEEK 4 (Sep21-30)
B114: Delivered to Boilers | C114: (Nm3) | D114: 95184 | E114: 99875 | F114: 83860 | G114: 194133
B115: Delivered to Engine | C115: (kWh) | D115: =D78*0.47 -> 60645.04 | E115: =E78*0.47 -> 29687.55 | F115: =F78*0.47 -> 21290.53 | G115: =G78*0.47 -> 29713.87
B116: CO2 Operation | C116: (Nm3)
B117: Flared | C117: (Nm3) | D117: 16696 | E117: 14168 | F117: 5084 | G117: 13784
B118: Total Produced | C118: (Nm3) | D118: =SUM(D114:D117) -> 172525.04 | E118: =SUM(E114:E117) -> 143730.55 | F118: =SUM(F114:F117) -> 110234.53 | G118: =SUM(G114:G117) -> 237630.87
B119: Accumulative | C119: (Nm3) | D119: =D114 -> 95184 | E119: =D119+E114 -> 195059 | F119: =E119+F114 -> 278919 | G119: =F119+G114 -> 473052
B120: Target Gas based on Delivered Substrates | C120: (Nm3) | D120: =D36*101*0.7842 -> 136672.39 | E120: =E36*101*0.7842 -> 115189.84 | F120: =F36*101*0.7842 -> 98172.814 | G120: =G36*101*0.7842 -> 175437.3
B121: Target to Reach SCA (Boiler) | C121: (Nm3) | D121: =(($C$86/31)*9) -> 321894.04 | E121: =(($C$86/31)*16)-D119 -> 477072.07 | F121: =(($C$86/31)*23)-E119 -> 627559.11 | G121: =(($C$86/31)*31)-F119 -> 829827.14
B124: Percent Utilization of Substrates - Y3
B126: Considering Original Weight
...

Sheet Oct
B2: Substrate Supply - Y3
B4: Annual SCA Minimum | C4: 143000 | D4: (mtons) | E4: Fixed based on contract - Contract year starts April
B5: Monthly SCA Minimum | C5: =(C4-Sep!C7)/6 -> 16873.043 | D5: (mtons) | E5: Pro-rated based on actual substrates received
B6: Delivered | C6: =SUM(D39:H39) -> 5988.87 | D6: (mtons) | E6: Total monthly substrates received
B7: YTD total | C7: =Sep!C7+Oct!C6 -> 47750.61 | D7: (mtons) | E7: YTD substrtaes received from April
B8: Rejected | C8: =SUM(D38:G38) -> 0 | D8: (mtons) | E8: Total monthly substrates rejected
D33: Weekly Data from DPO Substrates Reconciliation
D34: WEEK 1 (Oct1-4) | E34: WEEK 2 (Oct5-11) | F34: WEEK 3 (Oct12-18) | G34: WEEK 4 (Oct19-25) | H34: WEEK 5 (Oct26-31)
B36: Delivered (DPO) | C36: (mtons) | D36: 1038.26 | E36: 1866.1 | F36: 905.65 | G36: 757.79 | H36: 1421.07
B37: Diverted
B39: Total Available | C39: (mtons) | D39: =D37+D36 -> 1038.26 | E39: =IF(E37+E36="",0,E37+E36) -> 1866.1 | F39: =IF(F37+F36="",0,F37+F36) -> 905.65 | G39: =IF(G37+G36="",0,G37+G36) -> 757.79 | H39: =IF(H37+H36="",0,H37+H36) -> 1421.07
B40: Monthly Accumulative | D40: =D39 -> 1038.26 | E40: =E39+D40 -> 2904.36 | F40: =F39+E40 -> 3810.01 | G40: =G39+F40 -> 4567.8 | H40: =H39+G40 -> 5988.87
B41: Target to Reach SCA Minimum | C41: (mtons) | D41: =(C5/31)*4 -> 2177.1669 | E41: =((C5/31)*11)-D40 -> 4948.9489 | F41: =((C5/31)*18)-E40 -> 6892.891 | G41: =((C5/31)*25)-F40 -> 9797.283 | H41: =((C5/31)*31)-G40 -> 12305.243
B47: Power Generation - Y3
B49: Annual SCA Minimum | C49: 9907200 | D49: (kWh) | E49: Fixed based on contract - CY starts April
B50: Monthly SCA Minimum | C50: =(C49-Sep!C52)/6 -> 1191235.2 | D50: (kWh) | E50: Pro-rated based on actual power delivered - Engine
B51: Delivered | C51: =SUM(D78:H78) -> 205404 | D51: (kWh) | E51: Total monthly power delivered
B52: YTD Total | C52: =Sep!C52+Oct!C51 -> 2965193 | D52: (kWh) | E52: YTD power delivered from April
B53: Target to Reach SCA Minimum | C53: =C50-C51 -> 985831.17 | D53: (kWh)
E60: (kWh)
D76: Weekly Data from Joint Monitoring - Gas Engine
D77: =D34 -> WEEK 1 (Oct1-4) | E77: =E34 -> WEEK 2 (Oct5-11) | F77: =F34 -> WEEK 3 (Oct12-18) | G77: =G34 -> WEEK 4 (Oct19-25) | H77: =H34 -> WEEK 5 (Oct26-31)
B78: Delivered | C78: (kWh) | E78: 54510 | F78: 66186 | G78: 5147 | H78: 79561
B79: Accumulative | C79: (kWh) | D79: =D78 -> 0 | E79: =D79+E78 -> 54510 | F79: =E79+F78 -> 120696 | G79: =F79+G78 -> 125843 | H79: =G79+H78 -> 205404
B80: Target to Reach SCA Minimum | C80: (kWh) | D80: =(C50/31)*4 -> 153707.76 | E80: =(($C50/31)*11)-D79 -> 422696.35 | F80: =(($C50/31)*18)-E79 -> 637174.94 | G80: =(($C50/31)*25)-F79 -> 839977.52 | H80: =(($C50/31)*31)-G79 -> 1065392.2
B83: Biogas Utilization - Y3
B85: Annual SCA Minimum | C85: 10000000 | D85: (Nm3) | E85: Fixed based on contract - CY starts April
B86: Monthly SCA Minimum | C86: =(C85-Sep!C88)/6 -> 1214695.2 | D86: (Nm3) | E86: Pro-rated based on actual biogas delivered - Thermax Boiler
B87: Delivered | C87: =SUM(D114:H114) -> 451214 | D87: (Nm3) | E87: Total monthly biogas delivered to boiler
B88: YTD Total | C88: =Sep!C88+Oct!C87 -> 3163043 | D88: (Nm3) | E88: YTD power delivered from April
B89: Target to Reach SCA Minimum | C89: =C86-C87 -> 763481.17 | D89: (Nm3)
D112: Weekly Data from Joint Monitoring - Boiler
D113: =D77 -> WEEK 1 (Oct1-4) | E113: =E77 -> WEEK 2 (Oct5-11) | F113: =F77 -> WEEK 3 (Oct12-18) | G113: =G77 -> WEEK 4 (Oct19-25) | H113: =H77 -> WEEK 5 (Oct26-31)
B114: Delivered to Boilers | C114: (Nm3) | D114: 77966 | E114: 116791 | F114: 21893 | G114: 93475 | H114: 141089
B115: Delivered to Engine | C115: (kWh) | D115: =D78*0.47 -> 0 | E115: =E78*0.47 -> 25619.7 | F115: =F78*0.47 -> 31107.42 | G115: =G78*0.47 -> 2419.09 | H115: =H78*0.47 -> 37393.67
B116: CO2 Operation | C116: (Nm3)
B117: Flared | C117: (Nm3) | E117: 13978 | F117: 36093 | H117: 2102
B118: Total Produced | C118: (Nm3) | D118: =SUM(D114:D117) -> 77966 | E118: =SUM(E114:E117) -> 156388.7 | F118: =SUM(F114:F117) -> 89093.42 | G118: =SUM(G114:G117) -> 95894.09 | H118: =SUM(H114:H117) -> 180584.67
B119: Accumulative | C119: (Nm3) | D119: =D114 -> 77966 | E119: =D119+E114 -> 194757 | F119: =E119+F114 -> 216650 | G119: =F119+G114 -> 310125 | H119: =G119+H114 -> 451214
B120: Target Gas based on Delivered Substrates | C120: (Nm3) | D120: =D36*101*0.7842 -> 82234.553 | E120: =E36*101*0.7842 -> 147802.96 | F120: =F36*101*0.7842 -> 71731.284 | G120: =G36*101*0.7842 -> 60020.151 | H120: =H36*101*0.7842 -> 112554.71
...

Sheet CY Yield
A3: Date | B3: Substrates (MT) | C3: Boiler Gas (Nm3) | D3: Power (kwH) | E3: SCA Gas Equivalent (Nm3) | F3: Actual Gas Produced (Nm3) | G3: Actual Yield (Monthly) | H3: YTD 2025 | I3: YTD CY4 | J3: Target Yield
A4: 45658 | B4: 9576.07 | C4: 776566 | D4: 571505 | E4: =B4*101 -> 967183.07 | F4: =C4+D4*0.476 -> 1048602.4 | G4: =F4/B4 -> 109.50237 | H4: =F4/B4 -> 109.50237 | J4: 101
A5: 45689 | B5: 6871.509 | C5: 539519 | D5: 562283 | E5: =B5*101 -> 694022.41 | F5: =C5+D5*0.476 -> 807165.71 | G5: =F5/B5 -> 117.46557 | H5: =SUM(F4:F5)/SUM(B4:B5) -> 112.82926 | J5: 101
A6: 45717 | B6: 6299.76 | C6: 437511 | D6: 558481 | E6: =B6*101 -> 636275.76 | F6: =C6+D6*0.476 -> 703347.96 | G6: =F6/B6 -> 111.64679 | H6: =SUM(F4:F6)/SUM(B4:B6) -> 112.50178 | J6: 101
A7: 45748 | B7: 6310.902 | C7: 307449 | D7: 532132 | E7: =B7*101 -> 637401.1 | F7: =C7+D7*0.476 -> 560743.83 | G7: =F7/B7 -> 88.853199 | H7: =SUM(F4:F7)/SUM(B4:B7) -> 107.36575 | I7: =F7/B7 -> 88.853199 | J7: 101
A8: 45778 | B8: 7538.234 | C8: 517346 | D8: 529726 | E8: =B8*101 -> 761361.63 | F8: =C8+D8*0.476 -> 769495.58 | G8: =F8/B8 -> 102.07902 | H8: =SUM(F4:F8)/SUM(B4:B8) -> 106.27678 | I8: =SUM(F7:F8)/SUM(B7:B8) -> 96.052159 | J8: 101
A9: 45809 | B9: 6935.708 | C9: 471600 | D9: 652382 | E9: =B9*101 -> 700506.51 | F9: =C9+D9*0.476 -> 782133.83 | G9: =F9/B9 -> 112.76914 | H9: =SUM(F4:F9)/SUM(B4:B9) -> 107.31117 | I9: =SUM(F7:F9)/SUM(B7:B9) -> 101.63046 | J9: 101
A10: 45839 | B10: 6530.53 | C10: 424929 | D10: 333360 | E10: =B10*101 -> 659583.53 | F10: =C10+D10*0.476 -> 583608.36 | G10: =F10/B10 -> 89.366156 | H10: =SUM(F4:F10)/SUM(B4:B10) -> 104.97029 | I10: =SUM(F7:F10)/SUM(B7:B10) -> 98.698323 | J10: 101
A11: 45870 | B11: =Aug!C6 -> 7594.33 | C11: =Aug!C87+SUM(Aug!$D$117:$G$117) -> 561605 | D11: =Aug!C51 -> 401543 | E11: =B11*101 -> 767027.33 | F11: =C11+D11*0.476 -> 752739.47 | G11: =F11/B11 -> 99.118615 | H11: =SUM(F4:F11)/SUM(B4:B11) -> 104.19954 | I11: =SUM(F7:F11)/SUM(B7:B11) -> 98.789754 | J11: 101
A12: 45901 | B12: =Sep!C6 -> 6634.4 | C12: =Sep!C87+SUM(Sep!D117:G117) -> 522784 | D12: =Sep!C51 -> 300717 | E12: =B12*101 -> 670074.4 | F12: =C12+D12*0.476 -> 665925.29 | G12: =F12/B12 -> 100.37461 | H12: =SUM(F4:F12)/SUM(B4:B12) -> 103.80483 | I12: =SUM(F7:F12)/SUM(B7:B12) -> 99.042848 | J12: 101
A13: 45931 | B13: =Oct!$C$6 -> 5988.87 | C13: =Oct!$C$87+SUM(Oct!$D$117:$H$117) -> 503387 | D13: =Oct!$C$51 -> 205404 | E13: =B13*101 -> 604875.87 | F13: =C13+D13*0.476 -> 601159.3 | G13: =F13/B13 -> 100.37942 | H13: =SUM(F4:F13)/SUM(B4:B13) -> 103.51294 | I13: =SUM(F7:F13)/SUM(B7:B13) -> 99.211248 | J13: 101
A14: 45962 | J14: 101
A15: 45992 | J15: 101

Sheet Collectibles
P2: 101 | Q2: 13.5
